2023-05-14 09:57:39,288 - apscheduler.scheduler - INFO - Scheduler started
2023-05-14 10:00:34,469 - apscheduler.scheduler - INFO - Scheduler started
2023-05-14 10:02:08,830 - apscheduler.scheduler - INFO - Scheduler started
2023-05-14 10:04:00,717 - apscheduler.scheduler - INFO - Scheduler started
2023-05-14 10:05:48,150 - apscheduler.scheduler - INFO - Scheduler started
2023-05-14 10:07:12,079 - telegram.vendor.ptb_urllib3.urllib3.connectionpool - WARNING - Retrying (Retry(total=2, connect=None, read=None, redirect=None)) after connection broken by 'NewConnectionError('<telegram.vendor.ptb_urllib3.urllib3.connection.VerifiedHTTPSConnection object at 0x7f88dee75f40>: Failed to establish a new connection: [Errno 113] No route to host')': /bot5378417199:AAHp2CY0FZ4Pib-bA-yFKpVxXA4XCkGa6BI/getUpdates
2023-05-14 10:07:15,151 - telegram.vendor.ptb_urllib3.urllib3.connectionpool - WARNING - Retrying (Retry(total=1, connect=None, read=None, redirect=None)) after connection broken by 'NewConnectionError('<telegram.vendor.ptb_urllib3.urllib3.connection.VerifiedHTTPSConnection object at 0x7f88dee85160>: Failed to establish a new connection: [Errno 113] No route to host')': /bot5378417199:AAHp2CY0FZ4Pib-bA-yFKpVxXA4XCkGa6BI/getUpdates
2023-05-14 10:07:20,158 - telegram.vendor.ptb_urllib3.urllib3.connectionpool - WARNING - Retrying (Retry(total=0, connect=None, read=None, redirect=None)) after connection broken by 'ConnectTimeoutError(<telegram.vendor.ptb_urllib3.urllib3.connection.VerifiedHTTPSConnection object at 0x7f88dee852b0>, 'Connection to api.telegram.org timed out. (connect timeout=5.0)')': /bot5378417199:AAHp2CY0FZ4Pib-bA-yFKpVxXA4XCkGa6BI/getUpdates
2023-05-14 10:07:20,160 - telegram.ext.updater - ERROR - Error while getting Updates: urllib3 HTTPError HTTPSConnectionPool(host='api.telegram.org', port=443): Max retries exceeded with url: /bot5378417199:AAHp2CY0FZ4Pib-bA-yFKpVxXA4XCkGa6BI/getUpdates (Caused by NewConnectionError('<telegram.vendor.ptb_urllib3.urllib3.connection.VerifiedHTTPSConnection object at 0x7f88dee853d0>: Failed to establish a new connection: [Errno 101] Network is unreachable'))
2023-05-14 10:07:20,161 - telegram.ext.dispatcher - ERROR - No error handlers are registered, logging exception.
Traceback (most recent call last):
  File "/home/marta/.local/lib/python3.8/site-packages/telegram/vendor/ptb_urllib3/urllib3/connection.py", line 140, in _new_conn
    conn = connection.create_connection(
  File "/home/marta/.local/lib/python3.8/site-packages/telegram/vendor/ptb_urllib3/urllib3/util/connection.py", line 83, in create_connection
    raise err
  File "/home/marta/.local/lib/python3.8/site-packages/telegram/vendor/ptb_urllib3/urllib3/util/connection.py", line 73, in create_connection
    sock.connect(sa)
OSError: [Errno 101] Network is unreachable

During handling of the above exception, another exception occurred:

Traceback (most recent call last):
  File "/home/marta/.local/lib/python3.8/site-packages/telegram/vendor/ptb_urllib3/urllib3/connectionpool.py", line 614, in urlopen
    httplib_response = self._make_request(conn, method, url,
  File "/home/marta/.local/lib/python3.8/site-packages/telegram/vendor/ptb_urllib3/urllib3/connectionpool.py", line 360, in _make_request
    self._validate_conn(conn)
  File "/home/marta/.local/lib/python3.8/site-packages/telegram/vendor/ptb_urllib3/urllib3/connectionpool.py", line 857, in _validate_conn
    super(HTTPSConnectionPool, self)._validate_conn(conn)
  File "/home/marta/.local/lib/python3.8/site-packages/telegram/vendor/ptb_urllib3/urllib3/connectionpool.py", line 289, in _validate_conn
    conn.connect()
  File "/home/marta/.local/lib/python3.8/site-packages/telegram/vendor/ptb_urllib3/urllib3/connection.py", line 284, in connect
    conn = self._new_conn()
  File "/home/marta/.local/lib/python3.8/site-packages/telegram/vendor/ptb_urllib3/urllib3/connection.py", line 149, in _new_conn
    raise NewConnectionError(
telegram.vendor.ptb_urllib3.urllib3.exceptions.NewConnectionError: <telegram.vendor.ptb_urllib3.urllib3.connection.VerifiedHTTPSConnection object at 0x7f88dee853d0>: Failed to establish a new connection: [Errno 101] Network is unreachable

During handling of the above exception, another exception occurred:

Traceback (most recent call last):
  File "/home/marta/.local/lib/python3.8/site-packages/telegram/utils/request.py", line 259, in _request_wrapper
    resp = self._con_pool.request(*args, **kwargs)
  File "/home/marta/.local/lib/python3.8/site-packages/telegram/vendor/ptb_urllib3/urllib3/request.py", line 68, in request
    return self.request_encode_body(method, url, fields=fields,
  File "/home/marta/.local/lib/python3.8/site-packages/telegram/vendor/ptb_urllib3/urllib3/request.py", line 148, in request_encode_body
    return self.urlopen(method, url, **extra_kw)
  File "/home/marta/.local/lib/python3.8/site-packages/telegram/vendor/ptb_urllib3/urllib3/poolmanager.py", line 244, in urlopen
    response = conn.urlopen(method, u.request_uri, **kw)
  File "/home/marta/.local/lib/python3.8/site-packages/telegram/vendor/ptb_urllib3/urllib3/connectionpool.py", line 691, in urlopen
    return self.urlopen(method, url, body, headers, retries,
  File "/home/marta/.local/lib/python3.8/site-packages/telegram/vendor/ptb_urllib3/urllib3/connectionpool.py", line 691, in urlopen
    return self.urlopen(method, url, body, headers, retries,
  File "/home/marta/.local/lib/python3.8/site-packages/telegram/vendor/ptb_urllib3/urllib3/connectionpool.py", line 691, in urlopen
    return self.urlopen(method, url, body, headers, retries,
  File "/home/marta/.local/lib/python3.8/site-packages/telegram/vendor/ptb_urllib3/urllib3/connectionpool.py", line 665, in urlopen
    retries = retries.increment(method, url, error=e, _pool=self,
  File "/home/marta/.local/lib/python3.8/site-packages/telegram/vendor/ptb_urllib3/urllib3/util/retry.py", line 376, in increment
    raise MaxRetryError(_pool, url, error or ResponseError(cause))
telegram.vendor.ptb_urllib3.urllib3.exceptions.MaxRetryError: HTTPSConnectionPool(host='api.telegram.org', port=443): Max retries exceeded with url: /bot5378417199:AAHp2CY0FZ4Pib-bA-yFKpVxXA4XCkGa6BI/getUpdates (Caused by NewConnectionError('<telegram.vendor.ptb_urllib3.urllib3.connection.VerifiedHTTPSConnection object at 0x7f88dee853d0>: Failed to establish a new connection: [Errno 101] Network is unreachable'))

The above exception was the direct cause of the following exception:

Traceback (most recent call last):
  File "/home/marta/.local/lib/python3.8/site-packages/telegram/ext/updater.py", line 646, in _network_loop_retry
    if not action_cb():
  File "/home/marta/.local/lib/python3.8/site-packages/telegram/ext/updater.py", line 597, in polling_action_cb
    updates = self.bot.get_updates(
  File "/home/marta/.local/lib/python3.8/site-packages/telegram/ext/extbot.py", line 222, in get_updates
    updates = super().get_updates(
  File "/home/marta/.local/lib/python3.8/site-packages/telegram/bot.py", line 130, in decorator
    result = func(*args, **kwargs)
  File "/home/marta/.local/lib/python3.8/site-packages/telegram/bot.py", line 2945, in get_updates
    self._post(
  File "/home/marta/.local/lib/python3.8/site-packages/telegram/bot.py", line 295, in _post
    return self.request.post(
  File "/home/marta/.local/lib/python3.8/site-packages/telegram/utils/request.py", line 361, in post
    result = self._request_wrapper(
  File "/home/marta/.local/lib/python3.8/site-packages/telegram/utils/request.py", line 265, in _request_wrapper
    raise NetworkError(f'urllib3 HTTPError {error}') from error
telegram.error.NetworkError: urllib3 HTTPError HTTPSConnectionPool(host='api.telegram.org', port=443): Max retries exceeded with url: /bot5378417199:AAHp2CY0FZ4Pib-bA-yFKpVxXA4XCkGa6BI/getUpdates (Caused by NewConnectionError('<telegram.vendor.ptb_urllib3.urllib3.connection.VerifiedHTTPSConnection object at 0x7f88dee853d0>: Failed to establish a new connection: [Errno 101] Network is unreachable'))
2023-05-14 10:08:56,659 - apscheduler.scheduler - INFO - Scheduler started
2023-05-14 10:09:00,925 - apscheduler.scheduler - INFO - Scheduler started
2023-05-14 10:09:35,544 - root - INFO -  - CMD: DIVERBO - USER_ID: 28097231 - USERNAME: martatorrebarbeito - USER_FULLNAME: Marta - CHAT ID: 28097231
2023-05-14 10:09:35,545 - telegram.ext.dispatcher - ERROR - No error handlers are registered, logging exception.
Traceback (most recent call last):
  File "/home/marta/.local/lib/python3.8/site-packages/telegram/ext/dispatcher.py", line 555, in process_update
    handler.handle_update(update, self, check, context)
  File "/home/marta/.local/lib/python3.8/site-packages/telegram/ext/handler.py", line 198, in handle_update
    return self.callback(update, context)
  File "/home/marta/Proyectos/lverbobot/lverbobot.py", line 221, in diverbo
    pregunta = df.iloc[aleatorio]
NameError: name 'df' is not defined
2023-05-14 10:09:37,901 - root - INFO -  - CMD: DITIEMPO - USER_ID: 28097231 - USERNAME: martatorrebarbeito - USER_FULLNAME: Marta - CHAT ID: 28097231
2023-05-14 10:09:37,901 - telegram.ext.dispatcher - ERROR - No error handlers are registered, logging exception.
Traceback (most recent call last):
  File "/home/marta/.local/lib/python3.8/site-packages/telegram/ext/dispatcher.py", line 555, in process_update
    handler.handle_update(update, self, check, context)
  File "/home/marta/.local/lib/python3.8/site-packages/telegram/ext/handler.py", line 198, in handle_update
    return self.callback(update, context)
  File "/home/marta/Proyectos/lverbobot/lverbobot.py", line 205, in ditiempo
    listado['boton'] = listado.apply(lambda row: boton(verbo), axis=1)
NameError: name 'listado' is not defined
2023-05-14 10:11:45,864 - apscheduler.scheduler - INFO - Scheduler started
2023-05-14 10:12:16,301 - root - INFO -  - CMD: DIVERBO - USER_ID: 28097231 - USERNAME: martatorrebarbeito - USER_FULLNAME: Marta - CHAT ID: 28097231
2023-05-14 10:12:16,301 - telegram.ext.dispatcher - ERROR - No error handlers are registered, logging exception.
Traceback (most recent call last):
  File "/home/marta/.local/lib/python3.8/site-packages/telegram/ext/dispatcher.py", line 555, in process_update
    handler.handle_update(update, self, check, context)
  File "/home/marta/.local/lib/python3.8/site-packages/telegram/ext/handler.py", line 198, in handle_update
    return self.callback(update, context)
  File "/home/marta/Proyectos/lverbobot/lverbobot.py", line 221, in diverbo
    pregunta = df.iloc[aleatorio]
NameError: name 'df' is not defined
2023-05-14 10:12:27,175 - root - INFO -  - CMD: DITIEMPO - USER_ID: 28097231 - USERNAME: martatorrebarbeito - USER_FULLNAME: Marta - CHAT ID: 28097231
2023-05-14 10:17:45,757 - apscheduler.scheduler - INFO - Scheduler started
2023-05-14 10:17:57,010 - root - INFO -  - CMD: DIVERBO - USER_ID: 28097231 - USERNAME: martatorrebarbeito - USER_FULLNAME: Marta - CHAT ID: 28097231
2023-05-14 10:17:57,011 - telegram.ext.dispatcher - ERROR - No error handlers are registered, logging exception.
Traceback (most recent call last):
  File "/home/marta/.local/lib/python3.8/site-packages/telegram/ext/dispatcher.py", line 555, in process_update
    handler.handle_update(update, self, check, context)
  File "/home/marta/.local/lib/python3.8/site-packages/telegram/ext/handler.py", line 198, in handle_update
    return self.callback(update, context)
  File "/home/marta/Proyectos/lverbobot/lverbobot.py", line 222, in diverbo
    context.bot.send_message(chat_id=update.effective_chat.id, text=pregunta)
  File "/home/marta/.local/lib/python3.8/site-packages/telegram/bot.py", line 130, in decorator
    result = func(*args, **kwargs)
  File "/home/marta/.local/lib/python3.8/site-packages/telegram/bot.py", line 513, in send_message
    return self._message(  # type: ignore[return-value]
  File "/home/marta/.local/lib/python3.8/site-packages/telegram/ext/extbot.py", line 199, in _message
    result = super()._message(
  File "/home/marta/.local/lib/python3.8/site-packages/telegram/bot.py", line 332, in _message
    result = self._post(endpoint, data, timeout=timeout, api_kwargs=api_kwargs)
  File "/home/marta/.local/lib/python3.8/site-packages/telegram/bot.py", line 295, in _post
    return self.request.post(
  File "/home/marta/.local/lib/python3.8/site-packages/telegram/utils/request.py", line 364, in post
    body=json.dumps(data).encode('utf-8'),
  File "/usr/lib64/python3.8/json/__init__.py", line 231, in dumps
    return _default_encoder.encode(obj)
  File "/usr/lib64/python3.8/json/encoder.py", line 199, in encode
    chunks = self.iterencode(o, _one_shot=True)
  File "/usr/lib64/python3.8/json/encoder.py", line 257, in iterencode
    return _iterencode(o, 0)
  File "/usr/lib64/python3.8/json/encoder.py", line 179, in default
    raise TypeError(f'Object of type {o.__class__.__name__} '
TypeError: Object of type Series is not JSON serializable
2023-05-14 10:19:23,090 - apscheduler.scheduler - INFO - Scheduler started
2023-05-14 10:19:31,244 - root - INFO -  - CMD: DIVERBO - USER_ID: 28097231 - USERNAME: martatorrebarbeito - USER_FULLNAME: Marta - CHAT ID: 28097231
2023-05-14 10:19:52,454 - telegram.ext.dispatcher - ERROR - No error handlers are registered, logging exception.
Traceback (most recent call last):
  File "/home/marta/.local/lib/python3.8/site-packages/telegram/ext/dispatcher.py", line 555, in process_update
    handler.handle_update(update, self, check, context)
  File "/home/marta/.local/lib/python3.8/site-packages/telegram/ext/handler.py", line 198, in handle_update
    return self.callback(update, context)
  File "/home/marta/Proyectos/lverbobot/lverbobot.py", line 221, in diverbo
    pregunta = d_verbos.iloc[aleatorio]
  File "/home/marta/.local/lib/python3.8/site-packages/pandas/core/indexing.py", line 931, in __getitem__
    return self._getitem_axis(maybe_callable, axis=axis)
  File "/home/marta/.local/lib/python3.8/site-packages/pandas/core/indexing.py", line 1566, in _getitem_axis
    self._validate_integer(key, axis)
  File "/home/marta/.local/lib/python3.8/site-packages/pandas/core/indexing.py", line 1500, in _validate_integer
    raise IndexError("single positional indexer is out-of-bounds")
IndexError: single positional indexer is out-of-bounds
2023-05-14 10:20:07,001 - apscheduler.scheduler - INFO - Scheduler started
2023-05-14 10:20:10,530 - root - INFO -  - CMD: DIVERBO - USER_ID: 28097231 - USERNAME: martatorrebarbeito - USER_FULLNAME: Marta - CHAT ID: 28097231
2023-05-14 10:29:11,325 - apscheduler.scheduler - INFO - Scheduler started
2023-05-14 10:29:20,932 - root - INFO -  - CMD: DIVERBO - USER_ID: 28097231 - USERNAME: martatorrebarbeito - USER_FULLNAME: Marta - CHAT ID: 28097231
2023-05-14 10:29:20,933 - telegram.ext.dispatcher - ERROR - No error handlers are registered, logging exception.
Traceback (most recent call last):
  File "/home/marta/.local/lib/python3.8/site-packages/telegram/ext/dispatcher.py", line 555, in process_update
    handler.handle_update(update, self, check, context)
  File "/home/marta/.local/lib/python3.8/site-packages/telegram/ext/handler.py", line 198, in handle_update
    return self.callback(update, context)
  File "/home/marta/Proyectos/lverbobot/lverbobot.py", line 222, in diverbo
    context.bot.send_message(chat_id=update.effective_chat.id, text=pregunta)
  File "/home/marta/.local/lib/python3.8/site-packages/telegram/bot.py", line 130, in decorator
    result = func(*args, **kwargs)
  File "/home/marta/.local/lib/python3.8/site-packages/telegram/bot.py", line 513, in send_message
    return self._message(  # type: ignore[return-value]
  File "/home/marta/.local/lib/python3.8/site-packages/telegram/ext/extbot.py", line 199, in _message
    result = super()._message(
  File "/home/marta/.local/lib/python3.8/site-packages/telegram/bot.py", line 332, in _message
    result = self._post(endpoint, data, timeout=timeout, api_kwargs=api_kwargs)
  File "/home/marta/.local/lib/python3.8/site-packages/telegram/bot.py", line 295, in _post
    return self.request.post(
  File "/home/marta/.local/lib/python3.8/site-packages/telegram/utils/request.py", line 364, in post
    body=json.dumps(data).encode('utf-8'),
  File "/usr/lib64/python3.8/json/__init__.py", line 231, in dumps
    return _default_encoder.encode(obj)
  File "/usr/lib64/python3.8/json/encoder.py", line 199, in encode
    chunks = self.iterencode(o, _one_shot=True)
  File "/usr/lib64/python3.8/json/encoder.py", line 257, in iterencode
    return _iterencode(o, 0)
  File "/usr/lib64/python3.8/json/encoder.py", line 179, in default
    raise TypeError(f'Object of type {o.__class__.__name__} '
TypeError: Object of type Series is not JSON serializable
2023-05-14 10:29:55,519 - apscheduler.scheduler - INFO - Scheduler started
2023-05-14 10:30:04,532 - root - INFO -  - CMD: DIVERBO - USER_ID: 28097231 - USERNAME: martatorrebarbeito - USER_FULLNAME: Marta - CHAT ID: 28097231
2023-05-14 10:39:35,755 - apscheduler.scheduler - INFO - Scheduler started
2023-05-14 10:39:42,751 - root - INFO -  - CMD: DIVERBO - USER_ID: 28097231 - USERNAME: martatorrebarbeito - USER_FULLNAME: Marta - CHAT ID: 28097231
2023-05-14 10:39:42,752 - telegram.ext.dispatcher - ERROR - No error handlers are registered, logging exception.
Traceback (most recent call last):
  File "/home/marta/.local/lib/python3.8/site-packages/telegram/ext/dispatcher.py", line 555, in process_update
    handler.handle_update(update, self, check, context)
  File "/home/marta/.local/lib/python3.8/site-packages/telegram/ext/handler.py", line 198, in handle_update
    return self.callback(update, context)
  File "/home/marta/Proyectos/lverbobot/lverbobot.py", line 221, in diverbo
    pregunta.entrada = d_verbos.iloc[aleatorio]
UnboundLocalError: local variable 'pregunta' referenced before assignment
2023-05-14 10:39:58,935 - apscheduler.scheduler - INFO - Scheduler started
2023-05-14 10:39:59,529 - root - INFO -  - CMD: DIVERBO - USER_ID: 28097231 - USERNAME: martatorrebarbeito - USER_FULLNAME: Marta - CHAT ID: 28097231
2023-05-14 10:40:55,447 - apscheduler.scheduler - INFO - Scheduler started
2023-05-14 10:41:09,596 - root - INFO -  - CMD: DIVERBO - USER_ID: 28097231 - USERNAME: martatorrebarbeito - USER_FULLNAME: Marta - CHAT ID: 28097231
2023-05-14 10:43:41,629 - apscheduler.scheduler - INFO - Scheduler started
2023-05-14 10:43:42,682 - root - INFO -  - CMD: DIVERBO - USER_ID: 28097231 - USERNAME: martatorrebarbeito - USER_FULLNAME: Marta - CHAT ID: 28097231
2023-05-14 10:44:24,869 - apscheduler.scheduler - INFO - Scheduler started
2023-05-14 10:44:31,853 - root - INFO -  - CMD: DIVERBO - USER_ID: 28097231 - USERNAME: martatorrebarbeito - USER_FULLNAME: Marta - CHAT ID: 28097231
2023-05-14 10:45:15,945 - apscheduler.scheduler - INFO - Scheduler started
2023-05-14 10:45:21,402 - root - INFO -  - CMD: DIVERBO - USER_ID: 28097231 - USERNAME: martatorrebarbeito - USER_FULLNAME: Marta - CHAT ID: 28097231
2023-05-14 10:46:10,655 - apscheduler.scheduler - INFO - Scheduler started
2023-05-14 10:46:13,046 - root - INFO -  - CMD: DIVERBO - USER_ID: 28097231 - USERNAME: martatorrebarbeito - USER_FULLNAME: Marta - CHAT ID: 28097231
2023-05-14 11:12:23,878 - apscheduler.scheduler - INFO - Scheduler started
2023-05-14 11:12:28,231 - root - INFO -  - CMD: DITIEMPO - USER_ID: 28097231 - USERNAME: martatorrebarbeito - USER_FULLNAME: Marta - CHAT ID: 28097231
2023-05-14 11:13:27,591 - apscheduler.scheduler - INFO - Scheduler started
2023-05-14 11:13:27,888 - root - INFO -  - CMD: DITIEMPO - USER_ID: 28097231 - USERNAME: martatorrebarbeito - USER_FULLNAME: Marta - CHAT ID: 28097231
2023-05-14 11:14:15,685 - telegram.ext.dispatcher - ERROR - No error handlers are registered, logging exception.
Traceback (most recent call last):
  File "/home/marta/.local/lib/python3.8/site-packages/pandas/core/indexes/base.py", line 3361, in get_loc
    return self._engine.get_loc(casted_key)
  File "pandas/_libs/index.pyx", line 76, in pandas._libs.index.IndexEngine.get_loc
  File "pandas/_libs/index.pyx", line 108, in pandas._libs.index.IndexEngine.get_loc
  File "pandas/_libs/hashtable_class_helper.pxi", line 5198, in pandas._libs.hashtable.PyObjectHashTable.get_item
  File "pandas/_libs/hashtable_class_helper.pxi", line 5206, in pandas._libs.hashtable.PyObjectHashTable.get_item
KeyError: 'valor'

The above exception was the direct cause of the following exception:

Traceback (most recent call last):
  File "/home/marta/.local/lib/python3.8/site-packages/telegram/ext/dispatcher.py", line 555, in process_update
    handler.handle_update(update, self, check, context)
  File "/home/marta/.local/lib/python3.8/site-packages/telegram/ext/handler.py", line 198, in handle_update
    return self.callback(update, context)
  File "/home/marta/Proyectos/lverbobot/lverbobot.py", line 205, in ditiempo
    listado_botones = d_tiempos.apply(lambda row: boton(row), axis=1)
  File "/home/marta/.local/lib/python3.8/site-packages/pandas/core/frame.py", line 8740, in apply
    return op.apply()
  File "/home/marta/.local/lib/python3.8/site-packages/pandas/core/apply.py", line 688, in apply
    return self.apply_standard()
  File "/home/marta/.local/lib/python3.8/site-packages/pandas/core/apply.py", line 812, in apply_standard
    results, res_index = self.apply_series_generator()
  File "/home/marta/.local/lib/python3.8/site-packages/pandas/core/apply.py", line 828, in apply_series_generator
    results[i] = self.f(v)
  File "/home/marta/Proyectos/lverbobot/lverbobot.py", line 205, in <lambda>
    listado_botones = d_tiempos.apply(lambda row: boton(row), axis=1)
  File "/home/marta/Proyectos/lverbobot/lverbobot.py", line 184, in boton
    dato = verbo['valor']
  File "/home/marta/.local/lib/python3.8/site-packages/pandas/core/series.py", line 942, in __getitem__
    return self._get_value(key)
  File "/home/marta/.local/lib/python3.8/site-packages/pandas/core/series.py", line 1051, in _get_value
    loc = self.index.get_loc(label)
  File "/home/marta/.local/lib/python3.8/site-packages/pandas/core/indexes/base.py", line 3363, in get_loc
    raise KeyError(key) from err
KeyError: 'valor'
2023-05-14 11:15:20,437 - apscheduler.scheduler - INFO - Scheduler started
2023-05-14 11:15:30,765 - root - INFO -  - CMD: DITIEMPO - USER_ID: 28097231 - USERNAME: martatorrebarbeito - USER_FULLNAME: Marta - CHAT ID: 28097231
2023-05-14 11:19:16,052 - apscheduler.scheduler - INFO - Scheduler started
2023-05-14 11:19:19,780 - root - INFO -  - CMD: DITIEMPO - USER_ID: 28097231 - USERNAME: martatorrebarbeito - USER_FULLNAME: Marta - CHAT ID: 28097231
2023-05-14 11:19:52,808 - telegram.ext.dispatcher - ERROR - No error handlers are registered, logging exception.
Traceback (most recent call last):
  File "/home/marta/.local/lib/python3.8/site-packages/telegram/ext/dispatcher.py", line 555, in process_update
    handler.handle_update(update, self, check, context)
  File "/home/marta/.local/lib/python3.8/site-packages/telegram/ext/handler.py", line 198, in handle_update
    return self.callback(update, context)
  File "/home/marta/Proyectos/lverbobot/lverbobot.py", line 212, in ditiempo
    context.bot.send_message(chat_id=update.effective_chat.id,text='Verboalchou',reply_markup=listado_botones    )
  File "/home/marta/.local/lib/python3.8/site-packages/telegram/bot.py", line 130, in decorator
    result = func(*args, **kwargs)
  File "/home/marta/.local/lib/python3.8/site-packages/telegram/bot.py", line 513, in send_message
    return self._message(  # type: ignore[return-value]
  File "/home/marta/.local/lib/python3.8/site-packages/telegram/ext/extbot.py", line 199, in _message
    result = super()._message(
  File "/home/marta/.local/lib/python3.8/site-packages/telegram/bot.py", line 332, in _message
    result = self._post(endpoint, data, timeout=timeout, api_kwargs=api_kwargs)
  File "/home/marta/.local/lib/python3.8/site-packages/telegram/bot.py", line 295, in _post
    return self.request.post(
  File "/home/marta/.local/lib/python3.8/site-packages/telegram/utils/request.py", line 364, in post
    body=json.dumps(data).encode('utf-8'),
  File "/usr/lib64/python3.8/json/__init__.py", line 231, in dumps
    return _default_encoder.encode(obj)
  File "/usr/lib64/python3.8/json/encoder.py", line 199, in encode
    chunks = self.iterencode(o, _one_shot=True)
  File "/usr/lib64/python3.8/json/encoder.py", line 257, in iterencode
    return _iterencode(o, 0)
  File "/usr/lib64/python3.8/json/encoder.py", line 179, in default
    raise TypeError(f'Object of type {o.__class__.__name__} '
TypeError: Object of type Series is not JSON serializable
2023-05-14 11:21:13,217 - apscheduler.scheduler - INFO - Scheduler started
2023-05-14 11:21:15,236 - root - INFO -  - CMD: DITIEMPO - USER_ID: 28097231 - USERNAME: martatorrebarbeito - USER_FULLNAME: Marta - CHAT ID: 28097231
2023-05-14 12:01:07,191 - apscheduler.scheduler - INFO - Scheduler started
2023-05-14 12:01:12,763 - root - INFO -  - CMD: DITIEMPO - USER_ID: 28097231 - USERNAME: martatorrebarbeito - USER_FULLNAME: Marta - CHAT ID: 28097231
2023-05-14 12:01:12,771 - telegram.ext.dispatcher - ERROR - No error handlers are registered, logging exception.
Traceback (most recent call last):
  File "/home/marta/.local/lib/python3.8/site-packages/telegram/ext/dispatcher.py", line 555, in process_update
    handler.handle_update(update, self, check, context)
  File "/home/marta/.local/lib/python3.8/site-packages/telegram/ext/handler.py", line 198, in handle_update
    return self.callback(update, context)
  File "/home/marta/Proyectos/lverbobot/lverbobot.py", line 205, in ditiempo
    listado_botones['boton'] = d_tiempos.apply(lambda row: boton(row), axis=1)
NameError: name 'listado_botones' is not defined
2023-05-14 12:01:35,419 - apscheduler.scheduler - INFO - Scheduler started
2023-05-14 12:01:40,412 - root - INFO -  - CMD: DITIEMPO - USER_ID: 28097231 - USERNAME: martatorrebarbeito - USER_FULLNAME: Marta - CHAT ID: 28097231
2023-05-14 12:01:40,418 - telegram.ext.dispatcher - ERROR - No error handlers are registered, logging exception.
Traceback (most recent call last):
  File "/home/marta/.local/lib/python3.8/site-packages/telegram/ext/dispatcher.py", line 555, in process_update
    handler.handle_update(update, self, check, context)
  File "/home/marta/.local/lib/python3.8/site-packages/telegram/ext/handler.py", line 198, in handle_update
    return self.callback(update, context)
  File "/home/marta/Proyectos/lverbobot/lverbobot.py", line 205, in ditiempo
    listado_botones['boton'] = d_tiempos.apply(lambda row: boton(row), axis=1)
NameError: name 'listado_botones' is not defined
2023-05-14 12:01:50,018 - root - INFO -  - CMD: DIVERBO - USER_ID: 28097231 - USERNAME: martatorrebarbeito - USER_FULLNAME: Marta - CHAT ID: 28097231
2023-05-14 12:05:11,717 - apscheduler.scheduler - INFO - Scheduler started
2023-05-14 12:05:14,569 - root - INFO -  - CMD: DITIEMPO - USER_ID: 28097231 - USERNAME: martatorrebarbeito - USER_FULLNAME: Marta - CHAT ID: 28097231
2023-05-14 12:05:14,576 - telegram.ext.dispatcher - ERROR - No error handlers are registered, logging exception.
Traceback (most recent call last):
  File "/home/marta/.local/lib/python3.8/site-packages/telegram/ext/dispatcher.py", line 555, in process_update
    handler.handle_update(update, self, check, context)
  File "/home/marta/.local/lib/python3.8/site-packages/telegram/ext/handler.py", line 198, in handle_update
    return self.callback(update, context)
  File "/home/marta/Proyectos/lverbobot/lverbobot.py", line 205, in ditiempo
    listado_botones['boton'] = d_tiempos.apply(lambda row: boton(row), axis=1)
NameError: name 'listado_botones' is not defined
2023-05-14 12:05:16,997 - root - INFO -  - CMD: DIVERBO - USER_ID: 28097231 - USERNAME: martatorrebarbeito - USER_FULLNAME: Marta - CHAT ID: 28097231
2023-05-14 12:05:43,093 - telegram.ext.dispatcher - ERROR - No error handlers are registered, logging exception.
Traceback (most recent call last):
  File "/home/marta/.local/lib/python3.8/site-packages/telegram/ext/dispatcher.py", line 555, in process_update
    handler.handle_update(update, self, check, context)
  File "/home/marta/.local/lib/python3.8/site-packages/telegram/ext/handler.py", line 198, in handle_update
    return self.callback(update, context)
  File "/home/marta/Proyectos/lverbobot/lverbobot.py", line 231, in diverbo
    pregunta = + persona + ' del ' + tiempo + ' de ' + modo + ' del verbo ' + verbo
TypeError: bad operand type for unary +: 'str'
2023-05-14 12:06:36,626 - apscheduler.scheduler - INFO - Scheduler started
2023-05-14 12:06:49,129 - root - INFO -  - CMD: DITIEMPO - USER_ID: 28097231 - USERNAME: martatorrebarbeito - USER_FULLNAME: Marta - CHAT ID: 28097231
2023-05-14 12:07:14,397 - telegram.ext.dispatcher - ERROR - No error handlers are registered, logging exception.
Traceback (most recent call last):
  File "/home/marta/.local/lib/python3.8/site-packages/telegram/ext/dispatcher.py", line 555, in process_update
    handler.handle_update(update, self, check, context)
  File "/home/marta/.local/lib/python3.8/site-packages/telegram/ext/handler.py", line 198, in handle_update
    return self.callback(update, context)
  File "/home/marta/Proyectos/lverbobot/lverbobot.py", line 205, in ditiempo
    listado_botones['boton'] = d_tiempos.apply(lambda row: boton(row), axis=1)
NameError: name 'listado_botones' is not defined
2023-05-14 12:12:22,786 - apscheduler.scheduler - INFO - Scheduler started
2023-05-14 12:12:44,872 - root - INFO -  - CMD: DITIEMPO - USER_ID: 28097231 - USERNAME: martatorrebarbeito - USER_FULLNAME: Marta - CHAT ID: 28097231
2023-05-14 12:13:41,732 - apscheduler.scheduler - INFO - Scheduler started
2023-05-14 12:13:45,733 - root - INFO -  - CMD: DITIEMPO - USER_ID: 28097231 - USERNAME: martatorrebarbeito - USER_FULLNAME: Marta - CHAT ID: 28097231
2023-05-14 12:16:00,532 - apscheduler.scheduler - INFO - Scheduler started
2023-05-14 12:16:03,624 - root - INFO -  - CMD: DITIEMPO - USER_ID: 28097231 - USERNAME: martatorrebarbeito - USER_FULLNAME: Marta - CHAT ID: 28097231
2023-05-14 12:17:34,066 - apscheduler.scheduler - INFO - Scheduler started
2023-05-14 12:17:37,108 - root - INFO -  - CMD: DITIEMPO - USER_ID: 28097231 - USERNAME: martatorrebarbeito - USER_FULLNAME: Marta - CHAT ID: 28097231
2023-05-14 12:19:25,952 - apscheduler.scheduler - INFO - Scheduler started
2023-05-14 12:19:27,720 - root - INFO -  - CMD: DIVERBO - USER_ID: 28097231 - USERNAME: martatorrebarbeito - USER_FULLNAME: Marta - CHAT ID: 28097231
2023-05-14 12:21:10,316 - apscheduler.scheduler - INFO - Scheduler started
2023-05-14 12:21:17,342 - root - INFO -  - CMD: DIVERBO - USER_ID: 28097231 - USERNAME: martatorrebarbeito - USER_FULLNAME: Marta - CHAT ID: 28097231
2023-05-14 12:24:38,983 - apscheduler.scheduler - INFO - Scheduler started
2023-05-14 12:24:41,553 - root - INFO -  - CMD: DIVERBO - USER_ID: 28097231 - USERNAME: martatorrebarbeito - USER_FULLNAME: Marta - CHAT ID: 28097231
2023-05-14 12:26:06,684 - apscheduler.scheduler - INFO - Scheduler started
2023-05-14 12:26:08,594 - root - INFO -  - CMD: DIVERBO - USER_ID: 28097231 - USERNAME: martatorrebarbeito - USER_FULLNAME: Marta - CHAT ID: 28097231
2023-05-14 12:26:50,459 - apscheduler.scheduler - INFO - Scheduler started
2023-05-14 12:26:50,737 - root - INFO -  - CMD: DITIEMPO - USER_ID: 28097231 - USERNAME: martatorrebarbeito - USER_FULLNAME: Marta - CHAT ID: 28097231
2023-05-14 12:27:01,921 - root - INFO -  - CMD: DIVERBO - USER_ID: 28097231 - USERNAME: martatorrebarbeito - USER_FULLNAME: Marta - CHAT ID: 28097231
2023-05-14 12:55:21,694 - apscheduler.scheduler - INFO - Scheduler started
2023-05-14 12:55:27,697 - root - INFO -  - CMD: RESPUESTA - USER_ID: 28097231 - USERNAME: martatorrebarbeito - USER_FULLNAME: Marta - CHAT ID: 28097231
2023-05-14 12:58:36,443 - apscheduler.scheduler - INFO - Scheduler started
2023-05-14 12:58:57,216 - root - INFO -  - CMD: DIVERBO - USER_ID: 28097231 - USERNAME: martatorrebarbeito - USER_FULLNAME: Marta - CHAT ID: 28097231
2023-05-14 12:59:07,116 - root - INFO -  - CMD: RESPUESTA - USER_ID: 28097231 - USERNAME: martatorrebarbeito - USER_FULLNAME: Marta - CHAT ID: 28097231
2023-05-14 12:59:09,242 - root - INFO -  - CMD: RESPUESTA - USER_ID: 28097231 - USERNAME: martatorrebarbeito - USER_FULLNAME: Marta - CHAT ID: 28097231
2023-05-14 12:59:11,573 - root - INFO -  - CMD: RESPUESTA - USER_ID: 28097231 - USERNAME: martatorrebarbeito - USER_FULLNAME: Marta - CHAT ID: 28097231
2023-05-14 12:59:14,598 - root - INFO -  - CMD: DIVERBO - USER_ID: 28097231 - USERNAME: martatorrebarbeito - USER_FULLNAME: Marta - CHAT ID: 28097231
2023-05-14 12:59:29,700 - root - INFO -  - CMD: RESPUESTA - USER_ID: 28097231 - USERNAME: martatorrebarbeito - USER_FULLNAME: Marta - CHAT ID: 28097231
2023-05-14 12:59:34,660 - root - INFO -  - CMD: RESPUESTA - USER_ID: 28097231 - USERNAME: martatorrebarbeito - USER_FULLNAME: Marta - CHAT ID: 28097231
2023-05-14 13:00:34,355 - apscheduler.scheduler - INFO - Scheduler started
2023-05-14 13:00:38,621 - root - INFO -  - CMD: DIVERBO - USER_ID: 28097231 - USERNAME: martatorrebarbeito - USER_FULLNAME: Marta - CHAT ID: 28097231
2023-05-14 13:00:52,647 - root - INFO -  - CMD: RESPUESTA - USER_ID: 28097231 - USERNAME: martatorrebarbeito - USER_FULLNAME: Marta - CHAT ID: 28097231
2023-05-14 13:00:57,567 - root - INFO -  - CMD: DIVERBO - USER_ID: 28097231 - USERNAME: martatorrebarbeito - USER_FULLNAME: Marta - CHAT ID: 28097231
2023-05-14 13:01:07,673 - root - INFO -  - CMD: RESPUESTA - USER_ID: 28097231 - USERNAME: martatorrebarbeito - USER_FULLNAME: Marta - CHAT ID: 28097231
2023-05-14 13:01:10,907 - root - INFO -  - CMD: DIVERBO - USER_ID: 28097231 - USERNAME: martatorrebarbeito - USER_FULLNAME: Marta - CHAT ID: 28097231
2023-05-14 13:01:20,839 - root - INFO -  - CMD: RESPUESTA - USER_ID: 28097231 - USERNAME: martatorrebarbeito - USER_FULLNAME: Marta - CHAT ID: 28097231
2023-05-14 13:01:24,782 - root - INFO -  - CMD: RESPUESTA - USER_ID: 28097231 - USERNAME: martatorrebarbeito - USER_FULLNAME: Marta - CHAT ID: 28097231
2023-05-14 13:01:27,664 - root - INFO -  - CMD: RESPUESTA - USER_ID: 28097231 - USERNAME: martatorrebarbeito - USER_FULLNAME: Marta - CHAT ID: 28097231
2023-05-14 13:01:41,767 - apscheduler.scheduler - INFO - Scheduler started
2023-05-14 13:01:45,424 - root - INFO -  - CMD: DIVERBO - USER_ID: 28097231 - USERNAME: martatorrebarbeito - USER_FULLNAME: Marta - CHAT ID: 28097231
2023-05-14 13:01:50,762 - root - INFO -  - CMD: RESPUESTA - USER_ID: 28097231 - USERNAME: martatorrebarbeito - USER_FULLNAME: Marta - CHAT ID: 28097231
2023-05-14 13:04:49,878 - apscheduler.scheduler - INFO - Scheduler started
2023-05-14 13:07:10,629 - root - INFO -  - CMD: START - USER_ID: 41072934 - USERNAME: jjvf0 - USER_FULLNAME: JJ - CHAT ID: 41072934
2023-05-14 13:07:18,197 - root - INFO -  - CMD: DITIEMPO - USER_ID: 41072934 - USERNAME: jjvf0 - USER_FULLNAME: JJ - CHAT ID: 41072934
2023-05-14 13:07:37,767 - root - INFO -  - CMD: RESPUESTA - USER_ID: 41072934 - USERNAME: jjvf0 - USER_FULLNAME: JJ - CHAT ID: 41072934
2023-05-14 13:07:37,767 - telegram.ext.dispatcher - ERROR - No error handlers are registered, logging exception.
Traceback (most recent call last):
  File "/home/marta/.local/lib/python3.8/site-packages/telegram/ext/dispatcher.py", line 555, in process_update
    handler.handle_update(update, self, check, context)
  File "/home/marta/.local/lib/python3.8/site-packages/telegram/ext/handler.py", line 198, in handle_update
    return self.callback(update, context)
  File "/home/marta/Proyectos/lverbobot/lverbobot.py", line 230, in respuesta
    if (respuesta == context.user_data['respuestacorrecta_texto']):
KeyError: 'respuestacorrecta_texto'
2023-05-14 13:07:47,858 - root - INFO -  - CMD: DIVERBO - USER_ID: 41072934 - USERNAME: jjvf0 - USER_FULLNAME: JJ - CHAT ID: 41072934
2023-05-14 13:08:02,393 - root - INFO -  - CMD: DIVERBO - USER_ID: 41072934 - USERNAME: jjvf0 - USER_FULLNAME: JJ - CHAT ID: 41072934
2023-05-14 13:08:17,670 - root - INFO -  - CMD: START - USER_ID: 5605956369 - USERNAME: Kakatuza - USER_FULLNAME: Catu - CHAT ID: 5605956369
2023-05-14 13:08:17,670 - root - INFO -  - CMD: DIVERBO - USER_ID: 5605956369 - USERNAME: Kakatuza - USER_FULLNAME: Catu - CHAT ID: 5605956369
2023-05-14 13:08:17,772 - root - INFO -  - CMD: DIVERBO - USER_ID: 5605956369 - USERNAME: Kakatuza - USER_FULLNAME: Catu - CHAT ID: 5605956369
2023-05-14 13:08:17,928 - root - INFO -  - CMD: DIVERBO - USER_ID: 5605956369 - USERNAME: Kakatuza - USER_FULLNAME: Catu - CHAT ID: 5605956369
2023-05-14 13:08:18,055 - root - INFO -  - CMD: DIVERBO - USER_ID: 5605956369 - USERNAME: Kakatuza - USER_FULLNAME: Catu - CHAT ID: 5605956369
2023-05-14 13:08:18,209 - root - INFO -  - CMD: DITIEMPO - USER_ID: 5605956369 - USERNAME: Kakatuza - USER_FULLNAME: Catu - CHAT ID: 5605956369
2023-05-14 13:08:18,333 - root - INFO -  - CMD: DIVERBO - USER_ID: 5605956369 - USERNAME: Kakatuza - USER_FULLNAME: Catu - CHAT ID: 5605956369
2023-05-14 13:08:18,485 - root - INFO -  - CMD: DITIEMPO - USER_ID: 5605956369 - USERNAME: Kakatuza - USER_FULLNAME: Catu - CHAT ID: 5605956369
2023-05-14 13:08:18,811 - root - INFO -  - CMD: START - USER_ID: 5605956369 - USERNAME: Kakatuza - USER_FULLNAME: Catu - CHAT ID: 5605956369
2023-05-14 13:08:19,073 - root - INFO -  - CMD: START - USER_ID: 5605956369 - USERNAME: Kakatuza - USER_FULLNAME: Catu - CHAT ID: 5605956369
2023-05-14 13:08:36,893 - root - INFO -  - CMD: RESPUESTA - USER_ID: 41072934 - USERNAME: jjvf0 - USER_FULLNAME: JJ - CHAT ID: 41072934
2023-05-14 13:08:36,893 - root - INFO -  - CMD: FALLO - USER_ID: 41072934 - USERNAME: jjvf0 - USER_FULLNAME: JJ - CHAT ID: 41072934
2023-05-14 13:08:45,700 - root - INFO -  - CMD: DIVERBO - USER_ID: 5605956369 - USERNAME: Kakatuza - USER_FULLNAME: Catu - CHAT ID: 5605956369
2023-05-14 13:09:00,093 - root - INFO -  - CMD: RESPUESTA - USER_ID: 41072934 - USERNAME: jjvf0 - USER_FULLNAME: JJ - CHAT ID: 41072934
2023-05-14 13:09:59,053 - root - INFO -  - CMD: RESPUESTA - USER_ID: 5605956369 - USERNAME: Kakatuza - USER_FULLNAME: Catu - CHAT ID: 5605956369
2023-05-14 13:09:59,053 - root - INFO -  - CMD: FALLO - USER_ID: 5605956369 - USERNAME: Kakatuza - USER_FULLNAME: Catu - CHAT ID: 5605956369
2023-05-14 13:10:38,931 - root - INFO -  - CMD: RESPUESTA - USER_ID: 5605956369 - USERNAME: Kakatuza - USER_FULLNAME: Catu - CHAT ID: 5605956369
2023-05-14 13:10:38,931 - root - INFO -  - CMD: FALLO - USER_ID: 5605956369 - USERNAME: Kakatuza - USER_FULLNAME: Catu - CHAT ID: 5605956369
2023-05-14 13:10:47,825 - root - INFO -  - CMD: RESPUESTA - USER_ID: 5605956369 - USERNAME: Kakatuza - USER_FULLNAME: Catu - CHAT ID: 5605956369
2023-05-14 13:11:24,295 - apscheduler.scheduler - INFO - Scheduler started
2023-05-14 13:11:38,912 - root - INFO -  - CMD: DIVERBO - USER_ID: 5605956369 - USERNAME: Kakatuza - USER_FULLNAME: Catu - CHAT ID: 5605956369
2023-05-14 13:12:22,255 - root - INFO -  - CMD: RESPUESTA - USER_ID: 5605956369 - USERNAME: Kakatuza - USER_FULLNAME: Catu - CHAT ID: 5605956369
2023-05-14 13:12:22,255 - root - INFO -  - CMD: ACIERTO - USER_ID: 5605956369 - USERNAME: Kakatuza - USER_FULLNAME: Catu - CHAT ID: 5605956369
2023-05-14 13:12:33,950 - root - INFO -  - CMD: DIVERBO - USER_ID: 5605956369 - USERNAME: Kakatuza - USER_FULLNAME: Catu - CHAT ID: 5605956369
2023-05-14 13:12:59,556 - root - INFO -  - CMD: RESPUESTA - USER_ID: 5605956369 - USERNAME: Kakatuza - USER_FULLNAME: Catu - CHAT ID: 5605956369
2023-05-14 13:12:59,557 - root - INFO -  - CMD: FALLO - USER_ID: 5605956369 - USERNAME: Kakatuza - USER_FULLNAME: Catu - CHAT ID: 5605956369
2023-05-14 13:13:44,054 - root - INFO -  - CMD: RESPUESTA - USER_ID: 5605956369 - USERNAME: Kakatuza - USER_FULLNAME: Catu - CHAT ID: 5605956369
2023-05-14 13:13:44,054 - root - INFO -  - CMD: FALLO - USER_ID: 5605956369 - USERNAME: Kakatuza - USER_FULLNAME: Catu - CHAT ID: 5605956369
2023-05-14 13:13:57,111 - root - INFO -  - CMD: RESPUESTA - USER_ID: 5605956369 - USERNAME: Kakatuza - USER_FULLNAME: Catu - CHAT ID: 5605956369
2023-05-14 13:13:57,111 - root - INFO -  - CMD: FALLO - USER_ID: 5605956369 - USERNAME: Kakatuza - USER_FULLNAME: Catu - CHAT ID: 5605956369
2023-05-14 13:14:05,724 - root - INFO -  - CMD: RESPUESTA - USER_ID: 5605956369 - USERNAME: Kakatuza - USER_FULLNAME: Catu - CHAT ID: 5605956369
2023-05-14 13:14:05,725 - root - INFO -  - CMD: FALLO - USER_ID: 5605956369 - USERNAME: Kakatuza - USER_FULLNAME: Catu - CHAT ID: 5605956369
2023-05-14 13:14:20,327 - apscheduler.scheduler - INFO - Scheduler started
2023-05-14 13:14:42,826 - root - INFO -  - CMD: RESPUESTA - USER_ID: 5605956369 - USERNAME: Kakatuza - USER_FULLNAME: Catu - CHAT ID: 5605956369
2023-05-14 13:14:42,826 - telegram.ext.dispatcher - ERROR - No error handlers are registered, logging exception.
Traceback (most recent call last):
  File "/home/marta/.local/lib/python3.8/site-packages/telegram/ext/dispatcher.py", line 555, in process_update
    handler.handle_update(update, self, check, context)
  File "/home/marta/.local/lib/python3.8/site-packages/telegram/ext/handler.py", line 198, in handle_update
    return self.callback(update, context)
  File "/home/marta/Proyectos/lverbobot/lverbobot.py", line 228, in respuesta
    resultado = context.user_data['respuestacorrecta_texto']
KeyError: 'respuestacorrecta_texto'
2023-05-14 13:15:24,340 - root - INFO -  - CMD: RESPUESTA - USER_ID: 5605956369 - USERNAME: Kakatuza - USER_FULLNAME: Catu - CHAT ID: 5605956369
2023-05-14 13:15:24,341 - telegram.ext.dispatcher - ERROR - No error handlers are registered, logging exception.
Traceback (most recent call last):
  File "/home/marta/.local/lib/python3.8/site-packages/telegram/ext/dispatcher.py", line 555, in process_update
    handler.handle_update(update, self, check, context)
  File "/home/marta/.local/lib/python3.8/site-packages/telegram/ext/handler.py", line 198, in handle_update
    return self.callback(update, context)
  File "/home/marta/Proyectos/lverbobot/lverbobot.py", line 228, in respuesta
    resultado = context.user_data['respuestacorrecta_texto']
KeyError: 'respuestacorrecta_texto'
2023-05-14 13:15:52,143 - root - INFO -  - CMD: DIVERBO - USER_ID: 5605956369 - USERNAME: Kakatuza - USER_FULLNAME: Catu - CHAT ID: 5605956369
2023-05-14 13:15:52,143 - telegram.ext.dispatcher - ERROR - No error handlers are registered, logging exception.
Traceback (most recent call last):
  File "/home/marta/.local/lib/python3.8/site-packages/telegram/ext/dispatcher.py", line 555, in process_update
    handler.handle_update(update, self, check, context)
  File "/home/marta/.local/lib/python3.8/site-packages/telegram/ext/handler.py", line 198, in handle_update
    return self.callback(update, context)
  File "/home/marta/Proyectos/lverbobot/lverbobot.py", line 246, in diverbo
    pregunta_entrada = d_verbos.iloc[aleatorio]
  File "/home/marta/.local/lib/python3.8/site-packages/pandas/core/indexing.py", line 931, in __getitem__
    return self._getitem_axis(maybe_callable, axis=axis)
  File "/home/marta/.local/lib/python3.8/site-packages/pandas/core/indexing.py", line 1566, in _getitem_axis
    self._validate_integer(key, axis)
  File "/home/marta/.local/lib/python3.8/site-packages/pandas/core/indexing.py", line 1500, in _validate_integer
    raise IndexError("single positional indexer is out-of-bounds")
IndexError: single positional indexer is out-of-bounds
2023-05-14 13:16:05,194 - apscheduler.scheduler - INFO - Scheduler started
2023-05-14 13:16:30,557 - root - INFO -  - CMD: DIVERBO - USER_ID: 5605956369 - USERNAME: Kakatuza - USER_FULLNAME: Catu - CHAT ID: 5605956369
2023-05-14 13:16:43,755 - root - INFO -  - CMD: RESPUESTA - USER_ID: 5605956369 - USERNAME: Kakatuza - USER_FULLNAME: Catu - CHAT ID: 5605956369
2023-05-14 13:16:43,755 - root - INFO -  - CMD: ACIERTO - USER_ID: 5605956369 - USERNAME: Kakatuza - USER_FULLNAME: Catu - CHAT ID: 5605956369
2023-05-14 13:16:47,522 - root - INFO -  - CMD: DIVERBO - USER_ID: 5605956369 - USERNAME: Kakatuza - USER_FULLNAME: Catu - CHAT ID: 5605956369
2023-05-14 13:17:32,136 - root - INFO -  - CMD: RESPUESTA - USER_ID: 5605956369 - USERNAME: Kakatuza - USER_FULLNAME: Catu - CHAT ID: 5605956369
2023-05-14 13:17:38,700 - root - INFO -  - CMD: DIVERBO - USER_ID: 5605956369 - USERNAME: Kakatuza - USER_FULLNAME: Catu - CHAT ID: 5605956369
2023-05-14 13:18:03,750 - root - INFO -  - CMD: RESPUESTA - USER_ID: 5605956369 - USERNAME: Kakatuza - USER_FULLNAME: Catu - CHAT ID: 5605956369
2023-05-14 13:18:03,750 - root - INFO -  - CMD: FALLO - USER_ID: 5605956369 - USERNAME: Kakatuza - USER_FULLNAME: Catu - CHAT ID: 5605956369
2023-05-14 13:18:11,049 - root - INFO -  - CMD: RESPUESTA - USER_ID: 5605956369 - USERNAME: Kakatuza - USER_FULLNAME: Catu - CHAT ID: 5605956369
2023-05-14 13:18:11,050 - root - INFO -  - CMD: FALLO - USER_ID: 5605956369 - USERNAME: Kakatuza - USER_FULLNAME: Catu - CHAT ID: 5605956369
2023-05-14 13:18:20,276 - root - INFO -  - CMD: RESPUESTA - USER_ID: 5605956369 - USERNAME: Kakatuza - USER_FULLNAME: Catu - CHAT ID: 5605956369
2023-05-14 13:18:20,276 - root - INFO -  - CMD: ACIERTO - USER_ID: 5605956369 - USERNAME: Kakatuza - USER_FULLNAME: Catu - CHAT ID: 5605956369
2023-05-14 13:19:43,632 - root - INFO -  - CMD: DIVERBO - USER_ID: 5605956369 - USERNAME: Kakatuza - USER_FULLNAME: Catu - CHAT ID: 5605956369
2023-05-14 13:19:43,633 - telegram.ext.dispatcher - ERROR - No error handlers are registered, logging exception.
Traceback (most recent call last):
  File "/home/marta/.local/lib/python3.8/site-packages/telegram/ext/dispatcher.py", line 555, in process_update
    handler.handle_update(update, self, check, context)
  File "/home/marta/.local/lib/python3.8/site-packages/telegram/ext/handler.py", line 198, in handle_update
    return self.callback(update, context)
  File "/home/marta/Proyectos/lverbobot/lverbobot.py", line 250, in diverbo
    verbo = pregunta_entrada['verbo'].upper()
AttributeError: 'float' object has no attribute 'upper'
2023-05-14 13:20:54,813 - root - INFO -  - CMD: DIVERBO - USER_ID: 5605956369 - USERNAME: Kakatuza - USER_FULLNAME: Catu - CHAT ID: 5605956369
2023-05-14 13:22:08,253 - root - INFO -  - CMD: RESPUESTA - USER_ID: 5605956369 - USERNAME: Kakatuza - USER_FULLNAME: Catu - CHAT ID: 5605956369
2023-05-14 13:22:08,253 - root - INFO -  - CMD: FALLO - USER_ID: 5605956369 - USERNAME: Kakatuza - USER_FULLNAME: Catu - CHAT ID: 5605956369
2023-05-14 13:22:14,775 - root - INFO -  - CMD: RESPUESTA - USER_ID: 5605956369 - USERNAME: Kakatuza - USER_FULLNAME: Catu - CHAT ID: 5605956369
2023-05-14 13:22:14,775 - root - INFO -  - CMD: FALLO - USER_ID: 5605956369 - USERNAME: Kakatuza - USER_FULLNAME: Catu - CHAT ID: 5605956369
2023-05-14 13:22:22,802 - root - INFO -  - CMD: RESPUESTA - USER_ID: 5605956369 - USERNAME: Kakatuza - USER_FULLNAME: Catu - CHAT ID: 5605956369
2023-05-14 13:22:22,802 - root - INFO -  - CMD: FALLO - USER_ID: 5605956369 - USERNAME: Kakatuza - USER_FULLNAME: Catu - CHAT ID: 5605956369
2023-05-14 13:22:39,254 - root - INFO -  - CMD: RESPUESTA - USER_ID: 5605956369 - USERNAME: Kakatuza - USER_FULLNAME: Catu - CHAT ID: 5605956369
2023-05-14 13:22:39,254 - root - INFO -  - CMD: FALLO - USER_ID: 5605956369 - USERNAME: Kakatuza - USER_FULLNAME: Catu - CHAT ID: 5605956369
2023-05-14 13:22:45,709 - root - INFO -  - CMD: RESPUESTA - USER_ID: 5605956369 - USERNAME: Kakatuza - USER_FULLNAME: Catu - CHAT ID: 5605956369
2023-05-14 13:22:45,710 - root - INFO -  - CMD: FALLO - USER_ID: 5605956369 - USERNAME: Kakatuza - USER_FULLNAME: Catu - CHAT ID: 5605956369
2023-05-14 13:22:51,315 - root - INFO -  - CMD: RESPUESTA - USER_ID: 5605956369 - USERNAME: Kakatuza - USER_FULLNAME: Catu - CHAT ID: 5605956369
2023-05-14 13:24:01,975 - root - INFO -  - CMD: DIVERBO - USER_ID: 5605956369 - USERNAME: Kakatuza - USER_FULLNAME: Catu - CHAT ID: 5605956369
2023-05-14 13:24:27,688 - root - INFO -  - CMD: RESPUESTA - USER_ID: 5605956369 - USERNAME: Kakatuza - USER_FULLNAME: Catu - CHAT ID: 5605956369
2023-05-14 13:24:27,689 - root - INFO -  - CMD: FALLO - USER_ID: 5605956369 - USERNAME: Kakatuza - USER_FULLNAME: Catu - CHAT ID: 5605956369
2023-05-14 13:24:37,419 - root - INFO -  - CMD: RESPUESTA - USER_ID: 5605956369 - USERNAME: Kakatuza - USER_FULLNAME: Catu - CHAT ID: 5605956369
2023-05-14 13:24:37,419 - root - INFO -  - CMD: FALLO - USER_ID: 5605956369 - USERNAME: Kakatuza - USER_FULLNAME: Catu - CHAT ID: 5605956369
2023-05-14 13:24:45,730 - root - INFO -  - CMD: RESPUESTA - USER_ID: 5605956369 - USERNAME: Kakatuza - USER_FULLNAME: Catu - CHAT ID: 5605956369
2023-05-14 13:24:56,501 - root - INFO -  - CMD: DIVERBO - USER_ID: 5605956369 - USERNAME: Kakatuza - USER_FULLNAME: Catu - CHAT ID: 5605956369
2023-05-14 13:25:20,445 - root - INFO -  - CMD: RESPUESTA - USER_ID: 5605956369 - USERNAME: Kakatuza - USER_FULLNAME: Catu - CHAT ID: 5605956369
2023-05-14 13:25:20,446 - root - INFO -  - CMD: FALLO - USER_ID: 5605956369 - USERNAME: Kakatuza - USER_FULLNAME: Catu - CHAT ID: 5605956369
2023-05-14 13:25:26,782 - root - INFO -  - CMD: RESPUESTA - USER_ID: 5605956369 - USERNAME: Kakatuza - USER_FULLNAME: Catu - CHAT ID: 5605956369
2023-05-14 13:25:26,782 - root - INFO -  - CMD: ACIERTO - USER_ID: 5605956369 - USERNAME: Kakatuza - USER_FULLNAME: Catu - CHAT ID: 5605956369
2023-05-14 13:26:15,103 - root - INFO -  - CMD: DIVERBO - USER_ID: 5605956369 - USERNAME: Kakatuza - USER_FULLNAME: Catu - CHAT ID: 5605956369
2023-05-14 13:27:05,059 - root - INFO -  - CMD: RESPUESTA - USER_ID: 5605956369 - USERNAME: Kakatuza - USER_FULLNAME: Catu - CHAT ID: 5605956369
2023-05-14 13:27:05,059 - root - INFO -  - CMD: FALLO - USER_ID: 5605956369 - USERNAME: Kakatuza - USER_FULLNAME: Catu - CHAT ID: 5605956369
2023-05-14 13:27:11,637 - root - INFO -  - CMD: RESPUESTA - USER_ID: 5605956369 - USERNAME: Kakatuza - USER_FULLNAME: Catu - CHAT ID: 5605956369
2023-05-14 13:27:11,637 - root - INFO -  - CMD: FALLO - USER_ID: 5605956369 - USERNAME: Kakatuza - USER_FULLNAME: Catu - CHAT ID: 5605956369
2023-05-14 13:27:21,778 - root - INFO -  - CMD: RESPUESTA - USER_ID: 5605956369 - USERNAME: Kakatuza - USER_FULLNAME: Catu - CHAT ID: 5605956369
2023-05-14 13:27:21,778 - root - INFO -  - CMD: FALLO - USER_ID: 5605956369 - USERNAME: Kakatuza - USER_FULLNAME: Catu - CHAT ID: 5605956369
2023-05-14 13:27:27,854 - root - INFO -  - CMD: RESPUESTA - USER_ID: 5605956369 - USERNAME: Kakatuza - USER_FULLNAME: Catu - CHAT ID: 5605956369
2023-05-14 13:27:27,854 - root - INFO -  - CMD: FALLO - USER_ID: 5605956369 - USERNAME: Kakatuza - USER_FULLNAME: Catu - CHAT ID: 5605956369
2023-05-14 13:27:36,241 - apscheduler.scheduler - INFO - Scheduler started
2023-05-14 13:27:49,159 - root - INFO -  - CMD: DIVERBO - USER_ID: 5605956369 - USERNAME: Kakatuza - USER_FULLNAME: Catu - CHAT ID: 5605956369
2023-05-14 13:28:11,682 - root - INFO -  - CMD: RESPUESTA - USER_ID: 5605956369 - USERNAME: Kakatuza - USER_FULLNAME: Catu - CHAT ID: 5605956369
2023-05-14 13:28:11,682 - root - INFO -  - CMD: FALLO - USER_ID: 5605956369 - USERNAME: Kakatuza - USER_FULLNAME: Catu - CHAT ID: 5605956369
2023-05-14 13:28:35,913 - root - INFO -  - CMD: RESPUESTA - USER_ID: 5605956369 - USERNAME: Kakatuza - USER_FULLNAME: Catu - CHAT ID: 5605956369
2023-05-14 13:31:40,692 - apscheduler.scheduler - INFO - Scheduler started
2023-05-14 13:31:47,736 - root - INFO -  - CMD: DIVERBO - USER_ID: 5605956369 - USERNAME: Kakatuza - USER_FULLNAME: Catu - CHAT ID: 5605956369
2023-05-14 13:32:37,469 - root - INFO -  - CMD: RESPUESTA - USER_ID: 5605956369 - USERNAME: Kakatuza - USER_FULLNAME: Catu - CHAT ID: 5605956369
2023-05-14 13:32:37,469 - root - INFO -  - CMD: FALLO - USER_ID: 5605956369 - USERNAME: Kakatuza - USER_FULLNAME: Catu - CHAT ID: 5605956369
2023-05-14 13:32:54,168 - root - INFO -  - CMD: RESPUESTA - USER_ID: 5605956369 - USERNAME: Kakatuza - USER_FULLNAME: Catu - CHAT ID: 5605956369
2023-05-14 13:33:06,510 - root - INFO -  - CMD: DIVERBO - USER_ID: 5605956369 - USERNAME: Kakatuza - USER_FULLNAME: Catu - CHAT ID: 5605956369
2023-05-14 13:33:33,164 - root - INFO -  - CMD: RESPUESTA - USER_ID: 5605956369 - USERNAME: Kakatuza - USER_FULLNAME: Catu - CHAT ID: 5605956369
2023-05-14 13:33:33,164 - root - INFO -  - CMD: FALLO - USER_ID: 5605956369 - USERNAME: Kakatuza - USER_FULLNAME: Catu - CHAT ID: 5605956369
2023-05-14 13:33:43,539 - root - INFO -  - CMD: RESPUESTA - USER_ID: 5605956369 - USERNAME: Kakatuza - USER_FULLNAME: Catu - CHAT ID: 5605956369
2023-05-14 13:33:43,539 - root - INFO -  - CMD: ACIERTO - USER_ID: 5605956369 - USERNAME: Kakatuza - USER_FULLNAME: Catu - CHAT ID: 5605956369
2023-05-14 13:33:51,109 - root - INFO -  - CMD: DITIEMPO - USER_ID: 5605956369 - USERNAME: Kakatuza - USER_FULLNAME: Catu - CHAT ID: 5605956369
2023-05-14 13:34:02,621 - root - INFO -  - CMD: RESPUESTA - USER_ID: 5605956369 - USERNAME: Kakatuza - USER_FULLNAME: Catu - CHAT ID: 5605956369
2023-05-14 13:34:02,621 - root - INFO -  - CMD: FALLO - USER_ID: 5605956369 - USERNAME: Kakatuza - USER_FULLNAME: Catu - CHAT ID: 5605956369
2023-05-14 13:34:06,219 - root - INFO -  - CMD: RESPUESTA - USER_ID: 5605956369 - USERNAME: Kakatuza - USER_FULLNAME: Catu - CHAT ID: 5605956369
2023-05-14 13:34:06,220 - root - INFO -  - CMD: FALLO - USER_ID: 5605956369 - USERNAME: Kakatuza - USER_FULLNAME: Catu - CHAT ID: 5605956369
2023-05-14 13:34:13,094 - root - INFO -  - CMD: RESPUESTA - USER_ID: 5605956369 - USERNAME: Kakatuza - USER_FULLNAME: Catu - CHAT ID: 5605956369
2023-05-14 13:34:23,119 - root - INFO -  - CMD: DIVERBO - USER_ID: 5605956369 - USERNAME: Kakatuza - USER_FULLNAME: Catu - CHAT ID: 5605956369
2023-05-14 13:34:44,852 - root - INFO -  - CMD: RESPUESTA - USER_ID: 5605956369 - USERNAME: Kakatuza - USER_FULLNAME: Catu - CHAT ID: 5605956369
2023-05-14 13:34:44,852 - root - INFO -  - CMD: FALLO - USER_ID: 5605956369 - USERNAME: Kakatuza - USER_FULLNAME: Catu - CHAT ID: 5605956369
2023-05-14 13:35:00,684 - root - INFO -  - CMD: RESPUESTA - USER_ID: 5605956369 - USERNAME: Kakatuza - USER_FULLNAME: Catu - CHAT ID: 5605956369
2023-05-14 13:36:53,481 - root - INFO -  - CMD: DIVERBO - USER_ID: 5605956369 - USERNAME: Kakatuza - USER_FULLNAME: Catu - CHAT ID: 5605956369
2023-05-14 13:37:04,976 - root - INFO -  - CMD: RESPUESTA - USER_ID: 5605956369 - USERNAME: Kakatuza - USER_FULLNAME: Catu - CHAT ID: 5605956369
2023-05-14 13:37:04,977 - root - INFO -  - CMD: ACIERTO - USER_ID: 5605956369 - USERNAME: Kakatuza - USER_FULLNAME: Catu - CHAT ID: 5605956369
2023-05-14 13:38:06,829 - root - INFO -  - CMD: DIVERBO - USER_ID: 5605956369 - USERNAME: Kakatuza - USER_FULLNAME: Catu - CHAT ID: 5605956369
2023-05-14 13:38:40,140 - apscheduler.scheduler - INFO - Scheduler started
2023-05-14 13:38:52,205 - apscheduler.scheduler - INFO - Scheduler started
2023-05-14 13:39:02,541 - root - INFO -  - CMD: RESPUESTA - USER_ID: 5605956369 - USERNAME: Kakatuza - USER_FULLNAME: Catu - CHAT ID: 5605956369
2023-05-14 13:39:02,541 - telegram.ext.dispatcher - ERROR - No error handlers are registered, logging exception.
Traceback (most recent call last):
  File "/home/marta/.local/lib/python3.8/site-packages/telegram/ext/dispatcher.py", line 555, in process_update
    handler.handle_update(update, self, check, context)
  File "/home/marta/.local/lib/python3.8/site-packages/telegram/ext/handler.py", line 198, in handle_update
    return self.callback(update, context)
  File "/home/marta/Proyectos/lverbobot/lverbobot.py", line 230, in respuesta
    if (respuesta == context.user_data['respuestacorrecta_texto']):
KeyError: 'respuestacorrecta_texto'
2023-05-14 13:39:06,054 - root - INFO -  - CMD: DIVERBO - USER_ID: 5605956369 - USERNAME: Kakatuza - USER_FULLNAME: Catu - CHAT ID: 5605956369
2023-05-14 13:39:58,223 - apscheduler.scheduler - INFO - Scheduler started
2023-05-14 13:40:09,529 - root - INFO -  - CMD: DIVERBO - USER_ID: 5605956369 - USERNAME: Kakatuza - USER_FULLNAME: Catu - CHAT ID: 5605956369
2023-05-14 13:40:26,555 - root - INFO -  - CMD: RESPUESTA - USER_ID: 5605956369 - USERNAME: Kakatuza - USER_FULLNAME: Catu - CHAT ID: 5605956369
2023-05-14 13:40:26,555 - root - INFO -  - CMD: FALLO - USER_ID: 5605956369 - USERNAME: Kakatuza - USER_FULLNAME: Catu - CHAT ID: 5605956369
2023-05-14 13:40:52,724 - apscheduler.scheduler - INFO - Scheduler started
2023-05-14 13:41:07,991 - root - INFO -  - CMD: DIVERBO - USER_ID: 5605956369 - USERNAME: Kakatuza - USER_FULLNAME: Catu - CHAT ID: 5605956369
2023-05-14 13:41:33,405 - root - INFO -  - CMD: RESPUESTA - USER_ID: 5605956369 - USERNAME: Kakatuza - USER_FULLNAME: Catu - CHAT ID: 5605956369
2023-05-14 13:41:33,405 - root - INFO -  - CMD: ACIERTO - USER_ID: 5605956369 - USERNAME: Kakatuza - USER_FULLNAME: Catu - CHAT ID: 5605956369
2023-05-14 13:41:39,920 - root - INFO -  - CMD: DIVERBO - USER_ID: 5605956369 - USERNAME: Kakatuza - USER_FULLNAME: Catu - CHAT ID: 5605956369
2023-05-14 13:42:05,093 - root - INFO -  - CMD: RESPUESTA - USER_ID: 5605956369 - USERNAME: Kakatuza - USER_FULLNAME: Catu - CHAT ID: 5605956369
2023-05-14 13:42:05,093 - root - INFO -  - CMD: ACIERTO - USER_ID: 5605956369 - USERNAME: Kakatuza - USER_FULLNAME: Catu - CHAT ID: 5605956369
2023-05-14 13:42:08,935 - root - INFO -  - CMD: DIVERBO - USER_ID: 5605956369 - USERNAME: Kakatuza - USER_FULLNAME: Catu - CHAT ID: 5605956369
2023-05-14 13:42:23,782 - root - INFO -  - CMD: RESPUESTA - USER_ID: 5605956369 - USERNAME: Kakatuza - USER_FULLNAME: Catu - CHAT ID: 5605956369
2023-05-14 13:42:28,729 - root - INFO -  - CMD: DIVERBO - USER_ID: 5605956369 - USERNAME: Kakatuza - USER_FULLNAME: Catu - CHAT ID: 5605956369
2023-05-14 13:42:53,671 - root - INFO -  - CMD: RESPUESTA - USER_ID: 5605956369 - USERNAME: Kakatuza - USER_FULLNAME: Catu - CHAT ID: 5605956369
2023-05-14 13:42:53,671 - root - INFO -  - CMD: ACIERTO - USER_ID: 5605956369 - USERNAME: Kakatuza - USER_FULLNAME: Catu - CHAT ID: 5605956369
2023-05-14 13:43:02,061 - root - INFO -  - CMD: DIVERBO - USER_ID: 5605956369 - USERNAME: Kakatuza - USER_FULLNAME: Catu - CHAT ID: 5605956369
2023-05-14 13:43:02,062 - telegram.ext.dispatcher - ERROR - No error handlers are registered, logging exception.
Traceback (most recent call last):
  File "/home/marta/.local/lib/python3.8/site-packages/telegram/ext/dispatcher.py", line 555, in process_update
    handler.handle_update(update, self, check, context)
  File "/home/marta/.local/lib/python3.8/site-packages/telegram/ext/handler.py", line 198, in handle_update
    return self.callback(update, context)
  File "/home/marta/Proyectos/lverbobot/lverbobot.py", line 246, in diverbo
    pregunta_entrada = d_verbos.iloc[aleatorio]
  File "/home/marta/.local/lib/python3.8/site-packages/pandas/core/indexing.py", line 931, in __getitem__
    return self._getitem_axis(maybe_callable, axis=axis)
  File "/home/marta/.local/lib/python3.8/site-packages/pandas/core/indexing.py", line 1566, in _getitem_axis
    self._validate_integer(key, axis)
  File "/home/marta/.local/lib/python3.8/site-packages/pandas/core/indexing.py", line 1500, in _validate_integer
    raise IndexError("single positional indexer is out-of-bounds")
IndexError: single positional indexer is out-of-bounds
2023-05-14 13:43:11,966 - root - INFO -  - CMD: DIVERBO - USER_ID: 5605956369 - USERNAME: Kakatuza - USER_FULLNAME: Catu - CHAT ID: 5605956369
2023-05-14 13:44:24,461 - root - INFO -  - CMD: RESPUESTA - USER_ID: 5605956369 - USERNAME: Kakatuza - USER_FULLNAME: Catu - CHAT ID: 5605956369
2023-05-14 13:44:24,461 - root - INFO -  - CMD: ACIERTO - USER_ID: 5605956369 - USERNAME: Kakatuza - USER_FULLNAME: Catu - CHAT ID: 5605956369
2023-05-14 13:44:30,393 - root - INFO -  - CMD: DIVERBO - USER_ID: 5605956369 - USERNAME: Kakatuza - USER_FULLNAME: Catu - CHAT ID: 5605956369
2023-05-14 13:45:17,688 - root - INFO -  - CMD: RESPUESTA - USER_ID: 5605956369 - USERNAME: Kakatuza - USER_FULLNAME: Catu - CHAT ID: 5605956369
2023-05-14 13:45:17,689 - root - INFO -  - CMD: ACIERTO - USER_ID: 5605956369 - USERNAME: Kakatuza - USER_FULLNAME: Catu - CHAT ID: 5605956369
2023-05-14 13:45:24,181 - root - INFO -  - CMD: DIVERBO - USER_ID: 5605956369 - USERNAME: Kakatuza - USER_FULLNAME: Catu - CHAT ID: 5605956369
2023-05-14 13:45:26,933 - root - INFO -  - CMD: RESPUESTA - USER_ID: 5605956369 - USERNAME: Kakatuza - USER_FULLNAME: Catu - CHAT ID: 5605956369
2023-05-14 13:45:26,934 - root - INFO -  - CMD: FALLO - USER_ID: 5605956369 - USERNAME: Kakatuza - USER_FULLNAME: Catu - CHAT ID: 5605956369
2023-05-14 13:46:27,834 - apscheduler.scheduler - INFO - Scheduler started
2023-05-14 13:46:28,681 - root - INFO -  - CMD: DIVERBO - USER_ID: 5605956369 - USERNAME: Kakatuza - USER_FULLNAME: Catu - CHAT ID: 5605956369
2023-05-14 13:46:41,321 - root - INFO -  - CMD: RESPUESTA - USER_ID: 5605956369 - USERNAME: Kakatuza - USER_FULLNAME: Catu - CHAT ID: 5605956369
2023-05-14 13:46:41,321 - root - INFO -  - CMD: ACIERTO - USER_ID: 5605956369 - USERNAME: Kakatuza - USER_FULLNAME: Catu - CHAT ID: 5605956369
2023-05-14 13:49:38,403 - root - INFO -  - CMD: DIVERBO - USER_ID: 5605956369 - USERNAME: Kakatuza - USER_FULLNAME: Catu - CHAT ID: 5605956369
2023-05-14 13:50:27,550 - root - INFO -  - CMD: DIVERBO - USER_ID: 5605956369 - USERNAME: Kakatuza - USER_FULLNAME: Catu - CHAT ID: 5605956369
2023-05-14 13:57:29,647 - apscheduler.scheduler - INFO - Scheduler started
2023-05-14 13:59:34,895 - root - INFO -  - CMD: DIVERBO - USER_ID: 28097231 - USERNAME: martatorrebarbeito - USER_FULLNAME: Marta - CHAT ID: 28097231
2023-05-14 14:01:29,131 - root - INFO -  - CMD: RESPUESTA - USER_ID: 28097231 - USERNAME: martatorrebarbeito - USER_FULLNAME: Marta - CHAT ID: 28097231
2023-05-14 14:01:29,131 - root - INFO -  - CMD: ACIERTO - USER_ID: 28097231 - USERNAME: martatorrebarbeito - USER_FULLNAME: Marta - CHAT ID: 28097231
2023-05-14 14:01:50,558 - root - INFO -  - CMD: DIVERBO - USER_ID: 28097231 - USERNAME: martatorrebarbeito - USER_FULLNAME: Marta - CHAT ID: 28097231
2023-05-14 14:02:15,444 - root - INFO -  - CMD: RESPUESTA - USER_ID: 28097231 - USERNAME: martatorrebarbeito - USER_FULLNAME: Marta - CHAT ID: 28097231
2023-05-14 14:02:15,445 - root - INFO -  - CMD: FALLO - USER_ID: 28097231 - USERNAME: martatorrebarbeito - USER_FULLNAME: Marta - CHAT ID: 28097231
2023-05-14 14:02:34,615 - root - INFO -  - CMD: RESPUESTA - USER_ID: 28097231 - USERNAME: martatorrebarbeito - USER_FULLNAME: Marta - CHAT ID: 28097231
2023-05-14 14:02:34,615 - root - INFO -  - CMD: FALLO - USER_ID: 28097231 - USERNAME: martatorrebarbeito - USER_FULLNAME: Marta - CHAT ID: 28097231
2023-05-14 14:02:38,797 - root - INFO -  - CMD: RESPUESTA - USER_ID: 28097231 - USERNAME: martatorrebarbeito - USER_FULLNAME: Marta - CHAT ID: 28097231
2023-05-14 14:02:38,797 - root - INFO -  - CMD: FALLO - USER_ID: 28097231 - USERNAME: martatorrebarbeito - USER_FULLNAME: Marta - CHAT ID: 28097231
2023-05-14 14:02:42,239 - root - INFO -  - CMD: RESPUESTA - USER_ID: 28097231 - USERNAME: martatorrebarbeito - USER_FULLNAME: Marta - CHAT ID: 28097231
2023-05-14 14:02:42,239 - root - INFO -  - CMD: FALLO - USER_ID: 28097231 - USERNAME: martatorrebarbeito - USER_FULLNAME: Marta - CHAT ID: 28097231
2023-05-14 14:02:45,134 - root - INFO -  - CMD: RESPUESTA - USER_ID: 28097231 - USERNAME: martatorrebarbeito - USER_FULLNAME: Marta - CHAT ID: 28097231
2023-05-14 14:02:45,134 - root - INFO -  - CMD: FALLO - USER_ID: 28097231 - USERNAME: martatorrebarbeito - USER_FULLNAME: Marta - CHAT ID: 28097231
2023-05-14 14:02:48,478 - root - INFO -  - CMD: RESPUESTA - USER_ID: 28097231 - USERNAME: martatorrebarbeito - USER_FULLNAME: Marta - CHAT ID: 28097231
2023-05-14 14:02:48,478 - root - INFO -  - CMD: FALLO - USER_ID: 28097231 - USERNAME: martatorrebarbeito - USER_FULLNAME: Marta - CHAT ID: 28097231
2023-05-14 14:02:49,780 - root - INFO -  - CMD: RESPUESTA - USER_ID: 28097231 - USERNAME: martatorrebarbeito - USER_FULLNAME: Marta - CHAT ID: 28097231
2023-05-14 14:02:49,780 - root - INFO -  - CMD: FALLO - USER_ID: 28097231 - USERNAME: martatorrebarbeito - USER_FULLNAME: Marta - CHAT ID: 28097231
2023-05-14 14:02:50,747 - root - INFO -  - CMD: RESPUESTA - USER_ID: 28097231 - USERNAME: martatorrebarbeito - USER_FULLNAME: Marta - CHAT ID: 28097231
2023-05-14 14:02:50,748 - root - INFO -  - CMD: FALLO - USER_ID: 28097231 - USERNAME: martatorrebarbeito - USER_FULLNAME: Marta - CHAT ID: 28097231
2023-05-14 14:02:51,593 - root - INFO -  - CMD: RESPUESTA - USER_ID: 28097231 - USERNAME: martatorrebarbeito - USER_FULLNAME: Marta - CHAT ID: 28097231
2023-05-14 14:02:51,593 - root - INFO -  - CMD: FALLO - USER_ID: 28097231 - USERNAME: martatorrebarbeito - USER_FULLNAME: Marta - CHAT ID: 28097231
2023-05-14 14:02:52,265 - root - INFO -  - CMD: RESPUESTA - USER_ID: 28097231 - USERNAME: martatorrebarbeito - USER_FULLNAME: Marta - CHAT ID: 28097231
2023-05-14 14:02:52,266 - root - INFO -  - CMD: FALLO - USER_ID: 28097231 - USERNAME: martatorrebarbeito - USER_FULLNAME: Marta - CHAT ID: 28097231
2023-05-14 14:02:52,742 - root - INFO -  - CMD: RESPUESTA - USER_ID: 28097231 - USERNAME: martatorrebarbeito - USER_FULLNAME: Marta - CHAT ID: 28097231
2023-05-14 14:02:52,742 - root - INFO -  - CMD: FALLO - USER_ID: 28097231 - USERNAME: martatorrebarbeito - USER_FULLNAME: Marta - CHAT ID: 28097231
2023-05-14 14:02:53,900 - root - INFO -  - CMD: RESPUESTA - USER_ID: 28097231 - USERNAME: martatorrebarbeito - USER_FULLNAME: Marta - CHAT ID: 28097231
2023-05-14 14:02:53,901 - root - INFO -  - CMD: FALLO - USER_ID: 28097231 - USERNAME: martatorrebarbeito - USER_FULLNAME: Marta - CHAT ID: 28097231
2023-05-14 14:02:57,651 - root - INFO -  - CMD: RESPUESTA - USER_ID: 28097231 - USERNAME: martatorrebarbeito - USER_FULLNAME: Marta - CHAT ID: 28097231
2023-05-14 14:02:57,651 - root - INFO -  - CMD: FALLO - USER_ID: 28097231 - USERNAME: martatorrebarbeito - USER_FULLNAME: Marta - CHAT ID: 28097231
2023-05-14 14:03:02,571 - root - INFO -  - CMD: RESPUESTA - USER_ID: 28097231 - USERNAME: martatorrebarbeito - USER_FULLNAME: Marta - CHAT ID: 28097231
2023-05-14 14:03:02,571 - root - INFO -  - CMD: FALLO - USER_ID: 28097231 - USERNAME: martatorrebarbeito - USER_FULLNAME: Marta - CHAT ID: 28097231
2023-05-14 14:03:14,031 - root - INFO -  - CMD: RESPUESTA - USER_ID: 28097231 - USERNAME: martatorrebarbeito - USER_FULLNAME: Marta - CHAT ID: 28097231
2023-05-14 14:03:23,376 - root - INFO -  - CMD: DITIEMPO - USER_ID: 28097231 - USERNAME: martatorrebarbeito - USER_FULLNAME: Marta - CHAT ID: 28097231
2023-05-14 14:03:44,309 - root - INFO -  - CMD: RESPUESTA - USER_ID: 28097231 - USERNAME: martatorrebarbeito - USER_FULLNAME: Marta - CHAT ID: 28097231
2023-05-14 14:03:44,309 - root - INFO -  - CMD: FALLO - USER_ID: 28097231 - USERNAME: martatorrebarbeito - USER_FULLNAME: Marta - CHAT ID: 28097231
2023-05-14 14:03:51,733 - root - INFO -  - CMD: RESPUESTA - USER_ID: 28097231 - USERNAME: martatorrebarbeito - USER_FULLNAME: Marta - CHAT ID: 28097231
2023-05-14 14:03:51,733 - root - INFO -  - CMD: FALLO - USER_ID: 28097231 - USERNAME: martatorrebarbeito - USER_FULLNAME: Marta - CHAT ID: 28097231
2023-05-14 14:04:05,851 - root - INFO -  - CMD: DIVERBO - USER_ID: 28097231 - USERNAME: martatorrebarbeito - USER_FULLNAME: Marta - CHAT ID: 28097231
2023-05-14 14:04:21,749 - root - INFO -  - CMD: DIVERBO - USER_ID: 28097231 - USERNAME: martatorrebarbeito - USER_FULLNAME: Marta - CHAT ID: 28097231
2023-05-14 14:05:17,156 - root - INFO -  - CMD: DIVERBO - USER_ID: 28097231 - USERNAME: martatorrebarbeito - USER_FULLNAME: Marta - CHAT ID: 28097231
2023-05-14 14:39:39,131 - telegram.vendor.ptb_urllib3.urllib3.connectionpool - WARNING - Retrying (Retry(total=2, connect=None, read=None, redirect=None)) after connection broken by 'NewConnectionError('<telegram.vendor.ptb_urllib3.urllib3.connection.VerifiedHTTPSConnection object at 0x7f2d70fecac0>: Failed to establish a new connection: [Errno 101] Network is unreachable')': /bot6016703766:AAE0sJbP7mN6JA9HGsWHVEBB3iwgJOFtKVM/getUpdates
2023-05-14 14:39:39,132 - telegram.vendor.ptb_urllib3.urllib3.connectionpool - WARNING - Retrying (Retry(total=1, connect=None, read=None, redirect=None)) after connection broken by 'NewConnectionError('<telegram.vendor.ptb_urllib3.urllib3.connection.VerifiedHTTPSConnection object at 0x7f2d70fecaf0>: Failed to establish a new connection: [Errno 101] Network is unreachable')': /bot6016703766:AAE0sJbP7mN6JA9HGsWHVEBB3iwgJOFtKVM/getUpdates
2023-05-14 14:39:39,132 - telegram.vendor.ptb_urllib3.urllib3.connectionpool - WARNING - Retrying (Retry(total=0, connect=None, read=None, redirect=None)) after connection broken by 'NewConnectionError('<telegram.vendor.ptb_urllib3.urllib3.connection.VerifiedHTTPSConnection object at 0x7f2d7075d040>: Failed to establish a new connection: [Errno 101] Network is unreachable')': /bot6016703766:AAE0sJbP7mN6JA9HGsWHVEBB3iwgJOFtKVM/getUpdates
2023-05-14 14:39:39,133 - telegram.ext.updater - ERROR - Error while getting Updates: urllib3 HTTPError HTTPSConnectionPool(host='api.telegram.org', port=443): Max retries exceeded with url: /bot6016703766:AAE0sJbP7mN6JA9HGsWHVEBB3iwgJOFtKVM/getUpdates (Caused by NewConnectionError('<telegram.vendor.ptb_urllib3.urllib3.connection.VerifiedHTTPSConnection object at 0x7f2d7075d190>: Failed to establish a new connection: [Errno 101] Network is unreachable'))
2023-05-14 14:39:39,133 - telegram.ext.dispatcher - ERROR - No error handlers are registered, logging exception.
Traceback (most recent call last):
  File "/home/marta/.local/lib/python3.8/site-packages/telegram/vendor/ptb_urllib3/urllib3/connection.py", line 140, in _new_conn
    conn = connection.create_connection(
  File "/home/marta/.local/lib/python3.8/site-packages/telegram/vendor/ptb_urllib3/urllib3/util/connection.py", line 83, in create_connection
    raise err
  File "/home/marta/.local/lib/python3.8/site-packages/telegram/vendor/ptb_urllib3/urllib3/util/connection.py", line 73, in create_connection
    sock.connect(sa)
OSError: [Errno 101] Network is unreachable

During handling of the above exception, another exception occurred:

Traceback (most recent call last):
  File "/home/marta/.local/lib/python3.8/site-packages/telegram/vendor/ptb_urllib3/urllib3/connectionpool.py", line 614, in urlopen
    httplib_response = self._make_request(conn, method, url,
  File "/home/marta/.local/lib/python3.8/site-packages/telegram/vendor/ptb_urllib3/urllib3/connectionpool.py", line 360, in _make_request
    self._validate_conn(conn)
  File "/home/marta/.local/lib/python3.8/site-packages/telegram/vendor/ptb_urllib3/urllib3/connectionpool.py", line 857, in _validate_conn
    super(HTTPSConnectionPool, self)._validate_conn(conn)
  File "/home/marta/.local/lib/python3.8/site-packages/telegram/vendor/ptb_urllib3/urllib3/connectionpool.py", line 289, in _validate_conn
    conn.connect()
  File "/home/marta/.local/lib/python3.8/site-packages/telegram/vendor/ptb_urllib3/urllib3/connection.py", line 284, in connect
    conn = self._new_conn()
  File "/home/marta/.local/lib/python3.8/site-packages/telegram/vendor/ptb_urllib3/urllib3/connection.py", line 149, in _new_conn
    raise NewConnectionError(
telegram.vendor.ptb_urllib3.urllib3.exceptions.NewConnectionError: <telegram.vendor.ptb_urllib3.urllib3.connection.VerifiedHTTPSConnection object at 0x7f2d7075d190>: Failed to establish a new connection: [Errno 101] Network is unreachable

During handling of the above exception, another exception occurred:

Traceback (most recent call last):
  File "/home/marta/.local/lib/python3.8/site-packages/telegram/utils/request.py", line 259, in _request_wrapper
    resp = self._con_pool.request(*args, **kwargs)
  File "/home/marta/.local/lib/python3.8/site-packages/telegram/vendor/ptb_urllib3/urllib3/request.py", line 68, in request
    return self.request_encode_body(method, url, fields=fields,
  File "/home/marta/.local/lib/python3.8/site-packages/telegram/vendor/ptb_urllib3/urllib3/request.py", line 148, in request_encode_body
    return self.urlopen(method, url, **extra_kw)
  File "/home/marta/.local/lib/python3.8/site-packages/telegram/vendor/ptb_urllib3/urllib3/poolmanager.py", line 244, in urlopen
    response = conn.urlopen(method, u.request_uri, **kw)
  File "/home/marta/.local/lib/python3.8/site-packages/telegram/vendor/ptb_urllib3/urllib3/connectionpool.py", line 691, in urlopen
    return self.urlopen(method, url, body, headers, retries,
  File "/home/marta/.local/lib/python3.8/site-packages/telegram/vendor/ptb_urllib3/urllib3/connectionpool.py", line 691, in urlopen
    return self.urlopen(method, url, body, headers, retries,
  File "/home/marta/.local/lib/python3.8/site-packages/telegram/vendor/ptb_urllib3/urllib3/connectionpool.py", line 691, in urlopen
    return self.urlopen(method, url, body, headers, retries,
  File "/home/marta/.local/lib/python3.8/site-packages/telegram/vendor/ptb_urllib3/urllib3/connectionpool.py", line 665, in urlopen
    retries = retries.increment(method, url, error=e, _pool=self,
  File "/home/marta/.local/lib/python3.8/site-packages/telegram/vendor/ptb_urllib3/urllib3/util/retry.py", line 376, in increment
    raise MaxRetryError(_pool, url, error or ResponseError(cause))
telegram.vendor.ptb_urllib3.urllib3.exceptions.MaxRetryError: HTTPSConnectionPool(host='api.telegram.org', port=443): Max retries exceeded with url: /bot6016703766:AAE0sJbP7mN6JA9HGsWHVEBB3iwgJOFtKVM/getUpdates (Caused by NewConnectionError('<telegram.vendor.ptb_urllib3.urllib3.connection.VerifiedHTTPSConnection object at 0x7f2d7075d190>: Failed to establish a new connection: [Errno 101] Network is unreachable'))

The above exception was the direct cause of the following exception:

Traceback (most recent call last):
  File "/home/marta/.local/lib/python3.8/site-packages/telegram/ext/updater.py", line 646, in _network_loop_retry
    if not action_cb():
  File "/home/marta/.local/lib/python3.8/site-packages/telegram/ext/updater.py", line 597, in polling_action_cb
    updates = self.bot.get_updates(
  File "/home/marta/.local/lib/python3.8/site-packages/telegram/ext/extbot.py", line 222, in get_updates
    updates = super().get_updates(
  File "/home/marta/.local/lib/python3.8/site-packages/telegram/bot.py", line 130, in decorator
    result = func(*args, **kwargs)
  File "/home/marta/.local/lib/python3.8/site-packages/telegram/bot.py", line 2945, in get_updates
    self._post(
  File "/home/marta/.local/lib/python3.8/site-packages/telegram/bot.py", line 295, in _post
    return self.request.post(
  File "/home/marta/.local/lib/python3.8/site-packages/telegram/utils/request.py", line 361, in post
    result = self._request_wrapper(
  File "/home/marta/.local/lib/python3.8/site-packages/telegram/utils/request.py", line 265, in _request_wrapper
    raise NetworkError(f'urllib3 HTTPError {error}') from error
telegram.error.NetworkError: urllib3 HTTPError HTTPSConnectionPool(host='api.telegram.org', port=443): Max retries exceeded with url: /bot6016703766:AAE0sJbP7mN6JA9HGsWHVEBB3iwgJOFtKVM/getUpdates (Caused by NewConnectionError('<telegram.vendor.ptb_urllib3.urllib3.connection.VerifiedHTTPSConnection object at 0x7f2d7075d190>: Failed to establish a new connection: [Errno 101] Network is unreachable'))
2023-05-14 14:39:40,134 - telegram.vendor.ptb_urllib3.urllib3.connectionpool - WARNING - Retrying (Retry(total=2, connect=None, read=None, redirect=None)) after connection broken by 'NewConnectionError('<telegram.vendor.ptb_urllib3.urllib3.connection.VerifiedHTTPSConnection object at 0x7f2d7075d4c0>: Failed to establish a new connection: [Errno 101] Network is unreachable')': /bot6016703766:AAE0sJbP7mN6JA9HGsWHVEBB3iwgJOFtKVM/getUpdates
2023-05-14 14:39:40,135 - telegram.vendor.ptb_urllib3.urllib3.connectionpool - WARNING - Retrying (Retry(total=1, connect=None, read=None, redirect=None)) after connection broken by 'NewConnectionError('<telegram.vendor.ptb_urllib3.urllib3.connection.VerifiedHTTPSConnection object at 0x7f2d7075d640>: Failed to establish a new connection: [Errno 101] Network is unreachable')': /bot6016703766:AAE0sJbP7mN6JA9HGsWHVEBB3iwgJOFtKVM/getUpdates
2023-05-14 14:39:40,135 - telegram.vendor.ptb_urllib3.urllib3.connectionpool - WARNING - Retrying (Retry(total=0, connect=None, read=None, redirect=None)) after connection broken by 'NewConnectionError('<telegram.vendor.ptb_urllib3.urllib3.connection.VerifiedHTTPSConnection object at 0x7f2d7075d790>: Failed to establish a new connection: [Errno 101] Network is unreachable')': /bot6016703766:AAE0sJbP7mN6JA9HGsWHVEBB3iwgJOFtKVM/getUpdates
2023-05-14 14:39:40,135 - telegram.ext.updater - ERROR - Error while getting Updates: urllib3 HTTPError HTTPSConnectionPool(host='api.telegram.org', port=443): Max retries exceeded with url: /bot6016703766:AAE0sJbP7mN6JA9HGsWHVEBB3iwgJOFtKVM/getUpdates (Caused by NewConnectionError('<telegram.vendor.ptb_urllib3.urllib3.connection.VerifiedHTTPSConnection object at 0x7f2d7075d8e0>: Failed to establish a new connection: [Errno 101] Network is unreachable'))
2023-05-14 14:39:40,136 - telegram.ext.dispatcher - ERROR - No error handlers are registered, logging exception.
Traceback (most recent call last):
  File "/home/marta/.local/lib/python3.8/site-packages/telegram/vendor/ptb_urllib3/urllib3/connection.py", line 140, in _new_conn
    conn = connection.create_connection(
  File "/home/marta/.local/lib/python3.8/site-packages/telegram/vendor/ptb_urllib3/urllib3/util/connection.py", line 83, in create_connection
    raise err
  File "/home/marta/.local/lib/python3.8/site-packages/telegram/vendor/ptb_urllib3/urllib3/util/connection.py", line 73, in create_connection
    sock.connect(sa)
OSError: [Errno 101] Network is unreachable

During handling of the above exception, another exception occurred:

Traceback (most recent call last):
  File "/home/marta/.local/lib/python3.8/site-packages/telegram/vendor/ptb_urllib3/urllib3/connectionpool.py", line 614, in urlopen
    httplib_response = self._make_request(conn, method, url,
  File "/home/marta/.local/lib/python3.8/site-packages/telegram/vendor/ptb_urllib3/urllib3/connectionpool.py", line 360, in _make_request
    self._validate_conn(conn)
  File "/home/marta/.local/lib/python3.8/site-packages/telegram/vendor/ptb_urllib3/urllib3/connectionpool.py", line 857, in _validate_conn
    super(HTTPSConnectionPool, self)._validate_conn(conn)
  File "/home/marta/.local/lib/python3.8/site-packages/telegram/vendor/ptb_urllib3/urllib3/connectionpool.py", line 289, in _validate_conn
    conn.connect()
  File "/home/marta/.local/lib/python3.8/site-packages/telegram/vendor/ptb_urllib3/urllib3/connection.py", line 284, in connect
    conn = self._new_conn()
  File "/home/marta/.local/lib/python3.8/site-packages/telegram/vendor/ptb_urllib3/urllib3/connection.py", line 149, in _new_conn
    raise NewConnectionError(
telegram.vendor.ptb_urllib3.urllib3.exceptions.NewConnectionError: <telegram.vendor.ptb_urllib3.urllib3.connection.VerifiedHTTPSConnection object at 0x7f2d7075d8e0>: Failed to establish a new connection: [Errno 101] Network is unreachable

During handling of the above exception, another exception occurred:

Traceback (most recent call last):
  File "/home/marta/.local/lib/python3.8/site-packages/telegram/utils/request.py", line 259, in _request_wrapper
    resp = self._con_pool.request(*args, **kwargs)
  File "/home/marta/.local/lib/python3.8/site-packages/telegram/vendor/ptb_urllib3/urllib3/request.py", line 68, in request
    return self.request_encode_body(method, url, fields=fields,
  File "/home/marta/.local/lib/python3.8/site-packages/telegram/vendor/ptb_urllib3/urllib3/request.py", line 148, in request_encode_body
    return self.urlopen(method, url, **extra_kw)
  File "/home/marta/.local/lib/python3.8/site-packages/telegram/vendor/ptb_urllib3/urllib3/poolmanager.py", line 244, in urlopen
    response = conn.urlopen(method, u.request_uri, **kw)
  File "/home/marta/.local/lib/python3.8/site-packages/telegram/vendor/ptb_urllib3/urllib3/connectionpool.py", line 691, in urlopen
    return self.urlopen(method, url, body, headers, retries,
  File "/home/marta/.local/lib/python3.8/site-packages/telegram/vendor/ptb_urllib3/urllib3/connectionpool.py", line 691, in urlopen
    return self.urlopen(method, url, body, headers, retries,
  File "/home/marta/.local/lib/python3.8/site-packages/telegram/vendor/ptb_urllib3/urllib3/connectionpool.py", line 691, in urlopen
    return self.urlopen(method, url, body, headers, retries,
  File "/home/marta/.local/lib/python3.8/site-packages/telegram/vendor/ptb_urllib3/urllib3/connectionpool.py", line 665, in urlopen
    retries = retries.increment(method, url, error=e, _pool=self,
  File "/home/marta/.local/lib/python3.8/site-packages/telegram/vendor/ptb_urllib3/urllib3/util/retry.py", line 376, in increment
    raise MaxRetryError(_pool, url, error or ResponseError(cause))
telegram.vendor.ptb_urllib3.urllib3.exceptions.MaxRetryError: HTTPSConnectionPool(host='api.telegram.org', port=443): Max retries exceeded with url: /bot6016703766:AAE0sJbP7mN6JA9HGsWHVEBB3iwgJOFtKVM/getUpdates (Caused by NewConnectionError('<telegram.vendor.ptb_urllib3.urllib3.connection.VerifiedHTTPSConnection object at 0x7f2d7075d8e0>: Failed to establish a new connection: [Errno 101] Network is unreachable'))

The above exception was the direct cause of the following exception:

Traceback (most recent call last):
  File "/home/marta/.local/lib/python3.8/site-packages/telegram/ext/updater.py", line 646, in _network_loop_retry
    if not action_cb():
  File "/home/marta/.local/lib/python3.8/site-packages/telegram/ext/updater.py", line 597, in polling_action_cb
    updates = self.bot.get_updates(
  File "/home/marta/.local/lib/python3.8/site-packages/telegram/ext/extbot.py", line 222, in get_updates
    updates = super().get_updates(
  File "/home/marta/.local/lib/python3.8/site-packages/telegram/bot.py", line 130, in decorator
    result = func(*args, **kwargs)
  File "/home/marta/.local/lib/python3.8/site-packages/telegram/bot.py", line 2945, in get_updates
    self._post(
  File "/home/marta/.local/lib/python3.8/site-packages/telegram/bot.py", line 295, in _post
    return self.request.post(
  File "/home/marta/.local/lib/python3.8/site-packages/telegram/utils/request.py", line 361, in post
    result = self._request_wrapper(
  File "/home/marta/.local/lib/python3.8/site-packages/telegram/utils/request.py", line 265, in _request_wrapper
    raise NetworkError(f'urllib3 HTTPError {error}') from error
telegram.error.NetworkError: urllib3 HTTPError HTTPSConnectionPool(host='api.telegram.org', port=443): Max retries exceeded with url: /bot6016703766:AAE0sJbP7mN6JA9HGsWHVEBB3iwgJOFtKVM/getUpdates (Caused by NewConnectionError('<telegram.vendor.ptb_urllib3.urllib3.connection.VerifiedHTTPSConnection object at 0x7f2d7075d8e0>: Failed to establish a new connection: [Errno 101] Network is unreachable'))
2023-05-14 14:39:41,637 - telegram.vendor.ptb_urllib3.urllib3.connectionpool - WARNING - Retrying (Retry(total=2, connect=None, read=None, redirect=None)) after connection broken by 'NewConnectionError('<telegram.vendor.ptb_urllib3.urllib3.connection.VerifiedHTTPSConnection object at 0x7f2d7075da30>: Failed to establish a new connection: [Errno 101] Network is unreachable')': /bot6016703766:AAE0sJbP7mN6JA9HGsWHVEBB3iwgJOFtKVM/getUpdates
2023-05-14 14:39:41,637 - telegram.vendor.ptb_urllib3.urllib3.connectionpool - WARNING - Retrying (Retry(total=1, connect=None, read=None, redirect=None)) after connection broken by 'NewConnectionError('<telegram.vendor.ptb_urllib3.urllib3.connection.VerifiedHTTPSConnection object at 0x7f2d7075db80>: Failed to establish a new connection: [Errno 101] Network is unreachable')': /bot6016703766:AAE0sJbP7mN6JA9HGsWHVEBB3iwgJOFtKVM/getUpdates
2023-05-14 14:39:41,638 - telegram.vendor.ptb_urllib3.urllib3.connectionpool - WARNING - Retrying (Retry(total=0, connect=None, read=None, redirect=None)) after connection broken by 'NewConnectionError('<telegram.vendor.ptb_urllib3.urllib3.connection.VerifiedHTTPSConnection object at 0x7f2d7075dcd0>: Failed to establish a new connection: [Errno 101] Network is unreachable')': /bot6016703766:AAE0sJbP7mN6JA9HGsWHVEBB3iwgJOFtKVM/getUpdates
2023-05-14 14:39:41,638 - telegram.ext.updater - ERROR - Error while getting Updates: urllib3 HTTPError HTTPSConnectionPool(host='api.telegram.org', port=443): Max retries exceeded with url: /bot6016703766:AAE0sJbP7mN6JA9HGsWHVEBB3iwgJOFtKVM/getUpdates (Caused by NewConnectionError('<telegram.vendor.ptb_urllib3.urllib3.connection.VerifiedHTTPSConnection object at 0x7f2d7075de20>: Failed to establish a new connection: [Errno 101] Network is unreachable'))
2023-05-14 14:39:41,638 - telegram.ext.dispatcher - ERROR - No error handlers are registered, logging exception.
Traceback (most recent call last):
  File "/home/marta/.local/lib/python3.8/site-packages/telegram/vendor/ptb_urllib3/urllib3/connection.py", line 140, in _new_conn
    conn = connection.create_connection(
  File "/home/marta/.local/lib/python3.8/site-packages/telegram/vendor/ptb_urllib3/urllib3/util/connection.py", line 83, in create_connection
    raise err
  File "/home/marta/.local/lib/python3.8/site-packages/telegram/vendor/ptb_urllib3/urllib3/util/connection.py", line 73, in create_connection
    sock.connect(sa)
OSError: [Errno 101] Network is unreachable

During handling of the above exception, another exception occurred:

Traceback (most recent call last):
  File "/home/marta/.local/lib/python3.8/site-packages/telegram/vendor/ptb_urllib3/urllib3/connectionpool.py", line 614, in urlopen
    httplib_response = self._make_request(conn, method, url,
  File "/home/marta/.local/lib/python3.8/site-packages/telegram/vendor/ptb_urllib3/urllib3/connectionpool.py", line 360, in _make_request
    self._validate_conn(conn)
  File "/home/marta/.local/lib/python3.8/site-packages/telegram/vendor/ptb_urllib3/urllib3/connectionpool.py", line 857, in _validate_conn
    super(HTTPSConnectionPool, self)._validate_conn(conn)
  File "/home/marta/.local/lib/python3.8/site-packages/telegram/vendor/ptb_urllib3/urllib3/connectionpool.py", line 289, in _validate_conn
    conn.connect()
  File "/home/marta/.local/lib/python3.8/site-packages/telegram/vendor/ptb_urllib3/urllib3/connection.py", line 284, in connect
    conn = self._new_conn()
  File "/home/marta/.local/lib/python3.8/site-packages/telegram/vendor/ptb_urllib3/urllib3/connection.py", line 149, in _new_conn
    raise NewConnectionError(
telegram.vendor.ptb_urllib3.urllib3.exceptions.NewConnectionError: <telegram.vendor.ptb_urllib3.urllib3.connection.VerifiedHTTPSConnection object at 0x7f2d7075de20>: Failed to establish a new connection: [Errno 101] Network is unreachable

During handling of the above exception, another exception occurred:

Traceback (most recent call last):
  File "/home/marta/.local/lib/python3.8/site-packages/telegram/utils/request.py", line 259, in _request_wrapper
    resp = self._con_pool.request(*args, **kwargs)
  File "/home/marta/.local/lib/python3.8/site-packages/telegram/vendor/ptb_urllib3/urllib3/request.py", line 68, in request
    return self.request_encode_body(method, url, fields=fields,
  File "/home/marta/.local/lib/python3.8/site-packages/telegram/vendor/ptb_urllib3/urllib3/request.py", line 148, in request_encode_body
    return self.urlopen(method, url, **extra_kw)
  File "/home/marta/.local/lib/python3.8/site-packages/telegram/vendor/ptb_urllib3/urllib3/poolmanager.py", line 244, in urlopen
    response = conn.urlopen(method, u.request_uri, **kw)
  File "/home/marta/.local/lib/python3.8/site-packages/telegram/vendor/ptb_urllib3/urllib3/connectionpool.py", line 691, in urlopen
    return self.urlopen(method, url, body, headers, retries,
  File "/home/marta/.local/lib/python3.8/site-packages/telegram/vendor/ptb_urllib3/urllib3/connectionpool.py", line 691, in urlopen
    return self.urlopen(method, url, body, headers, retries,
  File "/home/marta/.local/lib/python3.8/site-packages/telegram/vendor/ptb_urllib3/urllib3/connectionpool.py", line 691, in urlopen
    return self.urlopen(method, url, body, headers, retries,
  File "/home/marta/.local/lib/python3.8/site-packages/telegram/vendor/ptb_urllib3/urllib3/connectionpool.py", line 665, in urlopen
    retries = retries.increment(method, url, error=e, _pool=self,
  File "/home/marta/.local/lib/python3.8/site-packages/telegram/vendor/ptb_urllib3/urllib3/util/retry.py", line 376, in increment
    raise MaxRetryError(_pool, url, error or ResponseError(cause))
telegram.vendor.ptb_urllib3.urllib3.exceptions.MaxRetryError: HTTPSConnectionPool(host='api.telegram.org', port=443): Max retries exceeded with url: /bot6016703766:AAE0sJbP7mN6JA9HGsWHVEBB3iwgJOFtKVM/getUpdates (Caused by NewConnectionError('<telegram.vendor.ptb_urllib3.urllib3.connection.VerifiedHTTPSConnection object at 0x7f2d7075de20>: Failed to establish a new connection: [Errno 101] Network is unreachable'))

The above exception was the direct cause of the following exception:

Traceback (most recent call last):
  File "/home/marta/.local/lib/python3.8/site-packages/telegram/ext/updater.py", line 646, in _network_loop_retry
    if not action_cb():
  File "/home/marta/.local/lib/python3.8/site-packages/telegram/ext/updater.py", line 597, in polling_action_cb
    updates = self.bot.get_updates(
  File "/home/marta/.local/lib/python3.8/site-packages/telegram/ext/extbot.py", line 222, in get_updates
    updates = super().get_updates(
  File "/home/marta/.local/lib/python3.8/site-packages/telegram/bot.py", line 130, in decorator
    result = func(*args, **kwargs)
  File "/home/marta/.local/lib/python3.8/site-packages/telegram/bot.py", line 2945, in get_updates
    self._post(
  File "/home/marta/.local/lib/python3.8/site-packages/telegram/bot.py", line 295, in _post
    return self.request.post(
  File "/home/marta/.local/lib/python3.8/site-packages/telegram/utils/request.py", line 361, in post
    result = self._request_wrapper(
  File "/home/marta/.local/lib/python3.8/site-packages/telegram/utils/request.py", line 265, in _request_wrapper
    raise NetworkError(f'urllib3 HTTPError {error}') from error
telegram.error.NetworkError: urllib3 HTTPError HTTPSConnectionPool(host='api.telegram.org', port=443): Max retries exceeded with url: /bot6016703766:AAE0sJbP7mN6JA9HGsWHVEBB3iwgJOFtKVM/getUpdates (Caused by NewConnectionError('<telegram.vendor.ptb_urllib3.urllib3.connection.VerifiedHTTPSConnection object at 0x7f2d7075de20>: Failed to establish a new connection: [Errno 101] Network is unreachable'))
2023-05-14 15:04:40,923 - telegram.vendor.ptb_urllib3.urllib3.connectionpool - WARNING - Retrying (Retry(total=2, connect=None, read=None, redirect=None)) after connection broken by 'NewConnectionError('<telegram.vendor.ptb_urllib3.urllib3.connection.VerifiedHTTPSConnection object at 0x7f2d7075d9d0>: Failed to establish a new connection: [Errno 101] Network is unreachable')': /bot6016703766:AAE0sJbP7mN6JA9HGsWHVEBB3iwgJOFtKVM/getUpdates
2023-05-14 15:04:40,924 - telegram.vendor.ptb_urllib3.urllib3.connectionpool - WARNING - Retrying (Retry(total=1, connect=None, read=None, redirect=None)) after connection broken by 'NewConnectionError('<telegram.vendor.ptb_urllib3.urllib3.connection.VerifiedHTTPSConnection object at 0x7f2d7075d880>: Failed to establish a new connection: [Errno 101] Network is unreachable')': /bot6016703766:AAE0sJbP7mN6JA9HGsWHVEBB3iwgJOFtKVM/getUpdates
2023-05-14 15:04:40,924 - telegram.vendor.ptb_urllib3.urllib3.connectionpool - WARNING - Retrying (Retry(total=0, connect=None, read=None, redirect=None)) after connection broken by 'NewConnectionError('<telegram.vendor.ptb_urllib3.urllib3.connection.VerifiedHTTPSConnection object at 0x7f2d7075d850>: Failed to establish a new connection: [Errno 101] Network is unreachable')': /bot6016703766:AAE0sJbP7mN6JA9HGsWHVEBB3iwgJOFtKVM/getUpdates
2023-05-14 15:04:40,925 - telegram.ext.updater - ERROR - Error while getting Updates: urllib3 HTTPError HTTPSConnectionPool(host='api.telegram.org', port=443): Max retries exceeded with url: /bot6016703766:AAE0sJbP7mN6JA9HGsWHVEBB3iwgJOFtKVM/getUpdates (Caused by NewConnectionError('<telegram.vendor.ptb_urllib3.urllib3.connection.VerifiedHTTPSConnection object at 0x7f2d7075d5e0>: Failed to establish a new connection: [Errno 101] Network is unreachable'))
2023-05-14 15:04:40,925 - telegram.ext.dispatcher - ERROR - No error handlers are registered, logging exception.
Traceback (most recent call last):
  File "/home/marta/.local/lib/python3.8/site-packages/telegram/vendor/ptb_urllib3/urllib3/connection.py", line 140, in _new_conn
    conn = connection.create_connection(
  File "/home/marta/.local/lib/python3.8/site-packages/telegram/vendor/ptb_urllib3/urllib3/util/connection.py", line 83, in create_connection
    raise err
  File "/home/marta/.local/lib/python3.8/site-packages/telegram/vendor/ptb_urllib3/urllib3/util/connection.py", line 73, in create_connection
    sock.connect(sa)
OSError: [Errno 101] Network is unreachable

During handling of the above exception, another exception occurred:

Traceback (most recent call last):
  File "/home/marta/.local/lib/python3.8/site-packages/telegram/vendor/ptb_urllib3/urllib3/connectionpool.py", line 614, in urlopen
    httplib_response = self._make_request(conn, method, url,
  File "/home/marta/.local/lib/python3.8/site-packages/telegram/vendor/ptb_urllib3/urllib3/connectionpool.py", line 360, in _make_request
    self._validate_conn(conn)
  File "/home/marta/.local/lib/python3.8/site-packages/telegram/vendor/ptb_urllib3/urllib3/connectionpool.py", line 857, in _validate_conn
    super(HTTPSConnectionPool, self)._validate_conn(conn)
  File "/home/marta/.local/lib/python3.8/site-packages/telegram/vendor/ptb_urllib3/urllib3/connectionpool.py", line 289, in _validate_conn
    conn.connect()
  File "/home/marta/.local/lib/python3.8/site-packages/telegram/vendor/ptb_urllib3/urllib3/connection.py", line 284, in connect
    conn = self._new_conn()
  File "/home/marta/.local/lib/python3.8/site-packages/telegram/vendor/ptb_urllib3/urllib3/connection.py", line 149, in _new_conn
    raise NewConnectionError(
telegram.vendor.ptb_urllib3.urllib3.exceptions.NewConnectionError: <telegram.vendor.ptb_urllib3.urllib3.connection.VerifiedHTTPSConnection object at 0x7f2d7075d5e0>: Failed to establish a new connection: [Errno 101] Network is unreachable

During handling of the above exception, another exception occurred:

Traceback (most recent call last):
  File "/home/marta/.local/lib/python3.8/site-packages/telegram/utils/request.py", line 259, in _request_wrapper
    resp = self._con_pool.request(*args, **kwargs)
  File "/home/marta/.local/lib/python3.8/site-packages/telegram/vendor/ptb_urllib3/urllib3/request.py", line 68, in request
    return self.request_encode_body(method, url, fields=fields,
  File "/home/marta/.local/lib/python3.8/site-packages/telegram/vendor/ptb_urllib3/urllib3/request.py", line 148, in request_encode_body
    return self.urlopen(method, url, **extra_kw)
  File "/home/marta/.local/lib/python3.8/site-packages/telegram/vendor/ptb_urllib3/urllib3/poolmanager.py", line 244, in urlopen
    response = conn.urlopen(method, u.request_uri, **kw)
  File "/home/marta/.local/lib/python3.8/site-packages/telegram/vendor/ptb_urllib3/urllib3/connectionpool.py", line 691, in urlopen
    return self.urlopen(method, url, body, headers, retries,
  File "/home/marta/.local/lib/python3.8/site-packages/telegram/vendor/ptb_urllib3/urllib3/connectionpool.py", line 691, in urlopen
    return self.urlopen(method, url, body, headers, retries,
  File "/home/marta/.local/lib/python3.8/site-packages/telegram/vendor/ptb_urllib3/urllib3/connectionpool.py", line 691, in urlopen
    return self.urlopen(method, url, body, headers, retries,
  File "/home/marta/.local/lib/python3.8/site-packages/telegram/vendor/ptb_urllib3/urllib3/connectionpool.py", line 665, in urlopen
    retries = retries.increment(method, url, error=e, _pool=self,
  File "/home/marta/.local/lib/python3.8/site-packages/telegram/vendor/ptb_urllib3/urllib3/util/retry.py", line 376, in increment
    raise MaxRetryError(_pool, url, error or ResponseError(cause))
telegram.vendor.ptb_urllib3.urllib3.exceptions.MaxRetryError: HTTPSConnectionPool(host='api.telegram.org', port=443): Max retries exceeded with url: /bot6016703766:AAE0sJbP7mN6JA9HGsWHVEBB3iwgJOFtKVM/getUpdates (Caused by NewConnectionError('<telegram.vendor.ptb_urllib3.urllib3.connection.VerifiedHTTPSConnection object at 0x7f2d7075d5e0>: Failed to establish a new connection: [Errno 101] Network is unreachable'))

The above exception was the direct cause of the following exception:

Traceback (most recent call last):
  File "/home/marta/.local/lib/python3.8/site-packages/telegram/ext/updater.py", line 646, in _network_loop_retry
    if not action_cb():
  File "/home/marta/.local/lib/python3.8/site-packages/telegram/ext/updater.py", line 597, in polling_action_cb
    updates = self.bot.get_updates(
  File "/home/marta/.local/lib/python3.8/site-packages/telegram/ext/extbot.py", line 222, in get_updates
    updates = super().get_updates(
  File "/home/marta/.local/lib/python3.8/site-packages/telegram/bot.py", line 130, in decorator
    result = func(*args, **kwargs)
  File "/home/marta/.local/lib/python3.8/site-packages/telegram/bot.py", line 2945, in get_updates
    self._post(
  File "/home/marta/.local/lib/python3.8/site-packages/telegram/bot.py", line 295, in _post
    return self.request.post(
  File "/home/marta/.local/lib/python3.8/site-packages/telegram/utils/request.py", line 361, in post
    result = self._request_wrapper(
  File "/home/marta/.local/lib/python3.8/site-packages/telegram/utils/request.py", line 265, in _request_wrapper
    raise NetworkError(f'urllib3 HTTPError {error}') from error
telegram.error.NetworkError: urllib3 HTTPError HTTPSConnectionPool(host='api.telegram.org', port=443): Max retries exceeded with url: /bot6016703766:AAE0sJbP7mN6JA9HGsWHVEBB3iwgJOFtKVM/getUpdates (Caused by NewConnectionError('<telegram.vendor.ptb_urllib3.urllib3.connection.VerifiedHTTPSConnection object at 0x7f2d7075d5e0>: Failed to establish a new connection: [Errno 101] Network is unreachable'))
2023-05-14 15:04:41,926 - telegram.vendor.ptb_urllib3.urllib3.connectionpool - WARNING - Retrying (Retry(total=2, connect=None, read=None, redirect=None)) after connection broken by 'NewConnectionError('<telegram.vendor.ptb_urllib3.urllib3.connection.VerifiedHTTPSConnection object at 0x7f2d7075d1c0>: Failed to establish a new connection: [Errno 101] Network is unreachable')': /bot6016703766:AAE0sJbP7mN6JA9HGsWHVEBB3iwgJOFtKVM/getUpdates
2023-05-14 15:04:41,927 - telegram.vendor.ptb_urllib3.urllib3.connectionpool - WARNING - Retrying (Retry(total=1, connect=None, read=None, redirect=None)) after connection broken by 'NewConnectionError('<telegram.vendor.ptb_urllib3.urllib3.connection.VerifiedHTTPSConnection object at 0x7f2d7075d0a0>: Failed to establish a new connection: [Errno 101] Network is unreachable')': /bot6016703766:AAE0sJbP7mN6JA9HGsWHVEBB3iwgJOFtKVM/getUpdates
2023-05-14 15:04:41,927 - telegram.vendor.ptb_urllib3.urllib3.connectionpool - WARNING - Retrying (Retry(total=0, connect=None, read=None, redirect=None)) after connection broken by 'NewConnectionError('<telegram.vendor.ptb_urllib3.urllib3.connection.VerifiedHTTPSConnection object at 0x7f2d70fec280>: Failed to establish a new connection: [Errno 101] Network is unreachable')': /bot6016703766:AAE0sJbP7mN6JA9HGsWHVEBB3iwgJOFtKVM/getUpdates
2023-05-14 15:04:41,927 - telegram.ext.updater - ERROR - Error while getting Updates: urllib3 HTTPError HTTPSConnectionPool(host='api.telegram.org', port=443): Max retries exceeded with url: /bot6016703766:AAE0sJbP7mN6JA9HGsWHVEBB3iwgJOFtKVM/getUpdates (Caused by NewConnectionError('<telegram.vendor.ptb_urllib3.urllib3.connection.VerifiedHTTPSConnection object at 0x7f2d70fecd30>: Failed to establish a new connection: [Errno 101] Network is unreachable'))
2023-05-14 15:04:41,928 - telegram.ext.dispatcher - ERROR - No error handlers are registered, logging exception.
Traceback (most recent call last):
  File "/home/marta/.local/lib/python3.8/site-packages/telegram/vendor/ptb_urllib3/urllib3/connection.py", line 140, in _new_conn
    conn = connection.create_connection(
  File "/home/marta/.local/lib/python3.8/site-packages/telegram/vendor/ptb_urllib3/urllib3/util/connection.py", line 83, in create_connection
    raise err
  File "/home/marta/.local/lib/python3.8/site-packages/telegram/vendor/ptb_urllib3/urllib3/util/connection.py", line 73, in create_connection
    sock.connect(sa)
OSError: [Errno 101] Network is unreachable

During handling of the above exception, another exception occurred:

Traceback (most recent call last):
  File "/home/marta/.local/lib/python3.8/site-packages/telegram/vendor/ptb_urllib3/urllib3/connectionpool.py", line 614, in urlopen
    httplib_response = self._make_request(conn, method, url,
  File "/home/marta/.local/lib/python3.8/site-packages/telegram/vendor/ptb_urllib3/urllib3/connectionpool.py", line 360, in _make_request
    self._validate_conn(conn)
  File "/home/marta/.local/lib/python3.8/site-packages/telegram/vendor/ptb_urllib3/urllib3/connectionpool.py", line 857, in _validate_conn
    super(HTTPSConnectionPool, self)._validate_conn(conn)
  File "/home/marta/.local/lib/python3.8/site-packages/telegram/vendor/ptb_urllib3/urllib3/connectionpool.py", line 289, in _validate_conn
    conn.connect()
  File "/home/marta/.local/lib/python3.8/site-packages/telegram/vendor/ptb_urllib3/urllib3/connection.py", line 284, in connect
    conn = self._new_conn()
  File "/home/marta/.local/lib/python3.8/site-packages/telegram/vendor/ptb_urllib3/urllib3/connection.py", line 149, in _new_conn
    raise NewConnectionError(
telegram.vendor.ptb_urllib3.urllib3.exceptions.NewConnectionError: <telegram.vendor.ptb_urllib3.urllib3.connection.VerifiedHTTPSConnection object at 0x7f2d70fecd30>: Failed to establish a new connection: [Errno 101] Network is unreachable

During handling of the above exception, another exception occurred:

Traceback (most recent call last):
  File "/home/marta/.local/lib/python3.8/site-packages/telegram/utils/request.py", line 259, in _request_wrapper
    resp = self._con_pool.request(*args, **kwargs)
  File "/home/marta/.local/lib/python3.8/site-packages/telegram/vendor/ptb_urllib3/urllib3/request.py", line 68, in request
    return self.request_encode_body(method, url, fields=fields,
  File "/home/marta/.local/lib/python3.8/site-packages/telegram/vendor/ptb_urllib3/urllib3/request.py", line 148, in request_encode_body
    return self.urlopen(method, url, **extra_kw)
  File "/home/marta/.local/lib/python3.8/site-packages/telegram/vendor/ptb_urllib3/urllib3/poolmanager.py", line 244, in urlopen
    response = conn.urlopen(method, u.request_uri, **kw)
  File "/home/marta/.local/lib/python3.8/site-packages/telegram/vendor/ptb_urllib3/urllib3/connectionpool.py", line 691, in urlopen
    return self.urlopen(method, url, body, headers, retries,
  File "/home/marta/.local/lib/python3.8/site-packages/telegram/vendor/ptb_urllib3/urllib3/connectionpool.py", line 691, in urlopen
    return self.urlopen(method, url, body, headers, retries,
  File "/home/marta/.local/lib/python3.8/site-packages/telegram/vendor/ptb_urllib3/urllib3/connectionpool.py", line 691, in urlopen
    return self.urlopen(method, url, body, headers, retries,
  File "/home/marta/.local/lib/python3.8/site-packages/telegram/vendor/ptb_urllib3/urllib3/connectionpool.py", line 665, in urlopen
    retries = retries.increment(method, url, error=e, _pool=self,
  File "/home/marta/.local/lib/python3.8/site-packages/telegram/vendor/ptb_urllib3/urllib3/util/retry.py", line 376, in increment
    raise MaxRetryError(_pool, url, error or ResponseError(cause))
telegram.vendor.ptb_urllib3.urllib3.exceptions.MaxRetryError: HTTPSConnectionPool(host='api.telegram.org', port=443): Max retries exceeded with url: /bot6016703766:AAE0sJbP7mN6JA9HGsWHVEBB3iwgJOFtKVM/getUpdates (Caused by NewConnectionError('<telegram.vendor.ptb_urllib3.urllib3.connection.VerifiedHTTPSConnection object at 0x7f2d70fecd30>: Failed to establish a new connection: [Errno 101] Network is unreachable'))

The above exception was the direct cause of the following exception:

Traceback (most recent call last):
  File "/home/marta/.local/lib/python3.8/site-packages/telegram/ext/updater.py", line 646, in _network_loop_retry
    if not action_cb():
  File "/home/marta/.local/lib/python3.8/site-packages/telegram/ext/updater.py", line 597, in polling_action_cb
    updates = self.bot.get_updates(
  File "/home/marta/.local/lib/python3.8/site-packages/telegram/ext/extbot.py", line 222, in get_updates
    updates = super().get_updates(
  File "/home/marta/.local/lib/python3.8/site-packages/telegram/bot.py", line 130, in decorator
    result = func(*args, **kwargs)
  File "/home/marta/.local/lib/python3.8/site-packages/telegram/bot.py", line 2945, in get_updates
    self._post(
  File "/home/marta/.local/lib/python3.8/site-packages/telegram/bot.py", line 295, in _post
    return self.request.post(
  File "/home/marta/.local/lib/python3.8/site-packages/telegram/utils/request.py", line 361, in post
    result = self._request_wrapper(
  File "/home/marta/.local/lib/python3.8/site-packages/telegram/utils/request.py", line 265, in _request_wrapper
    raise NetworkError(f'urllib3 HTTPError {error}') from error
telegram.error.NetworkError: urllib3 HTTPError HTTPSConnectionPool(host='api.telegram.org', port=443): Max retries exceeded with url: /bot6016703766:AAE0sJbP7mN6JA9HGsWHVEBB3iwgJOFtKVM/getUpdates (Caused by NewConnectionError('<telegram.vendor.ptb_urllib3.urllib3.connection.VerifiedHTTPSConnection object at 0x7f2d70fecd30>: Failed to establish a new connection: [Errno 101] Network is unreachable'))
2023-05-14 15:10:51,571 - apscheduler.scheduler - INFO - Scheduler started
2023-05-14 15:11:00,818 - root - INFO -  - CMD: DIVERBO - USER_ID: 28097231 - USERNAME: martatorrebarbeito - USER_FULLNAME: Marta - CHAT ID: 28097231
2023-05-14 15:11:00,818 - telegram.ext.dispatcher - ERROR - No error handlers are registered, logging exception.
Traceback (most recent call last):
  File "/home/marta/.local/lib/python3.8/site-packages/telegram/ext/dispatcher.py", line 555, in process_update
    handler.handle_update(update, self, check, context)
  File "/home/marta/.local/lib/python3.8/site-packages/telegram/ext/handler.py", line 198, in handle_update
    return self.callback(update, context)
  File "/home/marta/Proyectos/lverbobot/lverbobot.py", line 258, in diverbo
    selverbo()
  File "/home/marta/Proyectos/lverbobot/lverbobot.py", line 246, in selverbo
    context.user_data['respuestacorrecta_texto'] = pregunta_entrada['respuesta']
NameError: name 'context' is not defined
2023-05-14 15:11:43,555 - apscheduler.scheduler - INFO - Scheduler started
2023-05-14 15:11:52,547 - root - INFO -  - CMD: DIVERBO - USER_ID: 28097231 - USERNAME: martatorrebarbeito - USER_FULLNAME: Marta - CHAT ID: 28097231
2023-05-14 15:11:52,548 - telegram.ext.dispatcher - ERROR - No error handlers are registered, logging exception.
Traceback (most recent call last):
  File "/home/marta/.local/lib/python3.8/site-packages/telegram/ext/dispatcher.py", line 555, in process_update
    handler.handle_update(update, self, check, context)
  File "/home/marta/.local/lib/python3.8/site-packages/telegram/ext/handler.py", line 198, in handle_update
    return self.callback(update, context)
  File "/home/marta/Proyectos/lverbobot/lverbobot.py", line 258, in diverbo
    selverbo()
TypeError: selverbo() missing 1 required positional argument: 'context'
2023-05-14 15:12:04,748 - apscheduler.scheduler - INFO - Scheduler started
2023-05-14 15:12:18,018 - root - INFO -  - CMD: DIVERBO - USER_ID: 28097231 - USERNAME: martatorrebarbeito - USER_FULLNAME: Marta - CHAT ID: 28097231
2023-05-14 15:12:18,019 - telegram.ext.dispatcher - ERROR - No error handlers are registered, logging exception.
Traceback (most recent call last):
  File "/home/marta/.local/lib/python3.8/site-packages/telegram/ext/dispatcher.py", line 555, in process_update
    handler.handle_update(update, self, check, context)
  File "/home/marta/.local/lib/python3.8/site-packages/telegram/ext/handler.py", line 198, in handle_update
    return self.callback(update, context)
  File "/home/marta/Proyectos/lverbobot/lverbobot.py", line 258, in diverbo
    selverbo()
TypeError: selverbo() missing 1 required positional argument: 'context'
2023-05-14 15:12:35,852 - apscheduler.scheduler - INFO - Scheduler started
2023-05-14 15:12:43,145 - root - INFO -  - CMD: DIVERBO - USER_ID: 28097231 - USERNAME: martatorrebarbeito - USER_FULLNAME: Marta - CHAT ID: 28097231
2023-05-14 15:12:43,145 - telegram.ext.dispatcher - ERROR - No error handlers are registered, logging exception.
Traceback (most recent call last):
  File "/home/marta/.local/lib/python3.8/site-packages/telegram/ext/dispatcher.py", line 555, in process_update
    handler.handle_update(update, self, check, context)
  File "/home/marta/.local/lib/python3.8/site-packages/telegram/ext/handler.py", line 198, in handle_update
    return self.callback(update, context)
  File "/home/marta/Proyectos/lverbobot/lverbobot.py", line 258, in diverbo
    selverbo()
TypeError: selverbo() missing 1 required positional argument: 'context'
2023-05-14 15:13:06,474 - apscheduler.scheduler - INFO - Scheduler started
2023-05-14 15:13:15,172 - root - INFO -  - CMD: DIVERBO - USER_ID: 28097231 - USERNAME: martatorrebarbeito - USER_FULLNAME: Marta - CHAT ID: 28097231
2023-05-14 15:13:18,353 - root - INFO -  - CMD: RESPUESTA - USER_ID: 28097231 - USERNAME: martatorrebarbeito - USER_FULLNAME: Marta - CHAT ID: 28097231
2023-05-14 15:13:18,354 - root - INFO -  - CMD: FALLO - USER_ID: 28097231 - USERNAME: martatorrebarbeito - USER_FULLNAME: Marta - CHAT ID: 28097231
2023-05-14 15:13:32,482 - root - INFO -  - CMD: RESPUESTA - USER_ID: 28097231 - USERNAME: martatorrebarbeito - USER_FULLNAME: Marta - CHAT ID: 28097231
2023-05-14 15:13:32,482 - root - INFO -  - CMD: ACIERTO - USER_ID: 28097231 - USERNAME: martatorrebarbeito - USER_FULLNAME: Marta - CHAT ID: 28097231
2023-05-14 15:18:22,816 - apscheduler.scheduler - INFO - Scheduler started
2023-05-14 15:18:31,376 - root - INFO -  - CMD: DIVERBO - USER_ID: 28097231 - USERNAME: martatorrebarbeito - USER_FULLNAME: Marta - CHAT ID: 28097231
2023-05-14 15:18:37,799 - root - INFO -  - CMD: RESPUESTA - USER_ID: 28097231 - USERNAME: martatorrebarbeito - USER_FULLNAME: Marta - CHAT ID: 28097231
2023-05-14 15:18:37,800 - root - INFO -  - CMD: FALLO - USER_ID: 28097231 - USERNAME: martatorrebarbeito - USER_FULLNAME: Marta - CHAT ID: 28097231
2023-05-14 15:18:42,774 - root - INFO -  - CMD: RESPUESTA - USER_ID: 28097231 - USERNAME: martatorrebarbeito - USER_FULLNAME: Marta - CHAT ID: 28097231
2023-05-14 15:18:42,775 - root - INFO -  - CMD: FALLO - USER_ID: 28097231 - USERNAME: martatorrebarbeito - USER_FULLNAME: Marta - CHAT ID: 28097231
2023-05-14 15:18:53,590 - root - INFO -  - CMD: RESPUESTA - USER_ID: 28097231 - USERNAME: martatorrebarbeito - USER_FULLNAME: Marta - CHAT ID: 28097231
2023-05-14 15:18:53,591 - root - INFO -  - CMD: FALLO - USER_ID: 28097231 - USERNAME: martatorrebarbeito - USER_FULLNAME: Marta - CHAT ID: 28097231
2023-05-14 15:19:22,469 - root - INFO -  - CMD: RESPUESTA - USER_ID: 28097231 - USERNAME: martatorrebarbeito - USER_FULLNAME: Marta - CHAT ID: 28097231
2023-05-14 15:19:22,470 - root - INFO -  - CMD: FALLO - USER_ID: 28097231 - USERNAME: martatorrebarbeito - USER_FULLNAME: Marta - CHAT ID: 28097231
2023-05-14 15:19:25,469 - root - INFO -  - CMD: RESPUESTA - USER_ID: 28097231 - USERNAME: martatorrebarbeito - USER_FULLNAME: Marta - CHAT ID: 28097231
2023-05-14 15:19:25,469 - root - INFO -  - CMD: FALLO - USER_ID: 28097231 - USERNAME: martatorrebarbeito - USER_FULLNAME: Marta - CHAT ID: 28097231
2023-05-14 15:19:26,987 - telegram.ext.dispatcher - ERROR - No error handlers are registered, logging exception.
Traceback (most recent call last):
  File "/home/marta/.local/lib/python3.8/site-packages/telegram/ext/dispatcher.py", line 555, in process_update
    handler.handle_update(update, self, check, context)
  File "/home/marta/.local/lib/python3.8/site-packages/telegram/ext/handler.py", line 198, in handle_update
    return self.callback(update, context)
  File "/home/marta/Proyectos/lverbobot/lverbobot.py", line 224, in respuesta
    registra(update, 'RESPUESTA')
  File "/home/marta/Proyectos/lverbobot/lverbobot.py", line 34, in registra
    usuario=update.message.from_user
AttributeError: 'NoneType' object has no attribute 'from_user'
2023-05-14 15:19:37,889 - root - INFO -  - CMD: RESPUESTA - USER_ID: 28097231 - USERNAME: martatorrebarbeito - USER_FULLNAME: Marta - CHAT ID: 28097231
2023-05-14 15:19:37,889 - root - INFO -  - CMD: FALLO - USER_ID: 28097231 - USERNAME: martatorrebarbeito - USER_FULLNAME: Marta - CHAT ID: 28097231
2023-05-14 15:19:39,938 - root - INFO -  - CMD: RESPUESTA - USER_ID: 28097231 - USERNAME: martatorrebarbeito - USER_FULLNAME: Marta - CHAT ID: 28097231
2023-05-14 15:19:39,938 - root - INFO -  - CMD: FALLO - USER_ID: 28097231 - USERNAME: martatorrebarbeito - USER_FULLNAME: Marta - CHAT ID: 28097231
2023-05-14 15:19:43,459 - root - INFO -  - CMD: PIDOPAPAS - USER_ID: 28097231 - USERNAME: martatorrebarbeito - USER_FULLNAME: Marta - CHAT ID: 28097231
2023-05-14 15:20:19,088 - apscheduler.scheduler - INFO - Scheduler started
2023-05-14 15:20:21,504 - root - INFO -  - CMD: RESPUESTA - USER_ID: 28097231 - USERNAME: martatorrebarbeito - USER_FULLNAME: Marta - CHAT ID: 28097231
2023-05-14 15:20:21,505 - telegram.ext.dispatcher - ERROR - No error handlers are registered, logging exception.
Traceback (most recent call last):
  File "/home/marta/.local/lib/python3.8/site-packages/telegram/ext/dispatcher.py", line 555, in process_update
    handler.handle_update(update, self, check, context)
  File "/home/marta/.local/lib/python3.8/site-packages/telegram/ext/handler.py", line 198, in handle_update
    return self.callback(update, context)
  File "/home/marta/Proyectos/lverbobot/lverbobot.py", line 227, in respuesta
    if (respuesta == context.user_data['respuestacorrecta_texto']):
KeyError: 'respuestacorrecta_texto'
2023-05-14 15:21:16,129 - apscheduler.scheduler - INFO - Scheduler started
2023-05-14 15:21:19,041 - root - INFO -  - CMD: DITIEMPO - USER_ID: 28097231 - USERNAME: martatorrebarbeito - USER_FULLNAME: Marta - CHAT ID: 28097231
2023-05-14 15:26:52,193 - apscheduler.scheduler - INFO - Scheduler started
2023-05-14 15:26:56,145 - root - INFO -  - CMD: DITIEMPO - USER_ID: 28097231 - USERNAME: martatorrebarbeito - USER_FULLNAME: Marta - CHAT ID: 28097231
2023-05-14 15:27:19,285 - telegram.ext.dispatcher - ERROR - No error handlers are registered, logging exception.
Traceback (most recent call last):
  File "/home/marta/.local/lib/python3.8/site-packages/telegram/ext/dispatcher.py", line 555, in process_update
    handler.handle_update(update, self, check, context)
  File "/home/marta/.local/lib/python3.8/site-packages/telegram/ext/handler.py", line 198, in handle_update
    return self.callback(update, context)
  File "/home/marta/Proyectos/lverbobot/lverbobot.py", line 216, in ditiempo
    botonera = crea_botonera()
  File "/home/marta/Proyectos/lverbobot/lverbobot.py", line 195, in crea_botonera
    d_tiempos[boton] = InlineKeyboardButton(d_tiempos['tiempo'],d_tiempos['valor'])
NameError: name 'boton' is not defined
2023-05-14 15:28:28,467 - apscheduler.scheduler - INFO - Scheduler started
2023-05-14 15:28:38,357 - root - INFO -  - CMD: DITIEMPO - USER_ID: 28097231 - USERNAME: martatorrebarbeito - USER_FULLNAME: Marta - CHAT ID: 28097231
2023-05-14 15:32:40,342 - apscheduler.scheduler - INFO - Scheduler started
2023-05-14 15:32:50,028 - apscheduler.scheduler - INFO - Scheduler started
2023-05-14 15:32:54,359 - root - INFO -  - CMD: DITIEMPO - USER_ID: 28097231 - USERNAME: martatorrebarbeito - USER_FULLNAME: Marta - CHAT ID: 28097231
2023-05-14 15:32:54,362 - telegram.ext.dispatcher - ERROR - No error handlers are registered, logging exception.
Traceback (most recent call last):
  File "/home/marta/.local/lib/python3.8/site-packages/telegram/ext/dispatcher.py", line 555, in process_update
    handler.handle_update(update, self, check, context)
  File "/home/marta/.local/lib/python3.8/site-packages/telegram/ext/handler.py", line 198, in handle_update
    return self.callback(update, context)
  File "/home/marta/Proyectos/lverbobot/lverbobot.py", line 219, in ditiempo
    context.bot.send_message(chat_id=update.effective_chat.id,text='Verboalchou',reply_markup=botonera)
  File "/home/marta/.local/lib/python3.8/site-packages/telegram/bot.py", line 130, in decorator
    result = func(*args, **kwargs)
  File "/home/marta/.local/lib/python3.8/site-packages/telegram/bot.py", line 513, in send_message
    return self._message(  # type: ignore[return-value]
  File "/home/marta/.local/lib/python3.8/site-packages/telegram/ext/extbot.py", line 199, in _message
    result = super()._message(
  File "/home/marta/.local/lib/python3.8/site-packages/telegram/bot.py", line 322, in _message
    data['reply_markup'] = reply_markup.to_json()
  File "/home/marta/.local/lib/python3.8/site-packages/telegram/base.py", line 104, in to_json
    return json.dumps(self.to_dict())
  File "/home/marta/.local/lib/python3.8/site-packages/telegram/inline/inlinekeyboardmarkup.py", line 62, in to_dict
    data['inline_keyboard'].append([x.to_dict() for x in inline_keyboard])
  File "/home/marta/.local/lib/python3.8/site-packages/telegram/inline/inlinekeyboardmarkup.py", line 62, in <listcomp>
    data['inline_keyboard'].append([x.to_dict() for x in inline_keyboard])
  File "/home/marta/.local/lib/python3.8/site-packages/telegram/base.py", line 51, in __getitem__
    return getattr(self, item, None)
TypeError: getattr(): attribute name must be string
2023-05-14 15:34:25,297 - apscheduler.scheduler - INFO - Scheduler started
2023-05-14 15:34:28,560 - root - INFO -  - CMD: DITIEMPO - USER_ID: 28097231 - USERNAME: martatorrebarbeito - USER_FULLNAME: Marta - CHAT ID: 28097231
2023-05-14 15:34:38,560 - telegram.ext.dispatcher - ERROR - No error handlers are registered, logging exception.
Traceback (most recent call last):
  File "/home/marta/.local/lib/python3.8/site-packages/telegram/ext/dispatcher.py", line 555, in process_update
    handler.handle_update(update, self, check, context)
  File "/home/marta/.local/lib/python3.8/site-packages/telegram/ext/handler.py", line 198, in handle_update
    return self.callback(update, context)
  File "/home/marta/Proyectos/lverbobot/lverbobot.py", line 219, in ditiempo
    context.bot.send_message(chat_id=update.effective_chat.id,text='Verboalchou',reply_markup=botonera)
  File "/home/marta/.local/lib/python3.8/site-packages/telegram/bot.py", line 130, in decorator
    result = func(*args, **kwargs)
  File "/home/marta/.local/lib/python3.8/site-packages/telegram/bot.py", line 513, in send_message
    return self._message(  # type: ignore[return-value]
  File "/home/marta/.local/lib/python3.8/site-packages/telegram/ext/extbot.py", line 199, in _message
    result = super()._message(
  File "/home/marta/.local/lib/python3.8/site-packages/telegram/bot.py", line 322, in _message
    data['reply_markup'] = reply_markup.to_json()
  File "/home/marta/.local/lib/python3.8/site-packages/telegram/base.py", line 104, in to_json
    return json.dumps(self.to_dict())
  File "/home/marta/.local/lib/python3.8/site-packages/telegram/inline/inlinekeyboardmarkup.py", line 62, in to_dict
    data['inline_keyboard'].append([x.to_dict() for x in inline_keyboard])
  File "/home/marta/.local/lib/python3.8/site-packages/telegram/inline/inlinekeyboardmarkup.py", line 62, in <listcomp>
    data['inline_keyboard'].append([x.to_dict() for x in inline_keyboard])
  File "/home/marta/.local/lib/python3.8/site-packages/telegram/base.py", line 51, in __getitem__
    return getattr(self, item, None)
TypeError: getattr(): attribute name must be string
2023-05-14 15:35:02,155 - apscheduler.scheduler - INFO - Scheduler started
2023-05-14 15:35:03,057 - root - INFO -  - CMD: DITIEMPO - USER_ID: 28097231 - USERNAME: martatorrebarbeito - USER_FULLNAME: Marta - CHAT ID: 28097231
2023-05-14 15:35:44,680 - telegram.ext.dispatcher - ERROR - No error handlers are registered, logging exception.
Traceback (most recent call last):
  File "/home/marta/.local/lib/python3.8/site-packages/telegram/ext/dispatcher.py", line 555, in process_update
    handler.handle_update(update, self, check, context)
  File "/home/marta/.local/lib/python3.8/site-packages/telegram/ext/handler.py", line 198, in handle_update
    return self.callback(update, context)
  File "/home/marta/Proyectos/lverbobot/lverbobot.py", line 219, in ditiempo
    context.bot.send_message(chat_id=update.effective_chat.id,text='Verboalchou',reply_markup=botonera)
  File "/home/marta/.local/lib/python3.8/site-packages/telegram/bot.py", line 130, in decorator
    result = func(*args, **kwargs)
  File "/home/marta/.local/lib/python3.8/site-packages/telegram/bot.py", line 513, in send_message
    return self._message(  # type: ignore[return-value]
  File "/home/marta/.local/lib/python3.8/site-packages/telegram/ext/extbot.py", line 199, in _message
    result = super()._message(
  File "/home/marta/.local/lib/python3.8/site-packages/telegram/bot.py", line 322, in _message
    data['reply_markup'] = reply_markup.to_json()
  File "/home/marta/.local/lib/python3.8/site-packages/telegram/base.py", line 104, in to_json
    return json.dumps(self.to_dict())
  File "/home/marta/.local/lib/python3.8/site-packages/telegram/inline/inlinekeyboardmarkup.py", line 62, in to_dict
    data['inline_keyboard'].append([x.to_dict() for x in inline_keyboard])
  File "/home/marta/.local/lib/python3.8/site-packages/telegram/inline/inlinekeyboardmarkup.py", line 62, in <listcomp>
    data['inline_keyboard'].append([x.to_dict() for x in inline_keyboard])
  File "/home/marta/.local/lib/python3.8/site-packages/telegram/base.py", line 51, in __getitem__
    return getattr(self, item, None)
TypeError: getattr(): attribute name must be string
2023-05-14 15:38:25,386 - apscheduler.scheduler - INFO - Scheduler started
2023-05-14 15:38:26,808 - root - INFO -  - CMD: DITIEMPO - USER_ID: 28097231 - USERNAME: martatorrebarbeito - USER_FULLNAME: Marta - CHAT ID: 28097231
2023-05-14 15:41:36,798 - apscheduler.scheduler - INFO - Scheduler started
2023-05-14 15:41:37,605 - root - INFO -  - CMD: DIVERBO - USER_ID: 28097231 - USERNAME: martatorrebarbeito - USER_FULLNAME: Marta - CHAT ID: 28097231
2023-05-14 15:41:48,672 - root - INFO -  - CMD: DITIEMPO - USER_ID: 28097231 - USERNAME: martatorrebarbeito - USER_FULLNAME: Marta - CHAT ID: 28097231
2023-05-14 15:49:35,440 - apscheduler.scheduler - INFO - Scheduler started
2023-05-14 15:49:42,569 - root - INFO -  - CMD: DITIEMPO - USER_ID: 28097231 - USERNAME: martatorrebarbeito - USER_FULLNAME: Marta - CHAT ID: 28097231
2023-05-14 15:51:52,987 - apscheduler.scheduler - INFO - Scheduler started
2023-05-14 15:51:55,647 - root - INFO -  - CMD: DITIEMPO - USER_ID: 28097231 - USERNAME: martatorrebarbeito - USER_FULLNAME: Marta - CHAT ID: 28097231
2023-05-14 15:52:45,057 - apscheduler.scheduler - INFO - Scheduler started
2023-05-14 15:52:45,319 - root - INFO -  - CMD: DITIEMPO - USER_ID: 28097231 - USERNAME: martatorrebarbeito - USER_FULLNAME: Marta - CHAT ID: 28097231
2023-05-14 15:52:51,286 - apscheduler.scheduler - INFO - Scheduler started
2023-05-14 15:52:52,539 - root - INFO -  - CMD: DITIEMPO - USER_ID: 28097231 - USERNAME: martatorrebarbeito - USER_FULLNAME: Marta - CHAT ID: 28097231
2023-05-14 15:53:15,320 - apscheduler.scheduler - INFO - Scheduler started
2023-05-14 15:53:18,490 - root - INFO -  - CMD: DITIEMPO - USER_ID: 28097231 - USERNAME: martatorrebarbeito - USER_FULLNAME: Marta - CHAT ID: 28097231
2023-05-14 15:53:28,494 - apscheduler.scheduler - INFO - Scheduler started
2023-05-14 15:53:48,923 - apscheduler.scheduler - INFO - Scheduler started
2023-05-14 15:53:53,243 - root - INFO -  - CMD: DITIEMPO - USER_ID: 28097231 - USERNAME: martatorrebarbeito - USER_FULLNAME: Marta - CHAT ID: 28097231
2023-05-14 15:54:37,605 - telegram.vendor.ptb_urllib3.urllib3.connectionpool - WARNING - Retrying (Retry(total=2, connect=None, read=None, redirect=None)) after connection broken by 'NewConnectionError('<telegram.vendor.ptb_urllib3.urllib3.connection.VerifiedHTTPSConnection object at 0x7f7ddf4ccdf0>: Failed to establish a new connection: [Errno 113] No route to host')': /bot6016703766:AAE0sJbP7mN6JA9HGsWHVEBB3iwgJOFtKVM/getUpdates
2023-05-14 15:54:40,676 - telegram.vendor.ptb_urllib3.urllib3.connectionpool - WARNING - Retrying (Retry(total=1, connect=None, read=None, redirect=None)) after connection broken by 'NewConnectionError('<telegram.vendor.ptb_urllib3.urllib3.connection.VerifiedHTTPSConnection object at 0x7f7ddf4ccee0>: Failed to establish a new connection: [Errno 113] No route to host')': /bot6016703766:AAE0sJbP7mN6JA9HGsWHVEBB3iwgJOFtKVM/getUpdates
2023-05-14 15:54:45,680 - telegram.vendor.ptb_urllib3.urllib3.connectionpool - WARNING - Retrying (Retry(total=0, connect=None, read=None, redirect=None)) after connection broken by 'ConnectTimeoutError(<telegram.vendor.ptb_urllib3.urllib3.connection.VerifiedHTTPSConnection object at 0x7f7ddf4ccb50>, 'Connection to api.telegram.org timed out. (connect timeout=5.0)')': /bot6016703766:AAE0sJbP7mN6JA9HGsWHVEBB3iwgJOFtKVM/getUpdates
2023-05-14 15:54:45,681 - telegram.ext.updater - ERROR - Error while getting Updates: urllib3 HTTPError HTTPSConnectionPool(host='api.telegram.org', port=443): Max retries exceeded with url: /bot6016703766:AAE0sJbP7mN6JA9HGsWHVEBB3iwgJOFtKVM/getUpdates (Caused by NewConnectionError('<telegram.vendor.ptb_urllib3.urllib3.connection.VerifiedHTTPSConnection object at 0x7f7ddf4e50d0>: Failed to establish a new connection: [Errno 101] Network is unreachable'))
2023-05-14 15:54:45,682 - telegram.ext.dispatcher - ERROR - No error handlers are registered, logging exception.
Traceback (most recent call last):
  File "/home/marta/.local/lib/python3.8/site-packages/telegram/vendor/ptb_urllib3/urllib3/connection.py", line 140, in _new_conn
    conn = connection.create_connection(
  File "/home/marta/.local/lib/python3.8/site-packages/telegram/vendor/ptb_urllib3/urllib3/util/connection.py", line 83, in create_connection
    raise err
  File "/home/marta/.local/lib/python3.8/site-packages/telegram/vendor/ptb_urllib3/urllib3/util/connection.py", line 73, in create_connection
    sock.connect(sa)
OSError: [Errno 101] Network is unreachable

During handling of the above exception, another exception occurred:

Traceback (most recent call last):
  File "/home/marta/.local/lib/python3.8/site-packages/telegram/vendor/ptb_urllib3/urllib3/connectionpool.py", line 614, in urlopen
    httplib_response = self._make_request(conn, method, url,
  File "/home/marta/.local/lib/python3.8/site-packages/telegram/vendor/ptb_urllib3/urllib3/connectionpool.py", line 360, in _make_request
    self._validate_conn(conn)
  File "/home/marta/.local/lib/python3.8/site-packages/telegram/vendor/ptb_urllib3/urllib3/connectionpool.py", line 857, in _validate_conn
    super(HTTPSConnectionPool, self)._validate_conn(conn)
  File "/home/marta/.local/lib/python3.8/site-packages/telegram/vendor/ptb_urllib3/urllib3/connectionpool.py", line 289, in _validate_conn
    conn.connect()
  File "/home/marta/.local/lib/python3.8/site-packages/telegram/vendor/ptb_urllib3/urllib3/connection.py", line 284, in connect
    conn = self._new_conn()
  File "/home/marta/.local/lib/python3.8/site-packages/telegram/vendor/ptb_urllib3/urllib3/connection.py", line 149, in _new_conn
    raise NewConnectionError(
telegram.vendor.ptb_urllib3.urllib3.exceptions.NewConnectionError: <telegram.vendor.ptb_urllib3.urllib3.connection.VerifiedHTTPSConnection object at 0x7f7ddf4e50d0>: Failed to establish a new connection: [Errno 101] Network is unreachable

During handling of the above exception, another exception occurred:

Traceback (most recent call last):
  File "/home/marta/.local/lib/python3.8/site-packages/telegram/utils/request.py", line 259, in _request_wrapper
    resp = self._con_pool.request(*args, **kwargs)
  File "/home/marta/.local/lib/python3.8/site-packages/telegram/vendor/ptb_urllib3/urllib3/request.py", line 68, in request
    return self.request_encode_body(method, url, fields=fields,
  File "/home/marta/.local/lib/python3.8/site-packages/telegram/vendor/ptb_urllib3/urllib3/request.py", line 148, in request_encode_body
    return self.urlopen(method, url, **extra_kw)
  File "/home/marta/.local/lib/python3.8/site-packages/telegram/vendor/ptb_urllib3/urllib3/poolmanager.py", line 244, in urlopen
    response = conn.urlopen(method, u.request_uri, **kw)
  File "/home/marta/.local/lib/python3.8/site-packages/telegram/vendor/ptb_urllib3/urllib3/connectionpool.py", line 691, in urlopen
    return self.urlopen(method, url, body, headers, retries,
  File "/home/marta/.local/lib/python3.8/site-packages/telegram/vendor/ptb_urllib3/urllib3/connectionpool.py", line 691, in urlopen
    return self.urlopen(method, url, body, headers, retries,
  File "/home/marta/.local/lib/python3.8/site-packages/telegram/vendor/ptb_urllib3/urllib3/connectionpool.py", line 691, in urlopen
    return self.urlopen(method, url, body, headers, retries,
  File "/home/marta/.local/lib/python3.8/site-packages/telegram/vendor/ptb_urllib3/urllib3/connectionpool.py", line 665, in urlopen
    retries = retries.increment(method, url, error=e, _pool=self,
  File "/home/marta/.local/lib/python3.8/site-packages/telegram/vendor/ptb_urllib3/urllib3/util/retry.py", line 376, in increment
    raise MaxRetryError(_pool, url, error or ResponseError(cause))
telegram.vendor.ptb_urllib3.urllib3.exceptions.MaxRetryError: HTTPSConnectionPool(host='api.telegram.org', port=443): Max retries exceeded with url: /bot6016703766:AAE0sJbP7mN6JA9HGsWHVEBB3iwgJOFtKVM/getUpdates (Caused by NewConnectionError('<telegram.vendor.ptb_urllib3.urllib3.connection.VerifiedHTTPSConnection object at 0x7f7ddf4e50d0>: Failed to establish a new connection: [Errno 101] Network is unreachable'))

The above exception was the direct cause of the following exception:

Traceback (most recent call last):
  File "/home/marta/.local/lib/python3.8/site-packages/telegram/ext/updater.py", line 646, in _network_loop_retry
    if not action_cb():
  File "/home/marta/.local/lib/python3.8/site-packages/telegram/ext/updater.py", line 597, in polling_action_cb
    updates = self.bot.get_updates(
  File "/home/marta/.local/lib/python3.8/site-packages/telegram/ext/extbot.py", line 222, in get_updates
    updates = super().get_updates(
  File "/home/marta/.local/lib/python3.8/site-packages/telegram/bot.py", line 130, in decorator
    result = func(*args, **kwargs)
  File "/home/marta/.local/lib/python3.8/site-packages/telegram/bot.py", line 2945, in get_updates
    self._post(
  File "/home/marta/.local/lib/python3.8/site-packages/telegram/bot.py", line 295, in _post
    return self.request.post(
  File "/home/marta/.local/lib/python3.8/site-packages/telegram/utils/request.py", line 361, in post
    result = self._request_wrapper(
  File "/home/marta/.local/lib/python3.8/site-packages/telegram/utils/request.py", line 265, in _request_wrapper
    raise NetworkError(f'urllib3 HTTPError {error}') from error
telegram.error.NetworkError: urllib3 HTTPError HTTPSConnectionPool(host='api.telegram.org', port=443): Max retries exceeded with url: /bot6016703766:AAE0sJbP7mN6JA9HGsWHVEBB3iwgJOFtKVM/getUpdates (Caused by NewConnectionError('<telegram.vendor.ptb_urllib3.urllib3.connection.VerifiedHTTPSConnection object at 0x7f7ddf4e50d0>: Failed to establish a new connection: [Errno 101] Network is unreachable'))
2023-05-14 15:54:46,683 - telegram.vendor.ptb_urllib3.urllib3.connectionpool - WARNING - Retrying (Retry(total=2, connect=None, read=None, redirect=None)) after connection broken by 'NewConnectionError('<telegram.vendor.ptb_urllib3.urllib3.connection.VerifiedHTTPSConnection object at 0x7f7ddf4e5460>: Failed to establish a new connection: [Errno -2] Name or service not known')': /bot6016703766:AAE0sJbP7mN6JA9HGsWHVEBB3iwgJOFtKVM/getUpdates
2023-05-14 15:54:46,684 - telegram.vendor.ptb_urllib3.urllib3.connectionpool - WARNING - Retrying (Retry(total=1, connect=None, read=None, redirect=None)) after connection broken by 'NewConnectionError('<telegram.vendor.ptb_urllib3.urllib3.connection.VerifiedHTTPSConnection object at 0x7f7ddf4e55e0>: Failed to establish a new connection: [Errno -2] Name or service not known')': /bot6016703766:AAE0sJbP7mN6JA9HGsWHVEBB3iwgJOFtKVM/getUpdates
2023-05-14 15:54:46,685 - telegram.vendor.ptb_urllib3.urllib3.connectionpool - WARNING - Retrying (Retry(total=0, connect=None, read=None, redirect=None)) after connection broken by 'NewConnectionError('<telegram.vendor.ptb_urllib3.urllib3.connection.VerifiedHTTPSConnection object at 0x7f7ddf4e5730>: Failed to establish a new connection: [Errno -2] Name or service not known')': /bot6016703766:AAE0sJbP7mN6JA9HGsWHVEBB3iwgJOFtKVM/getUpdates
2023-05-14 15:54:46,685 - telegram.ext.updater - ERROR - Error while getting Updates: urllib3 HTTPError HTTPSConnectionPool(host='api.telegram.org', port=443): Max retries exceeded with url: /bot6016703766:AAE0sJbP7mN6JA9HGsWHVEBB3iwgJOFtKVM/getUpdates (Caused by NewConnectionError('<telegram.vendor.ptb_urllib3.urllib3.connection.VerifiedHTTPSConnection object at 0x7f7ddf4e5880>: Failed to establish a new connection: [Errno -2] Name or service not known'))
2023-05-14 15:54:46,685 - telegram.ext.dispatcher - ERROR - No error handlers are registered, logging exception.
Traceback (most recent call last):
  File "/home/marta/.local/lib/python3.8/site-packages/telegram/vendor/ptb_urllib3/urllib3/connection.py", line 140, in _new_conn
    conn = connection.create_connection(
  File "/home/marta/.local/lib/python3.8/site-packages/telegram/vendor/ptb_urllib3/urllib3/util/connection.py", line 60, in create_connection
    for res in socket.getaddrinfo(host, port, family, socket.SOCK_STREAM):
  File "/usr/lib64/python3.8/socket.py", line 918, in getaddrinfo
    for res in _socket.getaddrinfo(host, port, family, type, proto, flags):
socket.gaierror: [Errno -2] Name or service not known

During handling of the above exception, another exception occurred:

Traceback (most recent call last):
  File "/home/marta/.local/lib/python3.8/site-packages/telegram/vendor/ptb_urllib3/urllib3/connectionpool.py", line 614, in urlopen
    httplib_response = self._make_request(conn, method, url,
  File "/home/marta/.local/lib/python3.8/site-packages/telegram/vendor/ptb_urllib3/urllib3/connectionpool.py", line 360, in _make_request
    self._validate_conn(conn)
  File "/home/marta/.local/lib/python3.8/site-packages/telegram/vendor/ptb_urllib3/urllib3/connectionpool.py", line 857, in _validate_conn
    super(HTTPSConnectionPool, self)._validate_conn(conn)
  File "/home/marta/.local/lib/python3.8/site-packages/telegram/vendor/ptb_urllib3/urllib3/connectionpool.py", line 289, in _validate_conn
    conn.connect()
  File "/home/marta/.local/lib/python3.8/site-packages/telegram/vendor/ptb_urllib3/urllib3/connection.py", line 284, in connect
    conn = self._new_conn()
  File "/home/marta/.local/lib/python3.8/site-packages/telegram/vendor/ptb_urllib3/urllib3/connection.py", line 149, in _new_conn
    raise NewConnectionError(
telegram.vendor.ptb_urllib3.urllib3.exceptions.NewConnectionError: <telegram.vendor.ptb_urllib3.urllib3.connection.VerifiedHTTPSConnection object at 0x7f7ddf4e5880>: Failed to establish a new connection: [Errno -2] Name or service not known

During handling of the above exception, another exception occurred:

Traceback (most recent call last):
  File "/home/marta/.local/lib/python3.8/site-packages/telegram/utils/request.py", line 259, in _request_wrapper
    resp = self._con_pool.request(*args, **kwargs)
  File "/home/marta/.local/lib/python3.8/site-packages/telegram/vendor/ptb_urllib3/urllib3/request.py", line 68, in request
    return self.request_encode_body(method, url, fields=fields,
  File "/home/marta/.local/lib/python3.8/site-packages/telegram/vendor/ptb_urllib3/urllib3/request.py", line 148, in request_encode_body
    return self.urlopen(method, url, **extra_kw)
  File "/home/marta/.local/lib/python3.8/site-packages/telegram/vendor/ptb_urllib3/urllib3/poolmanager.py", line 244, in urlopen
    response = conn.urlopen(method, u.request_uri, **kw)
  File "/home/marta/.local/lib/python3.8/site-packages/telegram/vendor/ptb_urllib3/urllib3/connectionpool.py", line 691, in urlopen
    return self.urlopen(method, url, body, headers, retries,
  File "/home/marta/.local/lib/python3.8/site-packages/telegram/vendor/ptb_urllib3/urllib3/connectionpool.py", line 691, in urlopen
    return self.urlopen(method, url, body, headers, retries,
  File "/home/marta/.local/lib/python3.8/site-packages/telegram/vendor/ptb_urllib3/urllib3/connectionpool.py", line 691, in urlopen
    return self.urlopen(method, url, body, headers, retries,
  File "/home/marta/.local/lib/python3.8/site-packages/telegram/vendor/ptb_urllib3/urllib3/connectionpool.py", line 665, in urlopen
    retries = retries.increment(method, url, error=e, _pool=self,
  File "/home/marta/.local/lib/python3.8/site-packages/telegram/vendor/ptb_urllib3/urllib3/util/retry.py", line 376, in increment
    raise MaxRetryError(_pool, url, error or ResponseError(cause))
telegram.vendor.ptb_urllib3.urllib3.exceptions.MaxRetryError: HTTPSConnectionPool(host='api.telegram.org', port=443): Max retries exceeded with url: /bot6016703766:AAE0sJbP7mN6JA9HGsWHVEBB3iwgJOFtKVM/getUpdates (Caused by NewConnectionError('<telegram.vendor.ptb_urllib3.urllib3.connection.VerifiedHTTPSConnection object at 0x7f7ddf4e5880>: Failed to establish a new connection: [Errno -2] Name or service not known'))

The above exception was the direct cause of the following exception:

Traceback (most recent call last):
  File "/home/marta/.local/lib/python3.8/site-packages/telegram/ext/updater.py", line 646, in _network_loop_retry
    if not action_cb():
  File "/home/marta/.local/lib/python3.8/site-packages/telegram/ext/updater.py", line 597, in polling_action_cb
    updates = self.bot.get_updates(
  File "/home/marta/.local/lib/python3.8/site-packages/telegram/ext/extbot.py", line 222, in get_updates
    updates = super().get_updates(
  File "/home/marta/.local/lib/python3.8/site-packages/telegram/bot.py", line 130, in decorator
    result = func(*args, **kwargs)
  File "/home/marta/.local/lib/python3.8/site-packages/telegram/bot.py", line 2945, in get_updates
    self._post(
  File "/home/marta/.local/lib/python3.8/site-packages/telegram/bot.py", line 295, in _post
    return self.request.post(
  File "/home/marta/.local/lib/python3.8/site-packages/telegram/utils/request.py", line 361, in post
    result = self._request_wrapper(
  File "/home/marta/.local/lib/python3.8/site-packages/telegram/utils/request.py", line 265, in _request_wrapper
    raise NetworkError(f'urllib3 HTTPError {error}') from error
telegram.error.NetworkError: urllib3 HTTPError HTTPSConnectionPool(host='api.telegram.org', port=443): Max retries exceeded with url: /bot6016703766:AAE0sJbP7mN6JA9HGsWHVEBB3iwgJOFtKVM/getUpdates (Caused by NewConnectionError('<telegram.vendor.ptb_urllib3.urllib3.connection.VerifiedHTTPSConnection object at 0x7f7ddf4e5880>: Failed to establish a new connection: [Errno -2] Name or service not known'))
2023-05-14 15:55:09,843 - apscheduler.scheduler - INFO - Scheduler started
2023-05-14 15:55:21,363 - root - INFO -  - CMD: DITIEMPO - USER_ID: 28097231 - USERNAME: martatorrebarbeito - USER_FULLNAME: Marta - CHAT ID: 28097231
2023-05-14 15:55:21,605 - telegram.ext.dispatcher - ERROR - No error handlers are registered, logging exception.
Traceback (most recent call last):
  File "/home/marta/.local/lib/python3.8/site-packages/telegram/ext/dispatcher.py", line 555, in process_update
    handler.handle_update(update, self, check, context)
  File "/home/marta/.local/lib/python3.8/site-packages/telegram/ext/handler.py", line 198, in handle_update
    return self.callback(update, context)
  File "/home/marta/Proyectos/lverbobot/lverbobot.py", line 221, in ditiempo
    context.bot.send_message(chat_id=update.effective_chat.id,text=context.user_data['respuestacorrecta_valor'])
  File "/home/marta/.local/lib/python3.8/site-packages/telegram/bot.py", line 130, in decorator
    result = func(*args, **kwargs)
  File "/home/marta/.local/lib/python3.8/site-packages/telegram/bot.py", line 513, in send_message
    return self._message(  # type: ignore[return-value]
  File "/home/marta/.local/lib/python3.8/site-packages/telegram/ext/extbot.py", line 199, in _message
    result = super()._message(
  File "/home/marta/.local/lib/python3.8/site-packages/telegram/bot.py", line 332, in _message
    result = self._post(endpoint, data, timeout=timeout, api_kwargs=api_kwargs)
  File "/home/marta/.local/lib/python3.8/site-packages/telegram/bot.py", line 295, in _post
    return self.request.post(
  File "/home/marta/.local/lib/python3.8/site-packages/telegram/utils/request.py", line 364, in post
    body=json.dumps(data).encode('utf-8'),
  File "/usr/lib64/python3.8/json/__init__.py", line 231, in dumps
    return _default_encoder.encode(obj)
  File "/usr/lib64/python3.8/json/encoder.py", line 199, in encode
    chunks = self.iterencode(o, _one_shot=True)
  File "/usr/lib64/python3.8/json/encoder.py", line 257, in iterencode
    return _iterencode(o, 0)
  File "/usr/lib64/python3.8/json/encoder.py", line 179, in default
    raise TypeError(f'Object of type {o.__class__.__name__} '
TypeError: Object of type int64 is not JSON serializable
2023-05-14 15:55:56,057 - root - INFO -  - CMD: DITIEMPO - USER_ID: 28097231 - USERNAME: martatorrebarbeito - USER_FULLNAME: Marta - CHAT ID: 28097231
2023-05-14 15:55:56,173 - telegram.ext.dispatcher - ERROR - No error handlers are registered, logging exception.
Traceback (most recent call last):
  File "/home/marta/.local/lib/python3.8/site-packages/telegram/ext/dispatcher.py", line 555, in process_update
    handler.handle_update(update, self, check, context)
  File "/home/marta/.local/lib/python3.8/site-packages/telegram/ext/handler.py", line 198, in handle_update
    return self.callback(update, context)
  File "/home/marta/Proyectos/lverbobot/lverbobot.py", line 221, in ditiempo
    context.bot.send_message(chat_id=update.effective_chat.id,text=context.user_data['respuestacorrecta_valor'])
  File "/home/marta/.local/lib/python3.8/site-packages/telegram/bot.py", line 130, in decorator
    result = func(*args, **kwargs)
  File "/home/marta/.local/lib/python3.8/site-packages/telegram/bot.py", line 513, in send_message
    return self._message(  # type: ignore[return-value]
  File "/home/marta/.local/lib/python3.8/site-packages/telegram/ext/extbot.py", line 199, in _message
    result = super()._message(
  File "/home/marta/.local/lib/python3.8/site-packages/telegram/bot.py", line 332, in _message
    result = self._post(endpoint, data, timeout=timeout, api_kwargs=api_kwargs)
  File "/home/marta/.local/lib/python3.8/site-packages/telegram/bot.py", line 295, in _post
    return self.request.post(
  File "/home/marta/.local/lib/python3.8/site-packages/telegram/utils/request.py", line 364, in post
    body=json.dumps(data).encode('utf-8'),
  File "/usr/lib64/python3.8/json/__init__.py", line 231, in dumps
    return _default_encoder.encode(obj)
  File "/usr/lib64/python3.8/json/encoder.py", line 199, in encode
    chunks = self.iterencode(o, _one_shot=True)
  File "/usr/lib64/python3.8/json/encoder.py", line 257, in iterencode
    return _iterencode(o, 0)
  File "/usr/lib64/python3.8/json/encoder.py", line 179, in default
    raise TypeError(f'Object of type {o.__class__.__name__} '
TypeError: Object of type int64 is not JSON serializable
2023-05-14 15:57:02,367 - apscheduler.scheduler - INFO - Scheduler started
2023-05-14 15:57:04,897 - root - INFO -  - CMD: DITIEMPO - USER_ID: 28097231 - USERNAME: martatorrebarbeito - USER_FULLNAME: Marta - CHAT ID: 28097231
2023-05-14 15:58:05,179 - telegram.ext.dispatcher - ERROR - No error handlers are registered, logging exception.
Traceback (most recent call last):
  File "/home/marta/.local/lib/python3.8/site-packages/telegram/ext/dispatcher.py", line 555, in process_update
    handler.handle_update(update, self, check, context)
  File "/home/marta/.local/lib/python3.8/site-packages/telegram/ext/handler.py", line 198, in handle_update
    return self.callback(update, context)
  File "/home/marta/Proyectos/lverbobot/lverbobot.py", line 164, in ditiempo
    context.bot.send_message(chat_id=update.effective_chat.id,text=context.user_data['respuestacorrecta_valor'])
  File "/home/marta/.local/lib/python3.8/site-packages/telegram/bot.py", line 130, in decorator
    result = func(*args, **kwargs)
  File "/home/marta/.local/lib/python3.8/site-packages/telegram/bot.py", line 513, in send_message
    return self._message(  # type: ignore[return-value]
  File "/home/marta/.local/lib/python3.8/site-packages/telegram/ext/extbot.py", line 199, in _message
    result = super()._message(
  File "/home/marta/.local/lib/python3.8/site-packages/telegram/bot.py", line 332, in _message
    result = self._post(endpoint, data, timeout=timeout, api_kwargs=api_kwargs)
  File "/home/marta/.local/lib/python3.8/site-packages/telegram/bot.py", line 295, in _post
    return self.request.post(
  File "/home/marta/.local/lib/python3.8/site-packages/telegram/utils/request.py", line 364, in post
    body=json.dumps(data).encode('utf-8'),
  File "/usr/lib64/python3.8/json/__init__.py", line 231, in dumps
    return _default_encoder.encode(obj)
  File "/usr/lib64/python3.8/json/encoder.py", line 199, in encode
    chunks = self.iterencode(o, _one_shot=True)
  File "/usr/lib64/python3.8/json/encoder.py", line 257, in iterencode
    return _iterencode(o, 0)
  File "/usr/lib64/python3.8/json/encoder.py", line 179, in default
    raise TypeError(f'Object of type {o.__class__.__name__} '
TypeError: Object of type int64 is not JSON serializable
2023-05-14 15:59:37,907 - apscheduler.scheduler - INFO - Scheduler started
2023-05-14 15:59:40,453 - root - INFO -  - CMD: DITIEMPO - USER_ID: 28097231 - USERNAME: martatorrebarbeito - USER_FULLNAME: Marta - CHAT ID: 28097231
2023-05-14 15:59:51,439 - root - INFO -  - CMD: DITIEMPO - USER_ID: 28097231 - USERNAME: martatorrebarbeito - USER_FULLNAME: Marta - CHAT ID: 28097231
2023-05-14 16:02:39,808 - apscheduler.scheduler - INFO - Scheduler started
2023-05-14 16:02:43,207 - apscheduler.scheduler - INFO - Scheduler started
2023-05-14 16:02:46,412 - root - INFO -  - CMD: DITIEMPO - USER_ID: 28097231 - USERNAME: martatorrebarbeito - USER_FULLNAME: Marta - CHAT ID: 28097231
2023-05-14 16:03:00,514 - telegram.ext.dispatcher - ERROR - No error handlers are registered, logging exception.
Traceback (most recent call last):
  File "/home/marta/.local/lib/python3.8/site-packages/telegram/ext/dispatcher.py", line 555, in process_update
    handler.handle_update(update, self, check, context)
  File "/home/marta/.local/lib/python3.8/site-packages/telegram/ext/handler.py", line 198, in handle_update
    return self.callback(update, context)
  File "/home/marta/Proyectos/lverbobot/lverbobot.py", line 157, in boton_pulsado
    registra(update, 'FALLO')
  File "/home/marta/Proyectos/lverbobot/lverbobot.py", line 34, in registra
    usuario=update.message.from_user
AttributeError: 'NoneType' object has no attribute 'from_user'
2023-05-14 16:03:25,435 - telegram.ext.dispatcher - ERROR - No error handlers are registered, logging exception.
Traceback (most recent call last):
  File "/home/marta/.local/lib/python3.8/site-packages/telegram/ext/dispatcher.py", line 555, in process_update
    handler.handle_update(update, self, check, context)
  File "/home/marta/.local/lib/python3.8/site-packages/telegram/ext/handler.py", line 198, in handle_update
    return self.callback(update, context)
  File "/home/marta/Proyectos/lverbobot/lverbobot.py", line 157, in boton_pulsado
    registra(update, 'FALLO')
  File "/home/marta/Proyectos/lverbobot/lverbobot.py", line 34, in registra
    usuario=update.message.from_user
AttributeError: 'NoneType' object has no attribute 'from_user'
2023-05-14 16:03:32,828 - telegram.ext.dispatcher - ERROR - No error handlers are registered, logging exception.
Traceback (most recent call last):
  File "/home/marta/.local/lib/python3.8/site-packages/telegram/ext/dispatcher.py", line 555, in process_update
    handler.handle_update(update, self, check, context)
  File "/home/marta/.local/lib/python3.8/site-packages/telegram/ext/handler.py", line 198, in handle_update
    return self.callback(update, context)
  File "/home/marta/Proyectos/lverbobot/lverbobot.py", line 157, in boton_pulsado
    registra(update, 'FALLO')
  File "/home/marta/Proyectos/lverbobot/lverbobot.py", line 34, in registra
    usuario=update.message.from_user
AttributeError: 'NoneType' object has no attribute 'from_user'
2023-05-14 16:03:35,137 - telegram.ext.dispatcher - ERROR - No error handlers are registered, logging exception.
Traceback (most recent call last):
  File "/home/marta/.local/lib/python3.8/site-packages/telegram/ext/dispatcher.py", line 555, in process_update
    handler.handle_update(update, self, check, context)
  File "/home/marta/.local/lib/python3.8/site-packages/telegram/ext/handler.py", line 198, in handle_update
    return self.callback(update, context)
  File "/home/marta/Proyectos/lverbobot/lverbobot.py", line 157, in boton_pulsado
    registra(update, 'FALLO')
  File "/home/marta/Proyectos/lverbobot/lverbobot.py", line 34, in registra
    usuario=update.message.from_user
AttributeError: 'NoneType' object has no attribute 'from_user'
2023-05-14 16:04:38,010 - apscheduler.scheduler - INFO - Scheduler started
2023-05-14 16:04:41,539 - root - INFO -  - CMD: DITIEMPO - USER_ID: 28097231 - USERNAME: martatorrebarbeito - USER_FULLNAME: Marta - CHAT ID: 28097231
2023-05-14 16:08:40,792 - apscheduler.scheduler - INFO - Scheduler started
2023-05-14 16:08:43,417 - root - INFO -  - CMD: DITIEMPO - USER_ID: 28097231 - USERNAME: martatorrebarbeito - USER_FULLNAME: Marta - CHAT ID: 28097231
2023-05-14 16:09:15,389 - apscheduler.scheduler - INFO - Scheduler started
2023-05-14 16:09:16,261 - root - INFO -  - CMD: DITIEMPO - USER_ID: 28097231 - USERNAME: martatorrebarbeito - USER_FULLNAME: Marta - CHAT ID: 28097231
2023-05-14 16:10:07,166 - telegram.ext.dispatcher - ERROR - No error handlers are registered, logging exception.
Traceback (most recent call last):
  File "/home/marta/.local/lib/python3.8/site-packages/telegram/ext/dispatcher.py", line 555, in process_update
    handler.handle_update(update, self, check, context)
  File "/home/marta/.local/lib/python3.8/site-packages/telegram/ext/handler.py", line 198, in handle_update
    return self.callback(update, context)
  File "/home/marta/Proyectos/lverbobot/lverbobot.py", line 157, in boton_pulsado
    registra(update, 'FALLO')
  File "/home/marta/Proyectos/lverbobot/lverbobot.py", line 34, in registra
    usuario=update.message.from_user
AttributeError: 'NoneType' object has no attribute 'from_user'
2023-05-14 16:11:12,696 - apscheduler.scheduler - INFO - Scheduler started
2023-05-14 16:11:18,738 - root - INFO -  - CMD: DITIEMPO - USER_ID: 28097231 - USERNAME: martatorrebarbeito - USER_FULLNAME: Marta - CHAT ID: 28097231
2023-05-14 16:12:10,614 - telegram.ext.dispatcher - ERROR - No error handlers are registered, logging exception.
Traceback (most recent call last):
  File "/home/marta/.local/lib/python3.8/site-packages/telegram/ext/dispatcher.py", line 555, in process_update
    handler.handle_update(update, self, check, context)
  File "/home/marta/.local/lib/python3.8/site-packages/telegram/ext/handler.py", line 198, in handle_update
    return self.callback(update, context)
  File "/home/marta/Proyectos/lverbobot/lverbobot.py", line 154, in boton_pulsado
    registra(update, 'ACIERTO')
  File "/home/marta/Proyectos/lverbobot/lverbobot.py", line 34, in registra
    usuario=update.message.from_user
AttributeError: 'NoneType' object has no attribute 'from_user'
2023-05-14 16:12:29,524 - apscheduler.scheduler - INFO - Scheduler started
2023-05-14 16:12:33,490 - root - INFO -  - CMD: DITIEMPO - USER_ID: 28097231 - USERNAME: martatorrebarbeito - USER_FULLNAME: Marta - CHAT ID: 28097231
2023-05-14 16:12:49,340 - root - INFO -  - CMD: DITIEMPO - USER_ID: 28097231 - USERNAME: martatorrebarbeito - USER_FULLNAME: Marta - CHAT ID: 28097231
2023-05-14 16:13:00,393 - root - INFO -  - CMD: DITIEMPO - USER_ID: 28097231 - USERNAME: martatorrebarbeito - USER_FULLNAME: Marta - CHAT ID: 28097231
2023-05-14 16:13:36,432 - apscheduler.scheduler - INFO - Scheduler started
2023-05-14 16:13:40,827 - root - INFO -  - CMD: DITIEMPO - USER_ID: 28097231 - USERNAME: martatorrebarbeito - USER_FULLNAME: Marta - CHAT ID: 28097231
2023-05-14 16:16:08,854 - apscheduler.scheduler - INFO - Scheduler started
2023-05-14 16:16:13,798 - root - INFO -  - CMD: DITIEMPO - USER_ID: 28097231 - USERNAME: martatorrebarbeito - USER_FULLNAME: Marta - CHAT ID: 28097231
2023-05-14 16:17:15,306 - apscheduler.scheduler - INFO - Scheduler started
2023-05-14 16:17:18,830 - root - INFO -  - CMD: DITIEMPO - USER_ID: 28097231 - USERNAME: martatorrebarbeito - USER_FULLNAME: Marta - CHAT ID: 28097231
2023-05-14 16:17:59,878 - apscheduler.scheduler - INFO - Scheduler started
2023-05-14 16:18:02,434 - root - INFO -  - CMD: DITIEMPO - USER_ID: 28097231 - USERNAME: martatorrebarbeito - USER_FULLNAME: Marta - CHAT ID: 28097231
2023-05-14 16:18:11,251 - root - INFO -  - CMD: DITIEMPO - USER_ID: 28097231 - USERNAME: martatorrebarbeito - USER_FULLNAME: Marta - CHAT ID: 28097231
2023-05-14 16:18:27,451 - root - INFO -  - CMD: DITIEMPO - USER_ID: 28097231 - USERNAME: martatorrebarbeito - USER_FULLNAME: Marta - CHAT ID: 28097231
2023-05-14 16:19:19,771 - root - INFO -  - CMD: DITIEMPO - USER_ID: 28097231 - USERNAME: martatorrebarbeito - USER_FULLNAME: Marta - CHAT ID: 28097231
2023-05-14 16:19:33,648 - root - INFO -  - CMD: DITIEMPO - USER_ID: 28097231 - USERNAME: martatorrebarbeito - USER_FULLNAME: Marta - CHAT ID: 28097231
2023-05-14 16:19:44,942 - root - INFO -  - CMD: DITIEMPO - USER_ID: 28097231 - USERNAME: martatorrebarbeito - USER_FULLNAME: Marta - CHAT ID: 28097231
2023-05-14 16:19:55,801 - root - INFO -  - CMD: DITIEMPO - USER_ID: 28097231 - USERNAME: martatorrebarbeito - USER_FULLNAME: Marta - CHAT ID: 28097231
2023-05-14 16:20:01,402 - root - INFO -  - CMD: DITIEMPO - USER_ID: 28097231 - USERNAME: martatorrebarbeito - USER_FULLNAME: Marta - CHAT ID: 28097231
2023-05-14 16:21:34,674 - apscheduler.scheduler - INFO - Scheduler started
2023-05-14 16:21:41,771 - root - INFO -  - CMD: DITIEMPO - USER_ID: 28097231 - USERNAME: martatorrebarbeito - USER_FULLNAME: Marta - CHAT ID: 28097231
2023-05-14 16:24:31,596 - apscheduler.scheduler - INFO - Scheduler started
2023-05-14 16:24:38,585 - root - INFO -  - CMD: DITIEMPO - USER_ID: 28097231 - USERNAME: martatorrebarbeito - USER_FULLNAME: Marta - CHAT ID: 28097231
2023-05-14 16:24:41,856 - telegram.ext.dispatcher - ERROR - No error handlers are registered, logging exception.
Traceback (most recent call last):
  File "/home/marta/.local/lib/python3.8/site-packages/telegram/ext/dispatcher.py", line 555, in process_update
    handler.handle_update(update, self, check, context)
  File "/home/marta/.local/lib/python3.8/site-packages/telegram/ext/handler.py", line 198, in handle_update
    return self.callback(update, context)
  File "/home/marta/Proyectos/lverbobot/lverbobot.py", line 160, in boton_pulsado
    registra(update, 'FALLO')
  File "/home/marta/Proyectos/lverbobot/lverbobot.py", line 34, in registra
    usuario=update.message.from_user
AttributeError: 'NoneType' object has no attribute 'from_user'
2023-05-14 16:25:40,947 - apscheduler.scheduler - INFO - Scheduler started
2023-05-14 16:27:29,732 - apscheduler.scheduler - INFO - Scheduler started
2023-05-14 16:27:30,018 - telegram.ext.dispatcher - ERROR - No error handlers are registered, logging exception.
Traceback (most recent call last):
  File "/home/marta/.local/lib/python3.8/site-packages/telegram/ext/dispatcher.py", line 555, in process_update
    handler.handle_update(update, self, check, context)
  File "/home/marta/.local/lib/python3.8/site-packages/telegram/ext/handler.py", line 198, in handle_update
    return self.callback(update, context)
  File "/home/marta/Proyectos/lverbobot/lverbobot.py", line 169, in ditiempo
    registra(update, 'DITIEMPO')
  File "/home/marta/Proyectos/lverbobot/lverbobot.py", line 35, in registra
    if (usuario.username is None):
NameError: name 'usuario' is not defined
2023-05-14 16:27:30,019 - telegram.ext.dispatcher - ERROR - No error handlers are registered, logging exception.
Traceback (most recent call last):
  File "/home/marta/.local/lib/python3.8/site-packages/telegram/ext/dispatcher.py", line 555, in process_update
    handler.handle_update(update, self, check, context)
  File "/home/marta/.local/lib/python3.8/site-packages/telegram/ext/handler.py", line 198, in handle_update
    return self.callback(update, context)
  File "/home/marta/Proyectos/lverbobot/lverbobot.py", line 169, in ditiempo
    registra(update, 'DITIEMPO')
  File "/home/marta/Proyectos/lverbobot/lverbobot.py", line 35, in registra
    if (usuario.username is None):
NameError: name 'usuario' is not defined
2023-05-14 16:27:34,193 - telegram.ext.dispatcher - ERROR - No error handlers are registered, logging exception.
Traceback (most recent call last):
  File "/home/marta/.local/lib/python3.8/site-packages/telegram/ext/dispatcher.py", line 555, in process_update
    handler.handle_update(update, self, check, context)
  File "/home/marta/.local/lib/python3.8/site-packages/telegram/ext/handler.py", line 198, in handle_update
    return self.callback(update, context)
  File "/home/marta/Proyectos/lverbobot/lverbobot.py", line 169, in ditiempo
    registra(update, 'DITIEMPO')
  File "/home/marta/Proyectos/lverbobot/lverbobot.py", line 35, in registra
    if (usuario.username is None):
NameError: name 'usuario' is not defined
2023-05-14 16:27:43,325 - apscheduler.scheduler - INFO - Scheduler started
2023-05-14 16:27:45,390 - telegram.ext.dispatcher - ERROR - No error handlers are registered, logging exception.
Traceback (most recent call last):
  File "/home/marta/.local/lib/python3.8/site-packages/telegram/ext/dispatcher.py", line 555, in process_update
    handler.handle_update(update, self, check, context)
  File "/home/marta/.local/lib/python3.8/site-packages/telegram/ext/handler.py", line 198, in handle_update
    return self.callback(update, context)
  File "/home/marta/Proyectos/lverbobot/lverbobot.py", line 169, in ditiempo
    registra(update, 'DITIEMPO')
  File "/home/marta/Proyectos/lverbobot/lverbobot.py", line 35, in registra
    if (usuario.username is None):
NameError: name 'usuario' is not defined
2023-05-14 16:28:06,348 - apscheduler.scheduler - INFO - Scheduler started
2023-05-14 16:28:31,884 - telegram.ext.dispatcher - ERROR - No error handlers are registered, logging exception.
Traceback (most recent call last):
  File "/home/marta/.local/lib/python3.8/site-packages/telegram/ext/dispatcher.py", line 555, in process_update
    handler.handle_update(update, self, check, context)
  File "/home/marta/.local/lib/python3.8/site-packages/telegram/ext/handler.py", line 198, in handle_update
    return self.callback(update, context)
  File "/home/marta/Proyectos/lverbobot/lverbobot.py", line 169, in ditiempo
  File "/home/marta/Proyectos/lverbobot/lverbobot.py", line 35, in registra
    if (usuario.username is None):
NameError: name 'usuario' is not defined
2023-05-14 16:30:06,610 - apscheduler.scheduler - INFO - Scheduler started
2023-05-14 16:30:12,600 - root - INFO -  - CMD: DITIEMPO - USER_ID: 28097231 - USERNAME: martatorrebarbeito - USER_FULLNAME: Marta - CHAT ID: 28097231
2023-05-14 16:30:20,967 - root - INFO -  - CMD: DITIEMPO - USER_ID: 28097231 - USERNAME: martatorrebarbeito - USER_FULLNAME: Marta - CHAT ID: 28097231
2023-05-14 16:30:49,103 - root - INFO -  - CMD: DITIEMPO - USER_ID: 28097231 - USERNAME: martatorrebarbeito - USER_FULLNAME: Marta - CHAT ID: 28097231
2023-05-14 16:30:55,236 - root - INFO -  - CMD: DITIEMPO - USER_ID: 28097231 - USERNAME: martatorrebarbeito - USER_FULLNAME: Marta - CHAT ID: 28097231
2023-05-14 16:31:17,445 - root - INFO -  - CMD: DITIEMPO - USER_ID: 28097231 - USERNAME: martatorrebarbeito - USER_FULLNAME: Marta - CHAT ID: 28097231
2023-05-14 16:48:45,775 - apscheduler.scheduler - INFO - Scheduler started
2023-05-14 16:48:54,151 - root - INFO -  - CMD: DIVERBO - USER_ID: 28097231 - USERNAME: martatorrebarbeito - USER_FULLNAME: Marta - CHAT ID: 28097231
2023-05-14 16:49:06,675 - root - INFO -  - CMD: RESPUESTA - USER_ID: 28097231 - USERNAME: martatorrebarbeito - USER_FULLNAME: Marta - CHAT ID: 28097231
2023-05-14 16:49:06,675 - root - INFO -  - CMD: ACIERTO - USER_ID: 28097231 - USERNAME: martatorrebarbeito - USER_FULLNAME: Marta - CHAT ID: 28097231
2023-05-14 16:49:10,996 - root - INFO -  - CMD: DIVERBO - USER_ID: 28097231 - USERNAME: martatorrebarbeito - USER_FULLNAME: Marta - CHAT ID: 28097231
2023-05-14 16:49:15,656 - root - INFO -  - CMD: RESPUESTA - USER_ID: 28097231 - USERNAME: martatorrebarbeito - USER_FULLNAME: Marta - CHAT ID: 28097231
2023-05-14 16:49:15,656 - root - INFO -  - CMD: FALLO - USER_ID: 28097231 - USERNAME: martatorrebarbeito - USER_FULLNAME: Marta - CHAT ID: 28097231
2023-05-14 16:49:25,497 - root - INFO -  - CMD: RESPUESTA - USER_ID: 28097231 - USERNAME: martatorrebarbeito - USER_FULLNAME: Marta - CHAT ID: 28097231
2023-05-14 16:49:25,498 - root - INFO -  - CMD: FALLO - USER_ID: 28097231 - USERNAME: martatorrebarbeito - USER_FULLNAME: Marta - CHAT ID: 28097231
2023-05-14 16:49:35,325 - root - INFO -  - CMD: RESPUESTA - USER_ID: 28097231 - USERNAME: martatorrebarbeito - USER_FULLNAME: Marta - CHAT ID: 28097231
2023-05-14 16:49:35,326 - root - INFO -  - CMD: FALLO - USER_ID: 28097231 - USERNAME: martatorrebarbeito - USER_FULLNAME: Marta - CHAT ID: 28097231
2023-05-14 16:50:30,501 - root - INFO -  - CMD: RESPUESTA - USER_ID: 28097231 - USERNAME: martatorrebarbeito - USER_FULLNAME: Marta - CHAT ID: 28097231
2023-05-14 16:50:30,502 - root - INFO -  - CMD: ACIERTO - USER_ID: 28097231 - USERNAME: martatorrebarbeito - USER_FULLNAME: Marta - CHAT ID: 28097231
2023-05-14 16:50:34,303 - root - INFO -  - CMD: DITIEMPO - USER_ID: 28097231 - USERNAME: martatorrebarbeito - USER_FULLNAME: Marta - CHAT ID: 28097231
2023-05-14 16:50:50,886 - root - INFO -  - CMD: DITIEMPO - USER_ID: 28097231 - USERNAME: martatorrebarbeito - USER_FULLNAME: Marta - CHAT ID: 28097231
2023-05-14 16:50:59,093 - root - INFO -  - CMD: DIVERBO - USER_ID: 28097231 - USERNAME: martatorrebarbeito - USER_FULLNAME: Marta - CHAT ID: 28097231
2023-05-14 16:51:12,429 - root - INFO -  - CMD: RESPUESTA - USER_ID: 28097231 - USERNAME: martatorrebarbeito - USER_FULLNAME: Marta - CHAT ID: 28097231
2023-05-14 16:51:12,430 - root - INFO -  - CMD: FALLO - USER_ID: 28097231 - USERNAME: martatorrebarbeito - USER_FULLNAME: Marta - CHAT ID: 28097231
2023-05-14 16:51:15,859 - root - INFO -  - CMD: RESPUESTA - USER_ID: 28097231 - USERNAME: martatorrebarbeito - USER_FULLNAME: Marta - CHAT ID: 28097231
2023-05-14 16:51:15,859 - root - INFO -  - CMD: FALLO - USER_ID: 28097231 - USERNAME: martatorrebarbeito - USER_FULLNAME: Marta - CHAT ID: 28097231
2023-05-14 16:51:17,154 - root - INFO -  - CMD: RESPUESTA - USER_ID: 28097231 - USERNAME: martatorrebarbeito - USER_FULLNAME: Marta - CHAT ID: 28097231
2023-05-14 16:51:17,154 - root - INFO -  - CMD: ACIERTO - USER_ID: 28097231 - USERNAME: martatorrebarbeito - USER_FULLNAME: Marta - CHAT ID: 28097231
2023-05-14 16:51:21,360 - root - INFO -  - CMD: DIVERBO - USER_ID: 28097231 - USERNAME: martatorrebarbeito - USER_FULLNAME: Marta - CHAT ID: 28097231
2023-05-14 16:51:32,143 - root - INFO -  - CMD: RESPUESTA - USER_ID: 28097231 - USERNAME: martatorrebarbeito - USER_FULLNAME: Marta - CHAT ID: 28097231
2023-05-14 16:51:32,143 - root - INFO -  - CMD: ACIERTO - USER_ID: 28097231 - USERNAME: martatorrebarbeito - USER_FULLNAME: Marta - CHAT ID: 28097231
2023-05-14 16:51:36,143 - root - INFO -  - CMD: DIVERBO - USER_ID: 28097231 - USERNAME: martatorrebarbeito - USER_FULLNAME: Marta - CHAT ID: 28097231
2023-05-14 16:51:51,588 - root - INFO -  - CMD: RESPUESTA - USER_ID: 28097231 - USERNAME: martatorrebarbeito - USER_FULLNAME: Marta - CHAT ID: 28097231
2023-05-14 16:51:51,588 - root - INFO -  - CMD: ACIERTO - USER_ID: 28097231 - USERNAME: martatorrebarbeito - USER_FULLNAME: Marta - CHAT ID: 28097231
2023-05-14 16:56:53,904 - apscheduler.scheduler - INFO - Scheduler started
2023-05-14 16:56:57,510 - root - INFO -  - CMD: DITIEMPO - USER_ID: 28097231 - USERNAME: martatorrebarbeito - USER_FULLNAME: Marta - CHAT ID: 28097231
2023-05-14 16:56:59,317 - root - INFO -  - CMD: FALLO - USER_ID: -- - USERNAME: -- - USER_FULLNAME: -- - CHAT ID: 28097231
2023-05-14 16:57:12,488 - telegram.vendor.ptb_urllib3.urllib3.connectionpool - WARNING - Retrying (Retry(total=2, connect=None, read=None, redirect=None)) after connection broken by 'NewConnectionError('<telegram.vendor.ptb_urllib3.urllib3.connection.VerifiedHTTPSConnection object at 0x7fe6da66b040>: Failed to establish a new connection: [Errno 113] No route to host')': /bot6016703766:AAE0sJbP7mN6JA9HGsWHVEBB3iwgJOFtKVM/getUpdates
2023-05-14 16:57:15,556 - telegram.vendor.ptb_urllib3.urllib3.connectionpool - WARNING - Retrying (Retry(total=1, connect=None, read=None, redirect=None)) after connection broken by 'NewConnectionError('<telegram.vendor.ptb_urllib3.urllib3.connection.VerifiedHTTPSConnection object at 0x7fe6da66b250>: Failed to establish a new connection: [Errno 113] No route to host')': /bot6016703766:AAE0sJbP7mN6JA9HGsWHVEBB3iwgJOFtKVM/getUpdates
2023-05-14 16:57:17,989 - root - INFO -  - CMD: ACIERTO - USER_ID: -- - USERNAME: -- - USER_FULLNAME: -- - CHAT ID: 28097231
2023-05-14 16:57:45,646 - root - INFO -  - CMD: DITIEMPO - USER_ID: 28097231 - USERNAME: martatorrebarbeito - USER_FULLNAME: Marta - CHAT ID: 28097231
2023-05-14 16:57:48,196 - root - INFO -  - CMD: ACIERTO - USER_ID: -- - USERNAME: -- - USER_FULLNAME: -- - CHAT ID: 28097231
2023-05-14 16:57:56,814 - root - INFO -  - CMD: PIDOPAPAS - USER_ID: 28097231 - USERNAME: martatorrebarbeito - USER_FULLNAME: Marta - CHAT ID: 28097231
2023-05-14 16:59:20,970 - apscheduler.scheduler - INFO - Scheduler started
2023-05-14 16:59:23,947 - root - INFO -  - CMD: DITIEMPO - USER_ID: 28097231 - USERNAME: martatorrebarbeito - USER_FULLNAME: Marta - CHAT ID: 28097231
2023-05-14 16:59:26,614 - root - INFO -  - CMD: FALLO - USER_ID: -- - USERNAME: -- - USER_FULLNAME: -- - CHAT ID: 28097231
2023-05-14 16:59:29,279 - root - INFO -  - CMD: PIDOPAPAS - USER_ID: 28097231 - USERNAME: martatorrebarbeito - USER_FULLNAME: Marta - CHAT ID: 28097231
2023-05-14 16:59:46,181 - apscheduler.scheduler - INFO - Scheduler started
2023-05-14 16:59:51,049 - root - INFO -  - CMD: DITIEMPO - USER_ID: 28097231 - USERNAME: martatorrebarbeito - USER_FULLNAME: Marta - CHAT ID: 28097231
2023-05-14 16:59:52,224 - root - INFO -  - CMD: FALLO - USER_ID: -- - USERNAME: -- - USER_FULLNAME: -- - CHAT ID: 28097231
2023-05-14 16:59:54,914 - root - INFO -  - CMD: PIDOPAPAS - USER_ID: 28097231 - USERNAME: martatorrebarbeito - USER_FULLNAME: Marta - CHAT ID: 28097231
2023-05-14 17:02:38,317 - apscheduler.scheduler - INFO - Scheduler started
2023-05-14 17:02:41,590 - root - INFO -  - CMD: DITIEMPO - USER_ID: 28097231 - USERNAME: martatorrebarbeito - USER_FULLNAME: Marta - CHAT ID: 28097231
2023-05-14 17:02:43,058 - root - INFO -  - CMD: FALLO - USER_ID: -- - USERNAME: -- - USER_FULLNAME: -- - CHAT ID: 28097231
2023-05-14 17:02:45,888 - root - INFO -  - CMD: PIDOPAPAS - USER_ID: 28097231 - USERNAME: martatorrebarbeito - USER_FULLNAME: Marta - CHAT ID: 28097231
2023-05-14 17:02:57,643 - root - INFO -  - CMD: DITIEMPO - USER_ID: 28097231 - USERNAME: martatorrebarbeito - USER_FULLNAME: Marta - CHAT ID: 28097231
2023-05-14 17:02:59,843 - root - INFO -  - CMD: FALLO - USER_ID: -- - USERNAME: -- - USER_FULLNAME: -- - CHAT ID: 28097231
2023-05-14 17:03:03,071 - root - INFO -  - CMD: PIDOPAPAS - USER_ID: 28097231 - USERNAME: martatorrebarbeito - USER_FULLNAME: Marta - CHAT ID: 28097231
2023-05-14 17:03:10,278 - root - INFO -  - CMD: DIVERBO - USER_ID: 28097231 - USERNAME: martatorrebarbeito - USER_FULLNAME: Marta - CHAT ID: 28097231
2023-05-14 17:03:26,138 - root - INFO -  - CMD: RESPUESTA - USER_ID: 28097231 - USERNAME: martatorrebarbeito - USER_FULLNAME: Marta - CHAT ID: 28097231
2023-05-14 17:03:26,138 - root - INFO -  - CMD: ACIERTO - USER_ID: 28097231 - USERNAME: martatorrebarbeito - USER_FULLNAME: Marta - CHAT ID: 28097231
2023-05-14 17:03:30,655 - root - INFO -  - CMD: DIVERBO - USER_ID: 28097231 - USERNAME: martatorrebarbeito - USER_FULLNAME: Marta - CHAT ID: 28097231
2023-05-14 17:03:33,117 - root - INFO -  - CMD: RESPUESTA - USER_ID: 28097231 - USERNAME: martatorrebarbeito - USER_FULLNAME: Marta - CHAT ID: 28097231
2023-05-14 17:03:33,117 - root - INFO -  - CMD: FALLO - USER_ID: 28097231 - USERNAME: martatorrebarbeito - USER_FULLNAME: Marta - CHAT ID: 28097231
2023-05-14 17:03:36,222 - root - INFO -  - CMD: RESPUESTA - USER_ID: 28097231 - USERNAME: martatorrebarbeito - USER_FULLNAME: Marta - CHAT ID: 28097231
2023-05-14 17:03:36,222 - root - INFO -  - CMD: FALLO - USER_ID: 28097231 - USERNAME: martatorrebarbeito - USER_FULLNAME: Marta - CHAT ID: 28097231
2023-05-14 17:03:40,810 - root - INFO -  - CMD: PIDOPAPAS - USER_ID: 28097231 - USERNAME: martatorrebarbeito - USER_FULLNAME: Marta - CHAT ID: 28097231
2023-05-14 17:10:46,495 - apscheduler.scheduler - INFO - Scheduler started
